Workbook

Sheet homogeneidad
A1: HOMOGENEITY VALIDATION - SO2 60-nmol/mol
A2: ISO 13528:2022 Section 9.2 - Between-sample and within-sample standard deviations
A4: Parameters | B4: MADe | D4: NIQR
A5: g (samples) | B5: 10 | D5: =B5 -> 10
A6: m (replicates) | B6: 2 | D6: =B6 -> 2
A7: valor asignado x_pt | B7: =MEDIAN(B19:B28) -> -0.022837013 | D7: =MEDIAN(B19:B28) -> -0.022837013
A8: mediana diferencias | B8: =MEDIAN(F19:F28) -> 0.02623063 | C8: q1 | D8: =QUARTILE(B19:B28,1) -> -0.050386792
A9: desviacion | B9: =1.483*B8 -> 0.038900025 | C9: q3 | D9: =QUARTILE(B19:B28,3) -> 0.0046542553
A10: σ_pt | B10: =B9 -> 0.038900025 | C10: ICR | D10: =D9-D8 -> 0.055041048
A11: incertidumbre x_pt | B11: =1.25*B9/SQRT(B5) -> 0.015376585 | C11: NIQR | D11: =0.7413*D10 -> 0.040801929
C12: σ_pt | D12: =D11 -> 0.040801929
C13: incertidumbre x_pt | D13: =1.25*D11/SQRT(D5) -> 0.016128378
A18: Sample ID | B18: replicate_1 | C18: replicate_2 | D18: promedio muestra xt | E18: rango entre ensayos | F18: desviacion vs xpt
A19: 1 | B19: 0.0067021277 | C19: -0.047962264 | D19: =AVERAGE(B19,C19) -> -0.020630068 | E19: =ABS(B19-C19) -> 0.054664392 | F19: =ABS(C19-$B$7) -> 0.025125251
A20: 2 | B20: 0.004787234 | C20: -0.048849057 | D20: =AVERAGE(B20,C20) -> -0.022030911 | E20: =ABS(B20-C20) -> 0.053636291 | F20: =ABS(C20-$B$7) -> 0.026012043
A21: 3 | B21: -0.049283019 | C21: -0.04745283 | D21: =AVERAGE(B21,C21) -> -0.048367925 | E21: =ABS(B21-C21) -> 0.0018301887 | F21: =ABS(C21-$B$7) -> 0.024615817
A22: 4 | B22: 0.0042553191 | C22: -0.048679245 | D22: =AVERAGE(B22,C22) -> -0.022211963 | E22: =ABS(B22-C22) -> 0.052934564 | F22: =ABS(C22-$B$7) -> 0.025842232
A23: 5 | B23: 0.0060212766 | C23: -0.050169811 | D23: =AVERAGE(B23,C23) -> -0.022074267 | E23: =ABS(B23-C23) -> 0.056191088 | F23: =ABS(C23-$B$7) -> 0.027332798
A24: 6 | B24: -0.052264151 | C24: 0.0058510638 | D24: =AVERAGE(B24,C24) -> -0.023206544 | E24: =ABS(B24-C24) -> 0.058115215 | F24: =ABS(C24-$B$7) -> 0.028688077
A25: 7 | B25: 0.003212766 | C25: -0.051641509 | D25: =AVERAGE(B25,C25) -> -0.024214372 | E25: =ABS(B25-C25) -> 0.054854275 | F25: =ABS(C25-$B$7) -> 0.028804496
A26: 8 | B26: -0.050754717 | C26: 0.0045957447 | D26: =AVERAGE(B26,C26) -> -0.023079486 | E26: =ABS(B26-C26) -> 0.055350462 | F26: =ABS(C26-$B$7) -> 0.027432758
A27: 9 | B27: -0.051962264 | C27: 0.0032553191 | D27: =AVERAGE(B27,C27) -> -0.024353473 | E27: =ABS(B27-C27) -> 0.055217583 | F27: =ABS(C27-$B$7) -> 0.026092332
A28: 10 | B28: -0.048886792 | C28: 0.0035319149 | D28: =AVERAGE(B28,C28) -> -0.022677439 | E28: =ABS(B28-C28) -> 0.052418707 | F28: =ABS(C28-$B$7) -> 0.026368928
A30: CALCULATED STATISTICS
A31: Grand Mean (x̄̄) | B31: =AVERAGE(D19:D28) -> -0.025284645 | D31: =AVERAGE(D19:D28) -> -0.025284645
A32: sx | B32: =_xlfn.STDEV.S(D19:D28) -> 0.0081841913 | D32: =_xlfn.STDEV.S(D19:D28) -> 0.0081841913
A33: sw | B33: =SQRT(SUMSQ(E19:E28)/(2*COUNT(E19:E28))) -> 0.036793103 | D33: =SQRT(SUMSQ(E19:E28)/(2*COUNT(E19:E28))) -> 0.036793103
A34: ss (between-sample SD) | B34: =SQRT(ABS((B32^2)-((B33^2)/2))) -> 0.024695855 | D34: =SQRT(ABS((B32^2)-((B33^2)/2))) -> 0.024695855
A35: HOMOGENEITY CRITERION
A36: σ_pt | B36: =B10 -> 0.038900025 | D36: =D11 -> 0.040801929
A37: c = 0.3 × σ_pt | B37: =0.3*B10 -> 0.011670007 | D37: =0.3*D12 -> 0.012240579
A38: ss ≤ c ? | B38: =IF(B34<=B37,"PASS","FAIL") -> FAIL | D38: =IF(D34<=D37,"PASS","FAIL") -> FAIL
A39: C_Exp | B39: =$B66*B37*B37+$C66*B33*B33 -> 0.0016233052 | D39: =$B66*D37*D37+$C66*D33*D33 -> 0.0016489535
A55: g | B55: f1 | C55: f2
A56: 20 | B56: 1.59 | C56: 0.57
A57: 19 | B57: 1.6 | C57: 0.59
A58: 18 | B58: 1.62 | C58: 0.62
A59: 17 | B59: 1.64 | C59: 0.64
A60: 16 | B60: 1.67 | C60: 0.68
A61: 15 | B61: 1.69 | C61: 0.71
...

Sheet estabilidad
A1: STABILITY VALIDATION - SO2 60-nmol/mol
A2: ISO 13528:2022 Section 9.3 - Stability assessment
A4: =homogeneidad!A4 -> Parameters | B4: =homogeneidad!B4 -> MADe | D4: =homogeneidad!D4 -> NIQR
A5: =homogeneidad!A5 -> g (samples) | B5: =homogeneidad!B5 -> 10 | D5: =homogeneidad!D5 -> 10
A6: =homogeneidad!A6 -> m (replicates) | B6: =homogeneidad!B6 -> 2 | D6: =homogeneidad!D6 -> 2
A7: =homogeneidad!A7 -> valor asignado x_pt | B7: =homogeneidad!B7 -> -0.022837013 | D7: =homogeneidad!D7 -> -0.022837013
A8: =homogeneidad!A8 -> mediana diferencias | B8: =homogeneidad!B8 -> 0.02623063 | C8: =homogeneidad!C8 -> q1 | D8: =homogeneidad!D8 -> -0.050386792
A9: =homogeneidad!A9 -> desviacion | B9: =homogeneidad!B9 -> 0.038900025 | C9: =homogeneidad!C9 -> q3 | D9: =homogeneidad!D9 -> 0.0046542553
A10: =homogeneidad!A10 -> σ_pt | B10: =homogeneidad!B10 -> 0.038900025 | C10: =homogeneidad!C10 -> ICR | D10: =homogeneidad!D10 -> 0.055041048
A11: =homogeneidad!A11 -> incertidumbre x_pt | B11: =homogeneidad!B11 -> 0.015376585 | C11: =homogeneidad!C11 -> NIQR | D11: =homogeneidad!D11 -> 0.040801929
C12: =homogeneidad!C12 -> σ_pt | D12: =homogeneidad!D12 -> 0.040801929
C13: =homogeneidad!C13 -> incertidumbre x_pt | D13: =homogeneidad!D13 -> 0.016128378
A17: HOMOGENEITY DATA
A18: =homogeneidad!A18 -> Sample ID | B18: =homogeneidad!B18 -> replicate_1 | C18: =homogeneidad!C18 -> replicate_2 | D18: =homogeneidad!D18 -> promedio muestra xt | E18: =homogeneidad!E18 -> rango entre ensayos | F18: =homogeneidad!F18 -> desviacion vs xpt
A19: 1 | B19: =homogeneidad!B19 -> 0.0067021277 | C19: =homogeneidad!C19 -> -0.047962264 | D19: =homogeneidad!D19 -> -0.020630068 | E19: =homogeneidad!E19 -> 0.054664392 | F19: =homogeneidad!F19 -> 0.025125251
A20: 2 | B20: =homogeneidad!B20 -> 0.004787234 | C20: =homogeneidad!C20 -> -0.048849057 | D20: =homogeneidad!D20 -> -0.022030911 | E20: =homogeneidad!E20 -> 0.053636291 | F20: =homogeneidad!F20 -> 0.026012043
A21: 3 | B21: =homogeneidad!B21 -> -0.049283019 | C21: =homogeneidad!C21 -> -0.04745283 | D21: =homogeneidad!D21 -> -0.048367925 | E21: =homogeneidad!E21 -> 0.0018301887 | F21: =homogeneidad!F21 -> 0.024615817
A22: 4 | B22: =homogeneidad!B22 -> 0.0042553191 | C22: =homogeneidad!C22 -> -0.048679245 | D22: =homogeneidad!D22 -> -0.022211963 | E22: =homogeneidad!E22 -> 0.052934564 | F22: =homogeneidad!F22 -> 0.025842232
A23: 5 | B23: =homogeneidad!B23 -> 0.0060212766 | C23: =homogeneidad!C23 -> -0.050169811 | D23: =homogeneidad!D23 -> -0.022074267 | E23: =homogeneidad!E23 -> 0.056191088 | F23: =homogeneidad!F23 -> 0.027332798
A24: 6 | B24: =homogeneidad!B24 -> -0.052264151 | C24: =homogeneidad!C24 -> 0.0058510638 | D24: =homogeneidad!D24 -> -0.023206544 | E24: =homogeneidad!E24 -> 0.058115215 | F24: =homogeneidad!F24 -> 0.028688077
A25: 7 | B25: =homogeneidad!B25 -> 0.003212766 | C25: =homogeneidad!C25 -> -0.051641509 | D25: =homogeneidad!D25 -> -0.024214372 | E25: =homogeneidad!E25 -> 0.054854275 | F25: =homogeneidad!F25 -> 0.028804496
A26: 8 | B26: =homogeneidad!B26 -> -0.050754717 | C26: =homogeneidad!C26 -> 0.0045957447 | D26: =homogeneidad!D26 -> -0.023079486 | E26: =homogeneidad!E26 -> 0.055350462 | F26: =homogeneidad!F26 -> 0.027432758
A27: 9 | B27: =homogeneidad!B27 -> -0.051962264 | C27: =homogeneidad!C27 -> 0.0032553191 | D27: =homogeneidad!D27 -> -0.024353473 | E27: =homogeneidad!E27 -> 0.055217583 | F27: =homogeneidad!F27 -> 0.026092332
A28: 10 | B28: =homogeneidad!B28 -> -0.048886792 | C28: =homogeneidad!C28 -> 0.0035319149 | D28: =homogeneidad!D28 -> -0.022677439 | E28: =homogeneidad!E28 -> 0.052418707 | F28: =homogeneidad!F28 -> 0.026368928
A32: STABILITY DATA
A33: Sample ID | B33: Rep 1 | C33: Rep 2 | D33: Mean | E33: rango entre ensayos
A34: 1 | B34: -0.048075472 | C34: -0.049415094 | D34: =AVERAGE(B34,C34) -> -0.048745283 | E34: =ABS(B34-C34) -> 0.0013396226 | G34: pollutant | H34: run | I34: level | J34: replicate | K34: sample_id | L34: value
A35: 2 | B35: 0.0051489362 | C35: 0.0033191489 | D35: =AVERAGE(B35,C35) -> 0.0042340426 | E35: =ABS(B35-C35) -> 0.0018297872 | G35: co | H35: corrida_1 | I35: 0-μmol/mol | J35: 1 | K35: 1 | L35: -0.048075472
G36: co | H36: corrida_1 | I36: 0-μmol/mol | J36: 1 | K36: 2 | L36: 0.0051489362
A37: Stability Grand Mean | B37: =AVERAGE(B34:C35) -> -0.02225562 | D37: =AVERAGE(B34:C35) -> -0.02225562 | G37: co | H37: corrida_1 | I37: 0-μmol/mol | J37: 2 | K37: 1 | L37: -0.049415094
A38: Homogeneity Grand Mean | B38: =AVERAGE(B19:C28) -> -0.025284645 | D38: =AVERAGE(B19:C28) -> -0.025284645 | G38: co | H38: corrida_1 | I38: 0-μmol/mol | J38: 2 | K38: 2 | L38: 0.0033191489
A40: STABILITY ASSESSMENT
A41: |Stab Mean - Hom Mean| | B41: =ABS(B37-B38) -> 0.0030290245 | D41: =ABS(D37-D38) -> 0.0030290245
A42: Criterion c = 0.3 × σ_pt | B42: =0.3*B10 -> 0.011670007 | D42: =0.3*D12 -> 0.012240579
A43: diff ≤ c ? | B43: =IF(B41<=B42,"PASS","FAIL") -> PASS | D43: =IF(D41<=D42,"PASS","FAIL") -> PASS
A45: ADDITIONAL STABILITY CALCULATIONS
A46: u_stab = Dmax / √3 | B46: =B41/SQRT(3) -> 0.0017488081 | C46: ← Uncertainty due to instability

Sheet estadisticas_robustas
A1: ROBUST STATISTICS VALIDATION - SO2 60-nmol/mol
A2: ISO 13528:2022 Section 9.4 - MADe and nIQR calculations
A4: Values (xi) | B4: |xi - median|
A5: 59.902688 | B5: =ABS(A5-B20) -> 0.01225806
A6: 59.883118 | B6: =ABS(A6-B20) -> 0.00731183
A7: 59.902903 | B7: =ABS(A7-B20) -> 0.01247312
A8: 59.880215 | B8: =ABS(A8-B20) -> 0.01021506
A9: 59.887742 | B9: =ABS(A9-B20) -> 0.00268817
A10: 59.893118 | B10: =ABS(A10-B20) -> 0.00268817
A11: 59.904194 | B11: =ABS(A11-B20) -> 0.01376344
A12: 59.885054 | B12: =ABS(A12-B20) -> 0.00537635
A13: 59.912258 | B13: =ABS(A13-B20) -> 0.02182795
A14: 59.876989 | B14: =ABS(A14-B20) -> 0.01344086
A15: 59.920108 | B15: =ABS(A15-B20) -> 0.02967742
A16: 59.882903 | B16: =ABS(A16-B20) -> 0.00752688
A18: CALCULATIONS
A19: n (count) | B19: =COUNT(A5:A16) -> 12
A20: Median | B20: =MEDIAN(A5:A16) -> 59.89043
A21: Q1 (25th percentile) | B21: =quartile.inc(A5:A16,1) -> #NAME?
A22: Q3 (75th percentile) | B22: =quartile.inc(A5:A16,3) -> #NAME?
A23: IQR (Q3 - Q1) | B23: =B22-B21 -> #NAME?
A24: nIQR = 0.7413 × IQR | B24: =0.7413*B23 -> #NAME? | C24: ← Robust SD estimator
A25: MAD (median of |xi-median|) | B25: =MEDIAN(B5:B16) -> 0.01123656
A26: MADe = 1.483 × MAD | B26: =1.483*B25 -> 0.016663818 | C26: ← Robust SD estimator
A28: COMPARISON (Classical)
A29: Mean | B29: =AVERAGE(A5:A16) -> 59.894274
A30: SD | B30: =stdev.s(A5:A16) -> #NAME?

Sheet algoritmo_a
A1: ALGORITHM A VALIDATION - SO2 60-nmol/mol
A2: ISO 13528:2022 Annex C.3 - Iterative Robust Estimation (Winsorization Method)
A4: ALGORITHM PARAMETERS
A5: p (observations) | B5: 12
A6: MAD scale factor | B6: 1.483 | C6: ← Makes MAD consistent for normal distribution
A7: Winsorization factor (1.5×s*) | B7: 1.5 | C7: ← δ = 1.5 × s* for winsorization bounds
A8: Scale adjustment factor | B8: 1.134 | C8: ← Applied to s* calculation: 1.134 × SD
A10: INPUT DATA (xi)
A11: i | B11: xi
A12: 1 | B12: 59.902688 | C12: =ABS(B12-B26) -> 0.01225806
A13: 2 | B13: 59.883118 | C13: =ABS(B13-B26) -> 0.00731183
A14: 3 | B14: 59.902903 | C14: =ABS(B14-B26) -> 0.01247312
A15: 4 | B15: 59.880215 | C15: =ABS(B15-B26) -> 0.01021506
A16: 5 | B16: 59.887742 | C16: =ABS(B16-B26) -> 0.00268817
A17: 6 | B17: 59.893118 | C17: =ABS(B17-B26) -> 0.00268817
A18: 7 | B18: 59.904194 | C18: =ABS(B18-B26) -> 0.01376344
A19: 8 | B19: 59.885054 | C19: =ABS(B19-B26) -> 0.00537635
A20: 9 | B20: 59.912258 | C20: =ABS(B20-B26) -> 0.02182795
A21: 10 | B21: 59.876989 | C21: =ABS(B21-B26) -> 0.01344086
A22: 11 | B22: 59.920108 | C22: =ABS(B22-B26) -> 0.02967742
A23: 12 | B23: 59.882903 | C23: =ABS(B23-B26) -> 0.00752688
A25: INITIAL ESTIMATES (Iteration 0)
A26: Median | B26: =MEDIAN(B12:B23) -> 59.89043
A27: MAD (median of |xi - median|) | B27: =MEDIAN(C12:C23) -> 0.01123656
A28: x*₀ = median | B28: =B26 -> 59.89043
A29: s*₀ = 1.483 × MAD | B29: =B6*B27 -> 0.016663818
A30: δ₀ = 1.5 × s*₀ | B30: =B7*B29 -> 0.024995728
A31: Lower bound = x*₀ - δ₀ | B31: =B28-B30 -> 59.865434
A32: Upper bound = x*₀ + δ₀ | B32: =B28+B30 -> 59.915426
A35: ITERATION 1 DETAIL - WINSORIZATION
A36: i | B36: xi | C36: Lower bound | D36: Upper bound | E36: xi* (winsorized) | F36: (xi* - x*₁)²
A37: 1 | B37: 59.902688 | C37: =B31 -> 59.865434 | D37: =B32 -> 59.915426 | E37: =IF(B37<B31,B31,IF(B37>B32,B32,B37)) -> 59.902688 | F37: =(E37-B49)^2 -> 7.7512474e-05
A38: 2 | B38: 59.883118 | C38: =B31 -> 59.865434 | D38: =B32 -> 59.915426 | E38: =IF(B38<B31,B31,IF(B38>B32,B32,B38)) -> 59.883118 | F38: =(E38-B49)^2 -> 0.00011590187
A39: 3 | B39: 59.902903 | C39: =B31 -> 59.865434 | D39: =B32 -> 59.915426 | E39: =IF(B39<B31,B31,IF(B39>B32,B32,B39)) -> 59.902903 | F39: =(E39-B49)^2 -> 8.1345551e-05
A40: 4 | B40: 59.880215 | C40: =B31 -> 59.865434 | D40: =B32 -> 59.915426 | E40: =IF(B40<B31,B31,IF(B40>B32,B32,B40)) -> 59.880215 | F40: =(E40-B49)^2 -> 0.00018684165
A41: 5 | B41: 59.887742 | C41: =B31 -> 59.865434 | D41: =B32 -> 59.915426 | E41: =IF(B41<B31,B31,IF(B41>B32,B32,B41)) -> 59.887742 | F41: =(E41-B49)^2 -> 3.7725554e-05
A42: 6 | B42: 59.893118 | C42: =B31 -> 59.865434 | D42: =B32 -> 59.915426 | E42: =IF(B42<B31,B31,IF(B42>B32,B32,B42)) -> 59.893118 | F42: =(E42-B49)^2 -> 5.8640851e-07
A43: 7 | B43: 59.904194 | C43: =B31 -> 59.865434 | D43: =B32 -> 59.915426 | E43: =IF(B43<B31,B31,IF(B43>B32,B32,B43)) -> 59.904194 | F43: =(E43-B49)^2 -> 0.00010628573
A44: 8 | B44: 59.885054 | C44: =B31 -> 59.865434 | D44: =B32 -> 59.915426 | E44: =IF(B44<B31,B31,IF(B44>B32,B32,B44)) -> 59.885054 | F44: =(E44-B49)^2 -> 7.7974077e-05
A45: 9 | B45: 59.912258 | C45: =B31 -> 59.865434 | D45: =B32 -> 59.915426 | E45: =IF(B45<B31,B31,IF(B45>B32,B32,B45)) -> 59.912258 | F45: =(E45-B49)^2 -> 0.00033760413
...

Sheet contaminantes
A1: MULTI-POLLUTANT ROBUST STATISTICS COMPARISON
A2: ISO 13528:2022 - Robust estimates for all pollutants at selected levels
A4: CO 4-μmol/mol (n=12)
A5: Values (xi) | C5: Statistic | D5: Value | E5: Formula
A6: 4.0283471 | C6: n | D6: =COUNT(A6:A17) -> 12
A7: 4.0217482 | C7: Median | D7: =MEDIAN(A6:A17) -> 4.0254809 | E7: MEDIAN(xi)
A8: 4.0231958 | C8: Mean | D8: =AVERAGE(A6:A17) -> 4.0245247 | E8: AVERAGE(xi)
A9: 4.0255549 | C9: SD | D9: =stdev.s(A6:A17) -> #NAME? | E9: STDEV.S(xi)
A10: 4.0280486 | C10: Q1 | D10: =quartile.inc(A6:A17,1) -> #NAME?
A11: 4.0279864 | C11: Q3 | D11: =quartile.inc(A6:A17,3) -> #NAME?
A12: 4.025818 | C12: IQR | D12: =D11-D10 -> #NAME? | E12: Q3 - Q1
A13: 4.0183974 | C13: nIQR | D13: =0.7413*D12 -> #NAME? | E13: 0.7413 × IQR
A14: 4.0265958 | C14: MADe | D14: (computed) | E14: 1.483 × median(|xi-median|)
A15: 4.0254069
A16: 4.0215946
A17: 4.0216022
A20: NO 121-nmol/mol (n=12)
A21: Values (xi) | C21: Statistic | D21: Value | E21: Formula
A22: 120.41134 | C22: n | D22: =COUNT(A22:A33) -> 12
A23: 120.3347 | C23: Median | D23: =MEDIAN(A22:A33) -> 120.34773 | E23: MEDIAN(xi)
A24: 120.34526 | C24: Mean | D24: =AVERAGE(A22:A33) -> 120.3559 | E24: AVERAGE(xi)
A25: 120.33194 | C25: SD | D25: =stdev.s(A22:A33) -> #NAME? | E25: STDEV.S(xi)
A26: 120.32763 | C26: Q1 | D26: =quartile.inc(A22:A33,1) -> #NAME?
A27: 120.36775 | C27: Q3 | D27: =quartile.inc(A22:A33,3) -> #NAME?
A28: 120.38514 | C28: IQR | D28: =D27-D26 -> #NAME? | E28: Q3 - Q1
A29: 120.33261 | C29: nIQR | D29: =0.7413*D28 -> #NAME? | E29: 0.7413 × IQR
A30: 120.3653 | C30: MADe | D30: (computed) | E30: 1.483 × median(|xi-median|)
A31: 120.33237
A32: 120.3866
A33: 120.3502
A36: NO2 60-nmol/mol (n=12)
A37: Values (xi) | C37: Statistic | D37: Value | E37: Formula
A38: 65.094264 | C38: n | D38: =COUNT(A38:A49) -> 12
A39: 64.885352 | C39: Median | D39: =MEDIAN(A38:A49) -> 64.939533 | E39: MEDIAN(xi)
A40: 64.844549 | C40: Mean | D40: =AVERAGE(A38:A49) -> 64.960698 | E40: AVERAGE(xi)
A41: 64.937703 | C41: SD | D41: =stdev.s(A38:A49) -> #NAME? | E41: STDEV.S(xi)
A42: 65.028231 | C42: Q1 | D42: =quartile.inc(A38:A49,1) -> #NAME?
A43: 65.056429 | C43: Q3 | D43: =quartile.inc(A38:A49,3) -> #NAME?
A44: 64.998813 | C44: IQR | D44: =D43-D42 -> #NAME? | E44: Q3 - Q1
A45: 64.932231 | C45: nIQR | D45: =0.7413*D44 -> #NAME? | E45: 0.7413 × IQR
...

Sheet puntuaciones
A1: PT SCORES VALIDATION
A2: ISO 13528:2022 Section 10 - Performance scores
A4: ASSIGNED VALUE & PARAMETERS (Example: SO2 60-nmol/mol)
A5: x_pt (assigned value) | B5: 59.9
A6: σ_pt (std dev for PT) | B6: 0.6
A7: u_xpt (std uncertainty of x_pt) | B7: 0.1
A8: u_hom (uncertainty from homogeneity) | B8: 0.05
A9: u_stab (uncertainty from stability) | B9: 0.03
A10: u_xpt_def (definitive uncertainty) | B10: =SQRT(B7^2+B8^2+B9^2) -> 0.11575837 | C10: ← √(u_xpt² + u_hom² + u_stab²)
A11: U_xpt (expanded uncertainty, k=2) | B11: =2*B10 -> 0.23151674
A13: PARTICIPANT RESULTS
A14: Participant | B14: x (result) | C14: u_x (std unc) | D14: U_x (exp unc) | E14: z-score | F14: z'-score | G14: ζ-score | H14: En-score | I14: z Eval | J14: En Eval
A15: Lab A | B15: 59.95 | C15: 0.15 | D15: 0.3 | E15: =(B15-$B$5)/$B$6 -> 0.083333333 | F15: =(B15-$B$5)/SQRT($B$6^2+$B$10^2) -> 0.081824403 | G15: =(B15-$B$5)/SQRT(C15^2+$B$10^2) -> 0.26388991 | H15: =(B15-$B$5)/SQRT(D15^2+$B$11^2) -> 0.13194495 | I15: =IF(ABS(E15)<=2,"Satisfactorio",IF(ABS(E15)<3,"Cuestionable","No satisfactorio")) -> Satisfactorio | J15: =IF(ABS(H15)<=1,"Satisfactorio","No satisfactorio") -> Satisfactorio
A16: Lab B | B16: 59.8 | C16: 0.2 | D16: 0.4 | E16: =(B16-$B$5)/$B$6 -> -0.16666667 | F16: =(B16-$B$5)/SQRT($B$6^2+$B$10^2) -> -0.16364881 | G16: =(B16-$B$5)/SQRT(C16^2+$B$10^2) -> -0.43274232 | H16: =(B16-$B$5)/SQRT(D16^2+$B$11^2) -> -0.21637116 | I16: =IF(ABS(E16)<=2,"Satisfactorio",IF(ABS(E16)<3,"Cuestionable","No satisfactorio")) -> Satisfactorio | J16: =IF(ABS(H16)<=1,"Satisfactorio","No satisfactorio") -> Satisfactorio
A17: Lab C | B17: 60.5 | C17: 0.1 | D17: 0.2 | E17: =(B17-$B$5)/$B$6 -> 1 | F17: =(B17-$B$5)/SQRT($B$6^2+$B$10^2) -> 0.98189284 | G17: =(B17-$B$5)/SQRT(C17^2+$B$10^2) -> 3.9223227 | H17: =(B17-$B$5)/SQRT(D17^2+$B$11^2) -> 1.9611614 | I17: =IF(ABS(E17)<=2,"Satisfactorio",IF(ABS(E17)<3,"Cuestionable","No satisfactorio")) -> Satisfactorio | J17: =IF(ABS(H17)<=1,"Satisfactorio","No satisfactorio") -> No satisfactorio
A18: Lab D | B18: 59.9 | C18: 0.25 | D18: 0.5 | E18: =(B18-$B$5)/$B$6 -> 0 | F18: =(B18-$B$5)/SQRT($B$6^2+$B$10^2) -> 0 | G18: =(B18-$B$5)/SQRT(C18^2+$B$10^2) -> 0 | H18: =(B18-$B$5)/SQRT(D18^2+$B$11^2) -> 0 | I18: =IF(ABS(E18)<=2,"Satisfactorio",IF(ABS(E18)<3,"Cuestionable","No satisfactorio")) -> Satisfactorio | J18: =IF(ABS(H18)<=1,"Satisfactorio","No satisfactorio") -> Satisfactorio
A19: Lab E | B19: 58.5 | C19: 0.3 | D19: 0.6 | E19: =(B19-$B$5)/$B$6 -> -2.3333333 | F19: =(B19-$B$5)/SQRT($B$6^2+$B$10^2) -> -2.2910833 | G19: =(B19-$B$5)/SQRT(C19^2+$B$10^2) -> -4.3537929 | H19: =(B19-$B$5)/SQRT(D19^2+$B$11^2) -> -2.1768964 | I19: =IF(ABS(E19)<=2,"Satisfactorio",IF(ABS(E19)<3,"Cuestionable","No satisfactorio")) -> Cuestionable | J19: =IF(ABS(H19)<=1,"Satisfactorio","No satisfactorio") -> No satisfactorio
A21: FORMULA REFERENCE
A22: z-score | B22: z = (x - x_pt) / σ_pt
A23: z'-score | B23: z' = (x - x_pt) / √(σ_pt² + u_xpt_def²)
A24: ζ-score (zeta) | B24: ζ = (x - x_pt) / √(u_x² + u_xpt_def²)
A25: En-score | B25: En = (x - x_pt) / √(U_x² + U_xpt²)
A26: u_xpt_def | B26: u_xpt_def = √(u_xpt² + u_hom² + u_stab²)
A28: EVALUATION CRITERIA
A29: z-score | B29: |z| ≤ 2: Satisfactorio, 2 < |z| < 3: Cuestionable, |z| ≥ 3: No satisfactorio
A30: En-score | B30: |En| ≤ 1: Satisfactorio, |En| > 1: No satisfactorio
