Workbook

Sheet README
A1: Excel con formulas validacion O3
A3: bloque | B3: contenido
A4: Combo | B4: O3_180
A5: Nivel | B5: 180-nmol/mol
A6: Analito | B6: o3
A7: Fecha de generacion | B7: 2026-05-13 19:21:28 -0500
A8: Script generador | B8: validation_1/validation/excel/validacion_o3/script_excel_formulas_validacion_o3.R
A9: Fuentes | B9: data/homogeneity - homogeneity.csv data/stability - stability.csv data/summary_n13.csv data/pt_data_n13.csv validation_1/validation/excel/validacion_o3/valores_validacion_o3.csv
A10: Convenciones | B10: Azul = dato fuente; negro = formula; verde = link interno; amarillo = control.
A11: Criterio Fase 4 | B11: Homogeneidad y estabilidad generadas con formulas y controles contra snapshot.

Sheet datos_homogeneidad
A1: sample_id | B1: sample_1 | C1: sample_2 | D1: promedio_muestra | E1: rango_absoluto | F1: abs_diff_from_xpt
A2: 1 | B2: 180.414 | C2: 180.46 | D2: =AVERAGE(B2:C2) -> 180.437 | E2: =ABS(B2-C2) -> 0.046 | F2: =ABS(C2-MEDIAN($B$2:$B$11)) -> 3.922
A3: 2 | B3: 176.452 | C3: 176.396 | D3: =AVERAGE(B3:C3) -> 176.424 | E3: =ABS(B3-C3) -> 0.056 | F3: =ABS(C3-MEDIAN($B$2:$B$11)) -> 0.142
A4: 3 | B4: 176.56 | C4: 176.377 | D4: =AVERAGE(B4:C4) -> 176.4685 | E4: =ABS(B4-C4) -> 0.183 | F4: =ABS(C4-MEDIAN($B$2:$B$11)) -> 0.161
A5: 4 | B5: 176.372 | C5: 180.242 | D5: =AVERAGE(B5:C5) -> 178.307 | E5: =ABS(B5-C5) -> 3.87 | F5: =ABS(C5-MEDIAN($B$2:$B$11)) -> 3.704
A6: 5 | B6: 180.374 | C6: 180.34 | D6: =AVERAGE(B6:C6) -> 180.357 | E6: =ABS(B6-C6) -> 0.034 | F6: =ABS(C6-MEDIAN($B$2:$B$11)) -> 3.802
A7: 6 | B7: 176.362 | C7: 180.429 | D7: =AVERAGE(B7:C7) -> 178.3955 | E7: =ABS(B7-C7) -> 4.067 | F7: =ABS(C7-MEDIAN($B$2:$B$11)) -> 3.891
A8: 7 | B8: 176.422 | C8: 176.448 | D8: =AVERAGE(B8:C8) -> 176.435 | E8: =ABS(B8-C8) -> 0.026 | F8: =ABS(C8-MEDIAN($B$2:$B$11)) -> 0.09
A9: 8 | B9: 176.516 | C9: 176.592 | D9: =AVERAGE(B9:C9) -> 176.554 | E9: =ABS(B9-C9) -> 0.076 | F9: =ABS(C9-MEDIAN($B$2:$B$11)) -> 0.054
A10: 9 | B10: 180.529 | C10: 180.353 | D10: =AVERAGE(B10:C10) -> 180.441 | E10: =ABS(B10-C10) -> 0.176 | F10: =ABS(C10-MEDIAN($B$2:$B$11)) -> 3.815
A11: 10 | B11: 180.456 | C11: 176.545 | D11: =AVERAGE(B11:C11) -> 178.5005 | E11: =ABS(B11-C11) -> 3.911 | F11: =ABS(C11-MEDIAN($B$2:$B$11)) -> 0.007

Sheet calc_homogeneidad
A1: parametro | B1: valor | C1: notas
A2: g | B2: =COUNT(datos_homogeneidad!$B$2:$B$11) -> 10 | C2: Numero de muestras.
A3: m | B3: =2 -> 2 | C3: Numero de replicas.
A4: general_mean | B4: =AVERAGE(datos_homogeneidad!$B$2:$B$11,datos_homogeneidad!$C$2:$C$11) -> 178.23195 | C4: Promedio de todos los valores.
A5: x_pt | B5: =MEDIAN(datos_homogeneidad!$B$2:$B$11) -> 176.538 | C5: Mediana de sample_1.
A6: s_x_bar_sq | B6: =VAR(datos_homogeneidad!$D$2:$D$11) -> 2.9761633 | C6: Varianza de promedios por muestra.
A7: sw | B7: =SQRT(SUMSQ(datos_homogeneidad!$E$2:$E$11)/(2*B2)) -> 1.5311864 | C7: Desviacion dentro de muestra para m = 2.
A8: ss_sq | B8: =ABS(B6-(B7^2/B3)) -> 1.8038974 | C8: Componente entre muestras sin truncamiento, usando ABS como ptcalc.
A9: ss | B9: =SQRT(B8) -> 1.3430925 | C9: Desviacion entre muestras.
A10: median_abs_diff | B10: =MEDIAN(datos_homogeneidad!$F$2:$F$11) -> 1.9325 | C10: Mediana de |sample_2 - x_pt|.
A11: MADe | B11: =1.483*B10 -> 2.8658975 | C11: 1.483 * median_abs_diff.
A12: u_sigma_pt | B12: =IFERROR(1.25*B11/SQRT(B2),0) -> 1.1328455 | C12: 1.25 * MADe / sqrt(g).
A13: Q1 | B13: =QUARTILE(datos_homogeneidad!$B$2:$B$11,1) -> 176.4295 | C13: Cuartil 25% de sample_1, type 7 equivalente.
A14: Q3 | B14: =QUARTILE(datos_homogeneidad!$B$2:$B$11,3) -> 180.404 | C14: Cuartil 75% de sample_1, type 7 equivalente.
A15: IQR | B15: =B14-B13 -> 3.9745 | C15: Q3 - Q1.
A16: nIQR | B16: =0.7413*B15 -> 2.9462968 | C16: 0.7413 * IQR.
A17: u_sigma_pt_niqr | B17: =IFERROR(1.25*B16/SQRT(B2),0) -> 1.1646261 | C17: 1.25 * nIQR / sqrt(g).
A18: criterio_made | B18: =0.3*B11 -> 0.85976925 | C18: 0.3 * MADe.
A19: criterio_niqr | B19: =0.3*B16 -> 0.88388906 | C19: 0.3 * nIQR.

Sheet resultado_homogeneidad
A1: tabla | B1: parametro | C1: app_value | D1: calculado | E1: delta_abs | F1: tolerancia | G1: estado
A2: Resumen del Estudio (Método MADe) | B2: Muestras (g) | C2: 10 | D2: =calc_homogeneidad!$B$2 -> 10 | E2: =IFERROR(ABS(D2-C2),"") -> 0 | F2: 0.0005 | G2: =IF(E2="","Pendiente",IF(E2<=F2,"OK","FALLA")) -> OK
A3: Resumen del Estudio (Método MADe) | B3: Réplicas (m) | C3: 2 | D3: =calc_homogeneidad!$B$3 -> 2 | E3: =IFERROR(ABS(D3-C3),"") -> 0 | F3: 0.0005 | G3: =IF(E3="","Pendiente",IF(E3<=F3,"OK","FALLA")) -> OK
A4: Resumen del Estudio (Método MADe) | B4: x_pt (hom_stab) | C4: 176.5380 | D4: =ROUND(calc_homogeneidad!$B$5,4) -> 176.538 | E4: =IFERROR(ABS(D4-C4),"") -> 0 | F4: 0.0005 | G4: =IF(E4="","Pendiente",IF(E4<=F4,"OK","FALLA")) -> OK
A5: Resumen del Estudio (Método MADe) | B5: Median |sample_2 - x_pt| | C5: 2.8659 | D5: =ROUND(calc_homogeneidad!$B$11,4) -> 2.8659 | E5: =IFERROR(ABS(D5-C5),"") -> 0 | F5: 0.0005 | G5: =IF(E5="","Pendiente",IF(E5<=F5,"OK","FALLA")) -> OK
A6: Resumen del Estudio (Método MADe) | B6: MADe (1.483 × median) | C6: 2.8659 | D6: =ROUND(calc_homogeneidad!$B$11,4) -> 2.8659 | E6: =IFERROR(ABS(D6-C6),"") -> 0 | F6: 0.0005 | G6: =IF(E6="","Pendiente",IF(E6<=F6,"OK","FALLA")) -> OK
A7: Resumen del Estudio (Método MADe) | B7: u_sigma_pt | C7: 1.1328 | D7: =ROUND(calc_homogeneidad!$B$12,4) -> 1.1328 | E7: =IFERROR(ABS(D7-C7),"") -> 0 | F7: 0.0005 | G7: =IF(E7="","Pendiente",IF(E7<=F7,"OK","FALLA")) -> OK
A8: Resumen del Estudio (Método nIQR) | B8: Muestras (g) | C8: 10 | D8: =calc_homogeneidad!$B$2 -> 10 | E8: =IFERROR(ABS(D8-C8),"") -> 0 | F8: 0.0005 | G8: =IF(E8="","Pendiente",IF(E8<=F8,"OK","FALLA")) -> OK
A9: Resumen del Estudio (Método nIQR) | B9: Réplicas (m) | C9: 2 | D9: =calc_homogeneidad!$B$3 -> 2 | E9: =IFERROR(ABS(D9-C9),"") -> 0 | F9: 0.0005 | G9: =IF(E9="","Pendiente",IF(E9<=F9,"OK","FALLA")) -> OK
A10: Resumen del Estudio (Método nIQR) | B10: x_pt (hom_stab) | C10: 176.5380 | D10: =ROUND(calc_homogeneidad!$B$5,4) -> 176.538 | E10: =IFERROR(ABS(D10-C10),"") -> 0 | F10: 0.0005 | G10: =IF(E10="","Pendiente",IF(E10<=F10,"OK","FALLA")) -> OK
A11: Resumen del Estudio (Método nIQR) | B11: Q1 (25%) | C11: 176.4295 | D11: =ROUND(calc_homogeneidad!$B$13,4) -> 176.4295 | E11: =IFERROR(ABS(D11-C11),"") -> 0 | F11: 0.0005 | G11: =IF(E11="","Pendiente",IF(E11<=F11,"OK","FALLA")) -> OK
A12: Resumen del Estudio (Método nIQR) | B12: Q3 (75%) | C12: 180.4040 | D12: =ROUND(calc_homogeneidad!$B$14,4) -> 180.404 | E12: =IFERROR(ABS(D12-C12),"") -> 0 | F12: 0.0005 | G12: =IF(E12="","Pendiente",IF(E12<=F12,"OK","FALLA")) -> OK
A13: Resumen del Estudio (Método nIQR) | B13: IQR (Q3 - Q1) | C13: 3.9745 | D13: =ROUND(calc_homogeneidad!$B$15,4) -> 3.9745 | E13: =IFERROR(ABS(D13-C13),"") -> 0 | F13: 0.0005 | G13: =IF(E13="","Pendiente",IF(E13<=F13,"OK","FALLA")) -> OK
A14: Resumen del Estudio (Método nIQR) | B14: nIQR (0.7413 × IQR) | C14: 2.9463 | D14: =ROUND(calc_homogeneidad!$B$16,4) -> 2.9463 | E14: =IFERROR(ABS(D14-C14),"") -> 0 | F14: 0.0005 | G14: =IF(E14="","Pendiente",IF(E14<=F14,"OK","FALLA")) -> OK
A15: Resumen del Estudio (Método nIQR) | B15: u_sigma_pt (nIQR) | C15: 1.1646 | D15: =ROUND(calc_homogeneidad!$B$17,4) -> 1.1646 | E15: =IFERROR(ABS(D15-C15),"") -> 0 | F15: 0.0005 | G15: =IF(E15="","Pendiente",IF(E15<=F15,"OK","FALLA")) -> OK

Sheet datos_estabilidad
A1: sample_id | B1: sample_1 | C1: sample_2 | D1: promedio_muestra | E1: rango_absoluto | F1: abs_diff_from_xpt
A2: 1 | B2: 180.423 | C2: 176.484 | D2: =AVERAGE(B2:C2) -> 178.4535 | E2: =ABS(B2-C2) -> 3.939 | F2: =ABS(C2-MEDIAN($B$2:$B$3)) -> 3.9325
A3: 2 | B3: 180.41 | C3: 176.491 | D3: =AVERAGE(B3:C3) -> 178.4505 | E3: =ABS(B3-C3) -> 3.919 | F3: =ABS(C3-MEDIAN($B$2:$B$3)) -> 3.9255

Sheet calc_estabilidad
A1: parametro | B1: valor | C1: notas
A2: g_stab | B2: =COUNT(datos_estabilidad!$B$2:$B$3) -> 2 | C2: Numero de muestras estabilidad.
A3: m_stab | B3: =2 -> 2 | C3: Numero de replicas estabilidad.
A4: general_mean_stab | B4: =AVERAGE(datos_estabilidad!$B$2:$B$3,datos_estabilidad!$C$2:$C$3) -> 178.452 | C4: Promedio de todos los valores de estabilidad.
A5: x_pt_stab | B5: =MEDIAN(datos_estabilidad!$B$2:$B$3) -> 180.4165 | C5: Mediana de sample_1 estabilidad.
A6: s_x_bar_sq_stab | B6: =VAR(datos_estabilidad!$D$2:$D$3) -> 4.5e-06 | C6: Varianza de promedios estabilidad.
A7: sw_stab | B7: =SQRT(SUMSQ(datos_estabilidad!$E$2:$E$3)/(2*B2)) -> 2.7782315 | C7: Desviacion dentro de muestra para m = 2.
A8: ss_sq_stab | B8: =ABS(B6-(B7^2/B3)) -> 3.8592807 | C8: Componente entre muestras estabilidad.
A9: ss_stab | B9: =SQRT(B8) -> 1.9645052 | C9: Desviacion entre muestras estabilidad.
A10: diff_hom_stab | B10: =ABS(B4-calc_homogeneidad!$B$4) -> 0.22005 | C10: |media estabilidad - media homogeneidad|.
A11: u_hom_mean | B11: =IFERROR(stdev.s(datos_homogeneidad!$B$2:$C$3)/SQRT(COUNT(datos_homogeneidad!$B$2:$C$3)),0) -> 0 | C11: STDEV.S(valores homogeneidad) / sqrt(n).
A12: u_stab_mean | B12: =IFERROR(stdev.s(datos_estabilidad!$B$2:$C$3)/SQRT(COUNT(datos_estabilidad!$B$2:$C$3)),0) -> 0 | C12: STDEV.S(valores estabilidad) / sqrt(n).
A13: criterio_made | B13: =calc_homogeneidad!$B$18 -> 0.85976925 | C13: 0.3 * MADe de homogeneidad.
A14: criterio_made_expandido | B14: =B13+2*SQRT(B11^2+B12^2) -> 0.85976925 | C14: criterio + 2 * incertidumbre de medias.
A15: criterio_niqr | B15: =calc_homogeneidad!$B$19 -> 0.88388906 | C15: 0.3 * nIQR de homogeneidad.
A16: criterio_niqr_expandido | B16: =B15+2*SQRT(B11^2+B12^2) -> 0.88388906 | C16: criterio nIQR + 2 * incertidumbre de medias.

Sheet resultado_estabilidad
A1: tabla | B1: parametro | C1: app_value | D1: calculado | E1: delta_abs | F1: tolerancia | G1: estado
A2: Resumen del Estudio (Método MADe) | B2: Muestras (g) | C2: 10 | D2: =calc_homogeneidad!$B$2 -> 10 | E2: =IFERROR(ABS(D2-C2),"") -> 0 | F2: 0.0005 | G2: =IF(E2="","Pendiente",IF(E2<=F2,"OK","FALLA")) -> OK
A3: Resumen del Estudio (Método MADe) | B3: Réplicas (m) | C3: 2 | D3: =calc_homogeneidad!$B$3 -> 2 | E3: =IFERROR(ABS(D3-C3),"") -> 0 | F3: 0.0005 | G3: =IF(E3="","Pendiente",IF(E3<=F3,"OK","FALLA")) -> OK
A4: Resumen del Estudio (Método MADe) | B4: x_pt (hom_stab) | C4: 176.5380 | D4: =ROUND(calc_homogeneidad!$B$5,4) -> 176.538 | E4: =IFERROR(ABS(D4-C4),"") -> 0 | F4: 0.0005 | G4: =IF(E4="","Pendiente",IF(E4<=F4,"OK","FALLA")) -> OK
A5: Resumen del Estudio (Método MADe) | B5: Median |sample_2 - x_pt| | C5: 2.8659 | D5: =ROUND(calc_homogeneidad!$B$11,4) -> 2.8659 | E5: =IFERROR(ABS(D5-C5),"") -> 0 | F5: 0.0005 | G5: =IF(E5="","Pendiente",IF(E5<=F5,"OK","FALLA")) -> OK
A6: Resumen del Estudio (Método MADe) | B6: MADe (1.483 × median) | C6: 2.8659 | D6: =ROUND(calc_homogeneidad!$B$11,4) -> 2.8659 | E6: =IFERROR(ABS(D6-C6),"") -> 0 | F6: 0.0005 | G6: =IF(E6="","Pendiente",IF(E6<=F6,"OK","FALLA")) -> OK
A7: Resumen del Estudio (Método MADe) | B7: u_sigma_pt | C7: 1.1328 | D7: =ROUND(calc_homogeneidad!$B$12,4) -> 1.1328 | E7: =IFERROR(ABS(D7-C7),"") -> 0 | F7: 0.0005 | G7: =IF(E7="","Pendiente",IF(E7<=F7,"OK","FALLA")) -> OK
A8: Resumen del Estudio (Método nIQR) | B8: Muestras (g) | C8: 10 | D8: =calc_homogeneidad!$B$2 -> 10 | E8: =IFERROR(ABS(D8-C8),"") -> 0 | F8: 0.0005 | G8: =IF(E8="","Pendiente",IF(E8<=F8,"OK","FALLA")) -> OK
A9: Resumen del Estudio (Método nIQR) | B9: Réplicas (m) | C9: 2 | D9: =calc_homogeneidad!$B$3 -> 2 | E9: =IFERROR(ABS(D9-C9),"") -> 0 | F9: 0.0005 | G9: =IF(E9="","Pendiente",IF(E9<=F9,"OK","FALLA")) -> OK
A10: Resumen del Estudio (Método nIQR) | B10: x_pt (hom_stab) | C10: 176.5380 | D10: =ROUND(calc_homogeneidad!$B$5,4) -> 176.538 | E10: =IFERROR(ABS(D10-C10),"") -> 0 | F10: 0.0005 | G10: =IF(E10="","Pendiente",IF(E10<=F10,"OK","FALLA")) -> OK
A11: Resumen del Estudio (Método nIQR) | B11: Q1 (25%) | C11: 176.4295 | D11: =ROUND(calc_homogeneidad!$B$13,4) -> 176.4295 | E11: =IFERROR(ABS(D11-C11),"") -> 0 | F11: 0.0005 | G11: =IF(E11="","Pendiente",IF(E11<=F11,"OK","FALLA")) -> OK
A12: Resumen del Estudio (Método nIQR) | B12: Q3 (75%) | C12: 180.4040 | D12: =ROUND(calc_homogeneidad!$B$14,4) -> 180.404 | E12: =IFERROR(ABS(D12-C12),"") -> 0 | F12: 0.0005 | G12: =IF(E12="","Pendiente",IF(E12<=F12,"OK","FALLA")) -> OK
A13: Resumen del Estudio (Método nIQR) | B13: IQR (Q3 - Q1) | C13: 3.9745 | D13: =ROUND(calc_homogeneidad!$B$15,4) -> 3.9745 | E13: =IFERROR(ABS(D13-C13),"") -> 0 | F13: 0.0005 | G13: =IF(E13="","Pendiente",IF(E13<=F13,"OK","FALLA")) -> OK
A14: Resumen del Estudio (Método nIQR) | B14: nIQR (0.7413 × IQR) | C14: 2.9463 | D14: =ROUND(calc_homogeneidad!$B$16,4) -> 2.9463 | E14: =IFERROR(ABS(D14-C14),"") -> 0 | F14: 0.0005 | G14: =IF(E14="","Pendiente",IF(E14<=F14,"OK","FALLA")) -> OK
A15: Resumen del Estudio (Método nIQR) | B15: u_sigma_pt (nIQR) | C15: 1.1646 | D15: =ROUND(calc_homogeneidad!$B$17,4) -> 1.1646 | E15: =IFERROR(ABS(D15-C15),"") -> 0 | F15: 0.0005 | G15: =IF(E15="","Pendiente",IF(E15<=F15,"OK","FALLA")) -> OK

Sheet datos_participantes
A1: participant_id | B1: pollutant | C1: level | D1: mean_value | E1: sd_value | F1: u_i | G1: u_i_check
A2: part_1 | B2: o3 | C2: 180-nmol/mol | D2: 178.72233 | E2: 1.9626667 | F2: 0.33457897 | G2: =IFERROR(F2/SQRT(3),"") -> 0.19316926
A3: part_10 | B3: o3 | C3: 180-nmol/mol | D3: 177.98167 | E3: 2 | F3: 0.41435806 | G3: =IFERROR(F3/SQRT(3),"") -> 0.23922974
A4: part_11 | B4: o3 | C4: 180-nmol/mol | D4: 179.61033 | E4: 1.3003333 | F4: 0.38076127 | G4: =IFERROR(F4/SQRT(3),"") -> 0.21983262
A5: part_12 | B5: o3 | C5: 180-nmol/mol | D5: 178.66967 | E5: 2.0056667 | F5: 0.34365895 | G5: =IFERROR(F5/SQRT(3),"") -> 0.19841159
A6: part_2 | B6: o3 | C6: 180-nmol/mol | D6: 177.849 | E6: 2 | F6: 0.14017657 | G6: =IFERROR(F6/SQRT(3),"") -> 0.080930983
A7: part_3 | B7: o3 | C7: 180-nmol/mol | D7: 178.03933 | E7: 2.0656667 | F7: 0.0079606786 | G7: =IFERROR(F7/SQRT(3),"") -> 0.0045960999
A8: part_4 | B8: o3 | C8: 180-nmol/mol | D8: 179.19767 | E8: 1.8923333 | F8: 0.23561544 | G8: =IFERROR(F8/SQRT(3),"") -> 0.13603264
A9: part_5 | B9: o3 | C9: 180-nmol/mol | D9: 178.035 | E9: 2.0266667 | F9: 0.020271398 | G9: =IFERROR(F9/SQRT(3),"") -> 0.011703697
A10: part_6 | B10: o3 | C10: 180-nmol/mol | D10: 178.15267 | E10: 1.9453333 | F10: 0.49887455 | G10: =IFERROR(F10/SQRT(3),"") -> 0.28802536
A11: part_7 | B11: o3 | C11: 180-nmol/mol | D11: 178.29067 | E11: 1.9973333 | F11: 0.35508989 | G11: =IFERROR(F11/SQRT(3),"") -> 0.20501124
A12: part_8 | B12: o3 | C12: 180-nmol/mol | D12: 177.99833 | E12: 1.923 | F12: 0.46269517 | G12: =IFERROR(F12/SQRT(3),"") -> 0.26713718
A13: part_9 | B13: o3 | C13: 180-nmol/mol | D13: 178.26533 | E13: 2.064 | F13: 0.23697248 | G13: =IFERROR(F13/SQRT(3),"") -> 0.13681613

Sheet datos_referencia
A1: pollutant | B1: level | C1: participant_id | D1: mean_value | E1: sd_value | F1: x_pt_ref | G1: u_ref_check
A2: o3 | B2: 180-nmol/mol | C2: ref | D2: 177.614 | E2: 1.781 | F2: =AVERAGE(D2) -> 177.614 | G2: =IFERROR(stdev.s(D2)/SQRT(COUNT(D2)),"")

Sheet algoritmo_A_iteraciones
A1: metrica | B1: valor
A2: x0_mediana | B2: =MEDIAN(algoritmo_A_iteraciones!B11:B22) -> 178.209
A3: s0_MADe | B3: =1.483*MEDIAN(C11:C22) -> 0.324777
A4: tolerancia | B4: 1e-10
A5: n_participantes | B5: =COUNT(algoritmo_A_iteraciones!B11:B22) -> 12
A6: iteracion_final | B6: =IFERROR(MATCH(1,AC27:AC76,0),50) -> 14
A7: x_final | B7: =INDEX(S27:S76,$B$6) -> 178.34844
A8: s_final | B8: =INDEX(T27:T76,$B$6) -> 0.49401672
A9: n_winsorizadas_final | B9: =--(INDEX(G27:G76,$B$6)<>$B$11)+--(INDEX(H27:H76,$B$6)<>$B$12)+--(INDEX(I27:I76,$B$6)<>$B$13)+--(INDEX(J27:J76,$B$6)<>$B$14)+--(INDEX(K27:K76,$B$6)<>$B$15)+--(INDEX(L27:L76,$B$6)<>$B$16)+--(INDEX(M27:M76,$B$6)<>$B$17)+--(INDEX(N27:N76,$B$6)<>$B$18)+--(INDEX(O27:O76,$B$6)<>$B$19)+--(INDEX(P27:P76,$B$6)<>$B$20)+--(INDEX(Q27:Q76,$B$6)<>$B$21)+--(INDEX(R27:R76,$B$6)<>$B$22) -> 2
A10: participant_id | B10: xi | C10: abs_xi_x0
A11: part_1 | B11: 178.72233 | C11: =ABS(B11-$B$2) -> 0.51333333
A12: part_10 | B12: 177.98167 | C12: =ABS(B12-$B$2) -> 0.22733333
A13: part_11 | B13: 179.61033 | C13: =ABS(B13-$B$2) -> 1.4013333
A14: part_12 | B14: 178.66967 | C14: =ABS(B14-$B$2) -> 0.46066667
A15: part_2 | B15: 177.849 | C15: =ABS(B15-$B$2) -> 0.36
A16: part_3 | B16: 178.03933 | C16: =ABS(B16-$B$2) -> 0.16966667
A17: part_4 | B17: 179.19767 | C17: =ABS(B17-$B$2) -> 0.98866667
A18: part_5 | B18: 178.035 | C18: =ABS(B18-$B$2) -> 0.174
A19: part_6 | B19: 178.15267 | C19: =ABS(B19-$B$2) -> 0.056333333
A20: part_7 | B20: 178.29067 | C20: =ABS(B20-$B$2) -> 0.081666667
A21: part_8 | B21: 177.99833 | C21: =ABS(B21-$B$2) -> 0.21066667
A22: part_9 | B22: 178.26533 | C22: =ABS(B22-$B$2) -> 0.056333333
A26: iteracion | B26: x_prev | C26: s_prev | D26: delta | E26: limite_inf | F26: limite_sup | G26: w_part_1 | H26: w_part_10 | I26: w_part_11 | J26: w_part_12 | K26: w_part_2 | L26: w_part_3 | M26: w_part_4 | N26: w_part_5 | O26: w_part_6 | P26: w_part_7 | Q26: w_part_8 | R26: w_part_9 | S26: x_new | T26: s_new | U26: delta_x | V26: delta_s | W26: sig3_x_prev | X26: sig3_s_prev | Y26: sig3_x_new | Z26: sig3_s_new | AA26: signif3_converged | AB26: guardia_numerica | AC26: fila_seleccionada
A27: 1 | B27: =$B$2 -> 178.209 | C27: =$B$3 -> 0.324777 | D27: =1.5*C27 -> 0.4871655 | E27: =B27-D27 -> 177.72183 | F27: =B27+D27 -> 178.69617 | G27: =MIN(MAX($B$11,$E27),$F27) -> 178.69617 | H27: =MIN(MAX($B$12,$E27),$F27) -> 177.98167 | I27: =MIN(MAX($B$13,$E27),$F27) -> 178.69617 | J27: =MIN(MAX($B$14,$E27),$F27) -> 178.66967 | K27: =MIN(MAX($B$15,$E27),$F27) -> 177.849 | L27: =MIN(MAX($B$16,$E27),$F27) -> 178.03933 | M27: =MIN(MAX($B$17,$E27),$F27) -> 178.69617 | N27: =MIN(MAX($B$18,$E27),$F27) -> 178.035 | O27: =MIN(MAX($B$19,$E27),$F27) -> 178.15267 | P27: =MIN(MAX($B$20,$E27),$F27) -> 178.29067 | Q27: =MIN(MAX($B$21,$E27),$F27) -> 177.99833 | R27: =MIN(MAX($B$22,$E27),$F27) -> 178.26533 | S27: =AVERAGE(G27:R27) -> 178.28085 | T27: =1.134*STDEV(G27:R27) -> 0.36825261 | U27: =ABS(S27-B27) -> 0.071846931 | V27: =ABS(T27-C27) -> 0.043475609 | W27: =IF(OR(NOT(ISNUMBER(B27)),B27=0),B27,ROUND(B27,MAX(3-1-INT(LOG10(ABS(B27))),0))) -> 178 | X27: =IF(OR(NOT(ISNUMBER(C27)),C27=0),C27,ROUND(C27,MAX(3-1-INT(LOG10(ABS(C27))),0))) -> 0.325 | Y27: =IF(OR(NOT(ISNUMBER(S27)),S27=0),S27,ROUND(S27,MAX(3-1-INT(LOG10(ABS(S27))),0))) -> 178 | Z27: =IF(OR(NOT(ISNUMBER(T27)),T27=0),T27,ROUND(T27,MAX(3-1-INT(LOG10(ABS(T27))),0))) -> 0.368 | AA27: =IF(AND(Y27=W27,Z27=X27),1,0) -> 0 | AB27: =IF(AND(U27<$B$4,V27<$B$4),1,0) -> 0 | AC27: =IF(OR(AA27=1,AB27=1),1,0) -> 0
A28: 2 | B28: =S27 -> 178.28085 | C28: =T27 -> 0.36825261 | D28: =1.5*C28 -> 0.55237891 | E28: =B28-D28 -> 177.72847 | F28: =B28+D28 -> 178.83323 | G28: =MIN(MAX($B$11,$E28),$F28) -> 178.72233 | H28: =MIN(MAX($B$12,$E28),$F28) -> 177.98167 | I28: =MIN(MAX($B$13,$E28),$F28) -> 178.83323 | J28: =MIN(MAX($B$14,$E28),$F28) -> 178.66967 | K28: =MIN(MAX($B$15,$E28),$F28) -> 177.849 | L28: =MIN(MAX($B$16,$E28),$F28) -> 178.03933 | M28: =MIN(MAX($B$17,$E28),$F28) -> 178.83323 | N28: =MIN(MAX($B$18,$E28),$F28) -> 178.035 | O28: =MIN(MAX($B$19,$E28),$F28) -> 178.15267 | P28: =MIN(MAX($B$20,$E28),$F28) -> 178.29067 | Q28: =MIN(MAX($B$21,$E28),$F28) -> 177.99833 | R28: =MIN(MAX($B$22,$E28),$F28) -> 178.26533 | S28: =AVERAGE(G28:R28) -> 178.30587 | T28: =1.134*STDEV(G28:R28) -> 0.41032126 | U28: =ABS(S28-B28) -> 0.025024044 | V28: =ABS(T28-C28) -> 0.042068656 | W28: =IF(OR(NOT(ISNUMBER(B28)),B28=0),B28,ROUND(B28,MAX(3-1-INT(LOG10(ABS(B28))),0))) -> 178 | X28: =IF(OR(NOT(ISNUMBER(C28)),C28=0),C28,ROUND(C28,MAX(3-1-INT(LOG10(ABS(C28))),0))) -> 0.368 | Y28: =IF(OR(NOT(ISNUMBER(S28)),S28=0),S28,ROUND(S28,MAX(3-1-INT(LOG10(ABS(S28))),0))) -> 178 | Z28: =IF(OR(NOT(ISNUMBER(T28)),T28=0),T28,ROUND(T28,MAX(3-1-INT(LOG10(ABS(T28))),0))) -> 0.41 | AA28: =IF(AND(Y28=W28,Z28=X28),1,0) -> 0 | AB28: =IF(AND(U28<$B$4,V28<$B$4),1,0) -> 0 | AC28: =IF(OR(AA28=1,AB28=1),1,0) -> 0
A29: 3 | B29: =S28 -> 178.30587 | C29: =T28 -> 0.41032126 | D29: =1.5*C29 -> 0.6154819 | E29: =B29-D29 -> 177.69039 | F29: =B29+D29 -> 178.92135 | G29: =MIN(MAX($B$11,$E29),$F29) -> 178.72233 | H29: =MIN(MAX($B$12,$E29),$F29) -> 177.98167 | I29: =MIN(MAX($B$13,$E29),$F29) -> 178.92135 | J29: =MIN(MAX($B$14,$E29),$F29) -> 178.66967 | K29: =MIN(MAX($B$15,$E29),$F29) -> 177.849 | L29: =MIN(MAX($B$16,$E29),$F29) -> 178.03933 | M29: =MIN(MAX($B$17,$E29),$F29) -> 178.92135 | N29: =MIN(MAX($B$18,$E29),$F29) -> 178.035 | O29: =MIN(MAX($B$19,$E29),$F29) -> 178.15267 | P29: =MIN(MAX($B$20,$E29),$F29) -> 178.29067 | Q29: =MIN(MAX($B$21,$E29),$F29) -> 177.99833 | R29: =MIN(MAX($B$22,$E29),$F29) -> 178.26533 | S29: =AVERAGE(G29:R29) -> 178.32056 | T29: =1.134*STDEV(G29:R29) -> 0.4377317 | U29: =ABS(S29-B29) -> 0.014687838 | V29: =ABS(T29-C29) -> 0.027410439 | W29: =IF(OR(NOT(ISNUMBER(B29)),B29=0),B29,ROUND(B29,MAX(3-1-INT(LOG10(ABS(B29))),0))) -> 178 | X29: =IF(OR(NOT(ISNUMBER(C29)),C29=0),C29,ROUND(C29,MAX(3-1-INT(LOG10(ABS(C29))),0))) -> 0.41 | Y29: =IF(OR(NOT(ISNUMBER(S29)),S29=0),S29,ROUND(S29,MAX(3-1-INT(LOG10(ABS(S29))),0))) -> 178 | Z29: =IF(OR(NOT(ISNUMBER(T29)),T29=0),T29,ROUND(T29,MAX(3-1-INT(LOG10(ABS(T29))),0))) -> 0.438 | AA29: =IF(AND(Y29=W29,Z29=X29),1,0) -> 0 | AB29: =IF(AND(U29<$B$4,V29<$B$4),1,0) -> 0 | AC29: =IF(OR(AA29=1,AB29=1),1,0) -> 0
A30: 4 | B30: =S29 -> 178.32056 | C30: =T29 -> 0.4377317 | D30: =1.5*C30 -> 0.65659756 | E30: =B30-D30 -> 177.66396 | F30: =B30+D30 -> 178.97716 | G30: =MIN(MAX($B$11,$E30),$F30) -> 178.72233 | H30: =MIN(MAX($B$12,$E30),$F30) -> 177.98167 | I30: =MIN(MAX($B$13,$E30),$F30) -> 178.97716 | J30: =MIN(MAX($B$14,$E30),$F30) -> 178.66967 | K30: =MIN(MAX($B$15,$E30),$F30) -> 177.849 | L30: =MIN(MAX($B$16,$E30),$F30) -> 178.03933 | M30: =MIN(MAX($B$17,$E30),$F30) -> 178.97716 | N30: =MIN(MAX($B$18,$E30),$F30) -> 178.035 | O30: =MIN(MAX($B$19,$E30),$F30) -> 178.15267 | P30: =MIN(MAX($B$20,$E30),$F30) -> 178.29067 | Q30: =MIN(MAX($B$21,$E30),$F30) -> 177.99833 | R30: =MIN(MAX($B$22,$E30),$F30) -> 178.26533 | S30: =AVERAGE(G30:R30) -> 178.32986 | T30: =1.134*STDEV(G30:R30) -> 0.45595331 | U30: =ABS(S30-B30) -> 0.0093005828 | V30: =ABS(T30-C30) -> 0.018221605 | W30: =IF(OR(NOT(ISNUMBER(B30)),B30=0),B30,ROUND(B30,MAX(3-1-INT(LOG10(ABS(B30))),0))) -> 178 | X30: =IF(OR(NOT(ISNUMBER(C30)),C30=0),C30,ROUND(C30,MAX(3-1-INT(LOG10(ABS(C30))),0))) -> 0.438 | Y30: =IF(OR(NOT(ISNUMBER(S30)),S30=0),S30,ROUND(S30,MAX(3-1-INT(LOG10(ABS(S30))),0))) -> 178 | Z30: =IF(OR(NOT(ISNUMBER(T30)),T30=0),T30,ROUND(T30,MAX(3-1-INT(LOG10(ABS(T30))),0))) -> 0.456 | AA30: =IF(AND(Y30=W30,Z30=X30),1,0) -> 0 | AB30: =IF(AND(U30<$B$4,V30<$B$4),1,0) -> 0 | AC30: =IF(OR(AA30=1,AB30=1),1,0) -> 0
A31: 5 | B31: =S30 -> 178.32986 | C31: =T30 -> 0.45595331 | D31: =1.5*C31 -> 0.68392996 | E31: =B31-D31 -> 177.64593 | F31: =B31+D31 -> 179.01379 | G31: =MIN(MAX($B$11,$E31),$F31) -> 178.72233 | H31: =MIN(MAX($B$12,$E31),$F31) -> 177.98167 | I31: =MIN(MAX($B$13,$E31),$F31) -> 179.01379 | J31: =MIN(MAX($B$14,$E31),$F31) -> 178.66967 | K31: =MIN(MAX($B$15,$E31),$F31) -> 177.849 | L31: =MIN(MAX($B$16,$E31),$F31) -> 178.03933 | M31: =MIN(MAX($B$17,$E31),$F31) -> 179.01379 | N31: =MIN(MAX($B$18,$E31),$F31) -> 178.035 | O31: =MIN(MAX($B$19,$E31),$F31) -> 178.15267 | P31: =MIN(MAX($B$20,$E31),$F31) -> 178.29067 | Q31: =MIN(MAX($B$21,$E31),$F31) -> 177.99833 | R31: =MIN(MAX($B$22,$E31),$F31) -> 178.26533 | S31: =AVERAGE(G31:R31) -> 178.33596 | T31: =1.134*STDEV(G31:R31) -> 0.46823424 | U31: =ABS(S31-B31) -> 0.0061054983 | V31: =ABS(T31-C31) -> 0.012280933 | W31: =IF(OR(NOT(ISNUMBER(B31)),B31=0),B31,ROUND(B31,MAX(3-1-INT(LOG10(ABS(B31))),0))) -> 178 | X31: =IF(OR(NOT(ISNUMBER(C31)),C31=0),C31,ROUND(C31,MAX(3-1-INT(LOG10(ABS(C31))),0))) -> 0.456 | Y31: =IF(OR(NOT(ISNUMBER(S31)),S31=0),S31,ROUND(S31,MAX(3-1-INT(LOG10(ABS(S31))),0))) -> 178 | Z31: =IF(OR(NOT(ISNUMBER(T31)),T31=0),T31,ROUND(T31,MAX(3-1-INT(LOG10(ABS(T31))),0))) -> 0.468 | AA31: =IF(AND(Y31=W31,Z31=X31),1,0) -> 0 | AB31: =IF(AND(U31<$B$4,V31<$B$4),1,0) -> 0 | AC31: =IF(OR(AA31=1,AB31=1),1,0) -> 0
A32: 6 | B32: =S31 -> 178.33596 | C32: =T31 -> 0.46823424 | D32: =1.5*C32 -> 0.70235136 | E32: =B32-D32 -> 177.63361 | F32: =B32+D32 -> 179.03832 | G32: =MIN(MAX($B$11,$E32),$F32) -> 178.72233 | H32: =MIN(MAX($B$12,$E32),$F32) -> 177.98167 | I32: =MIN(MAX($B$13,$E32),$F32) -> 179.03832 | J32: =MIN(MAX($B$14,$E32),$F32) -> 178.66967 | K32: =MIN(MAX($B$15,$E32),$F32) -> 177.849 | L32: =MIN(MAX($B$16,$E32),$F32) -> 178.03933 | M32: =MIN(MAX($B$17,$E32),$F32) -> 179.03832 | N32: =MIN(MAX($B$18,$E32),$F32) -> 178.035 | O32: =MIN(MAX($B$19,$E32),$F32) -> 178.15267 | P32: =MIN(MAX($B$20,$E32),$F32) -> 178.29067 | Q32: =MIN(MAX($B$21,$E32),$F32) -> 177.99833 | R32: =MIN(MAX($B$22,$E32),$F32) -> 178.26533 | S32: =AVERAGE(G32:R32) -> 178.34005 | T32: =1.134*STDEV(G32:R32) -> 0.47658648 | U32: =ABS(S32-B32) -> 0.0040878162 | V32: =ABS(T32-C32) -> 0.0083522375 | W32: =IF(OR(NOT(ISNUMBER(B32)),B32=0),B32,ROUND(B32,MAX(3-1-INT(LOG10(ABS(B32))),0))) -> 178 | X32: =IF(OR(NOT(ISNUMBER(C32)),C32=0),C32,ROUND(C32,MAX(3-1-INT(LOG10(ABS(C32))),0))) -> 0.468 | Y32: =IF(OR(NOT(ISNUMBER(S32)),S32=0),S32,ROUND(S32,MAX(3-1-INT(LOG10(ABS(S32))),0))) -> 178 | Z32: =IF(OR(NOT(ISNUMBER(T32)),T32=0),T32,ROUND(T32,MAX(3-1-INT(LOG10(ABS(T32))),0))) -> 0.477 | AA32: =IF(AND(Y32=W32,Z32=X32),1,0) -> 0 | AB32: =IF(AND(U32<$B$4,V32<$B$4),1,0) -> 0 | AC32: =IF(OR(AA32=1,AB32=1),1,0) -> 0
A33: 7 | B33: =S32 -> 178.34005 | C33: =T32 -> 0.47658648 | D33: =1.5*C33 -> 0.71487972 | E33: =B33-D33 -> 177.62517 | F33: =B33+D33 -> 179.05493 | G33: =MIN(MAX($B$11,$E33),$F33) -> 178.72233 | H33: =MIN(MAX($B$12,$E33),$F33) -> 177.98167 | I33: =MIN(MAX($B$13,$E33),$F33) -> 179.05493 | J33: =MIN(MAX($B$14,$E33),$F33) -> 178.66967 | K33: =MIN(MAX($B$15,$E33),$F33) -> 177.849 | L33: =MIN(MAX($B$16,$E33),$F33) -> 178.03933 | M33: =MIN(MAX($B$17,$E33),$F33) -> 179.05493 | N33: =MIN(MAX($B$18,$E33),$F33) -> 178.035 | O33: =MIN(MAX($B$19,$E33),$F33) -> 178.15267 | P33: =MIN(MAX($B$20,$E33),$F33) -> 178.29067 | Q33: =MIN(MAX($B$21,$E33),$F33) -> 177.99833 | R33: =MIN(MAX($B$22,$E33),$F33) -> 178.26533 | S33: =AVERAGE(G33:R33) -> 178.34282 | T33: =1.134*STDEV(G33:R33) -> 0.48230075 | U33: =ABS(S33-B33) -> 0.0027693621 | V33: =ABS(T33-C33) -> 0.005714275 | W33: =IF(OR(NOT(ISNUMBER(B33)),B33=0),B33,ROUND(B33,MAX(3-1-INT(LOG10(ABS(B33))),0))) -> 178 | X33: =IF(OR(NOT(ISNUMBER(C33)),C33=0),C33,ROUND(C33,MAX(3-1-INT(LOG10(ABS(C33))),0))) -> 0.477 | Y33: =IF(OR(NOT(ISNUMBER(S33)),S33=0),S33,ROUND(S33,MAX(3-1-INT(LOG10(ABS(S33))),0))) -> 178 | Z33: =IF(OR(NOT(ISNUMBER(T33)),T33=0),T33,ROUND(T33,MAX(3-1-INT(LOG10(ABS(T33))),0))) -> 0.482 | AA33: =IF(AND(Y33=W33,Z33=X33),1,0) -> 0 | AB33: =IF(AND(U33<$B$4,V33<$B$4),1,0) -> 0 | AC33: =IF(OR(AA33=1,AB33=1),1,0) -> 0
A34: 8 | B34: =S33 -> 178.34282 | C34: =T33 -> 0.48230075 | D34: =1.5*C34 -> 0.72345113 | E34: =B34-D34 -> 177.61937 | F34: =B34+D34 -> 179.06627 | G34: =MIN(MAX($B$11,$E34),$F34) -> 178.72233 | H34: =MIN(MAX($B$12,$E34),$F34) -> 177.98167 | I34: =MIN(MAX($B$13,$E34),$F34) -> 179.06627 | J34: =MIN(MAX($B$14,$E34),$F34) -> 178.66967 | K34: =MIN(MAX($B$15,$E34),$F34) -> 177.849 | L34: =MIN(MAX($B$16,$E34),$F34) -> 178.03933 | M34: =MIN(MAX($B$17,$E34),$F34) -> 179.06627 | N34: =MIN(MAX($B$18,$E34),$F34) -> 178.035 | O34: =MIN(MAX($B$19,$E34),$F34) -> 178.15267 | P34: =MIN(MAX($B$20,$E34),$F34) -> 178.29067 | Q34: =MIN(MAX($B$21,$E34),$F34) -> 177.99833 | R34: =MIN(MAX($B$22,$E34),$F34) -> 178.26533 | S34: =AVERAGE(G34:R34) -> 178.34471 | T34: =1.134*STDEV(G34:R34) -> 0.4862258 | U34: =ABS(S34-B34) -> 0.0018901291 | V34: =ABS(T34-C34) -> 0.0039250412 | W34: =IF(OR(NOT(ISNUMBER(B34)),B34=0),B34,ROUND(B34,MAX(3-1-INT(LOG10(ABS(B34))),0))) -> 178 | X34: =IF(OR(NOT(ISNUMBER(C34)),C34=0),C34,ROUND(C34,MAX(3-1-INT(LOG10(ABS(C34))),0))) -> 0.482 | Y34: =IF(OR(NOT(ISNUMBER(S34)),S34=0),S34,ROUND(S34,MAX(3-1-INT(LOG10(ABS(S34))),0))) -> 178 | Z34: =IF(OR(NOT(ISNUMBER(T34)),T34=0),T34,ROUND(T34,MAX(3-1-INT(LOG10(ABS(T34))),0))) -> 0.486 | AA34: =IF(AND(Y34=W34,Z34=X34),1,0) -> 0 | AB34: =IF(AND(U34<$B$4,V34<$B$4),1,0) -> 0 | AC34: =IF(OR(AA34=1,AB34=1),1,0) -> 0
A35: 9 | B35: =S34 -> 178.34471 | C35: =T34 -> 0.4862258 | D35: =1.5*C35 -> 0.72933869 | E35: =B35-D35 -> 177.61537 | F35: =B35+D35 -> 179.07405 | G35: =MIN(MAX($B$11,$E35),$F35) -> 178.72233 | H35: =MIN(MAX($B$12,$E35),$F35) -> 177.98167 | I35: =MIN(MAX($B$13,$E35),$F35) -> 179.07405 | J35: =MIN(MAX($B$14,$E35),$F35) -> 178.66967 | K35: =MIN(MAX($B$15,$E35),$F35) -> 177.849 | L35: =MIN(MAX($B$16,$E35),$F35) -> 178.03933 | M35: =MIN(MAX($B$17,$E35),$F35) -> 179.07405 | N35: =MIN(MAX($B$18,$E35),$F35) -> 178.035 | O35: =MIN(MAX($B$19,$E35),$F35) -> 178.15267 | P35: =MIN(MAX($B$20,$E35),$F35) -> 178.29067 | Q35: =MIN(MAX($B$21,$E35),$F35) -> 177.99833 | R35: =MIN(MAX($B$22,$E35),$F35) -> 178.26533 | S35: =AVERAGE(G35:R35) -> 178.34601 | T35: =1.134*STDEV(G35:R35) -> 0.48892907 | U35: =ABS(S35-B35) -> 0.0012962818 | V35: =ABS(T35-C35) -> 0.0027032718 | W35: =IF(OR(NOT(ISNUMBER(B35)),B35=0),B35,ROUND(B35,MAX(3-1-INT(LOG10(ABS(B35))),0))) -> 178 | X35: =IF(OR(NOT(ISNUMBER(C35)),C35=0),C35,ROUND(C35,MAX(3-1-INT(LOG10(ABS(C35))),0))) -> 0.486 | Y35: =IF(OR(NOT(ISNUMBER(S35)),S35=0),S35,ROUND(S35,MAX(3-1-INT(LOG10(ABS(S35))),0))) -> 178 | Z35: =IF(OR(NOT(ISNUMBER(T35)),T35=0),T35,ROUND(T35,MAX(3-1-INT(LOG10(ABS(T35))),0))) -> 0.489 | AA35: =IF(AND(Y35=W35,Z35=X35),1,0) -> 0 | AB35: =IF(AND(U35<$B$4,V35<$B$4),1,0) -> 0 | AC35: =IF(OR(AA35=1,AB35=1),1,0) -> 0
A36: 10 | B36: =S35 -> 178.34601 | C36: =T35 -> 0.48892907 | D36: =1.5*C36 -> 0.7333936 | E36: =B36-D36 -> 177.61261 | F36: =B36+D36 -> 179.0794 | G36: =MIN(MAX($B$11,$E36),$F36) -> 178.72233 | H36: =MIN(MAX($B$12,$E36),$F36) -> 177.98167 | I36: =MIN(MAX($B$13,$E36),$F36) -> 179.0794 | J36: =MIN(MAX($B$14,$E36),$F36) -> 178.66967 | K36: =MIN(MAX($B$15,$E36),$F36) -> 177.849 | L36: =MIN(MAX($B$16,$E36),$F36) -> 178.03933 | M36: =MIN(MAX($B$17,$E36),$F36) -> 179.0794 | N36: =MIN(MAX($B$18,$E36),$F36) -> 178.035 | O36: =MIN(MAX($B$19,$E36),$F36) -> 178.15267 | P36: =MIN(MAX($B$20,$E36),$F36) -> 178.29067 | Q36: =MIN(MAX($B$21,$E36),$F36) -> 177.99833 | R36: =MIN(MAX($B$22,$E36),$F36) -> 178.26533 | S36: =AVERAGE(G36:R36) -> 178.3469 | T36: =1.134*STDEV(G36:R36) -> 0.49079427 | U36: =ABS(S36-B36) -> 0.00089186491 | V36: =ABS(T36-C36) -> 0.0018651982 | W36: =IF(OR(NOT(ISNUMBER(B36)),B36=0),B36,ROUND(B36,MAX(3-1-INT(LOG10(ABS(B36))),0))) -> 178 | X36: =IF(OR(NOT(ISNUMBER(C36)),C36=0),C36,ROUND(C36,MAX(3-1-INT(LOG10(ABS(C36))),0))) -> 0.489 | Y36: =IF(OR(NOT(ISNUMBER(S36)),S36=0),S36,ROUND(S36,MAX(3-1-INT(LOG10(ABS(S36))),0))) -> 178 | Z36: =IF(OR(NOT(ISNUMBER(T36)),T36=0),T36,ROUND(T36,MAX(3-1-INT(LOG10(ABS(T36))),0))) -> 0.491 | AA36: =IF(AND(Y36=W36,Z36=X36),1,0) -> 0 | AB36: =IF(AND(U36<$B$4,V36<$B$4),1,0) -> 0 | AC36: =IF(OR(AA36=1,AB36=1),1,0) -> 0
A37: 11 | B37: =S36 -> 178.3469 | C37: =T36 -> 0.49079427 | D37: =1.5*C37 -> 0.7361914 | E37: =B37-D37 -> 177.61071 | F37: =B37+D37 -> 179.08309 | G37: =MIN(MAX($B$11,$E37),$F37) -> 178.72233 | H37: =MIN(MAX($B$12,$E37),$F37) -> 177.98167 | I37: =MIN(MAX($B$13,$E37),$F37) -> 179.08309 | J37: =MIN(MAX($B$14,$E37),$F37) -> 178.66967 | K37: =MIN(MAX($B$15,$E37),$F37) -> 177.849 | L37: =MIN(MAX($B$16,$E37),$F37) -> 178.03933 | M37: =MIN(MAX($B$17,$E37),$F37) -> 179.08309 | N37: =MIN(MAX($B$18,$E37),$F37) -> 178.035 | O37: =MIN(MAX($B$19,$E37),$F37) -> 178.15267 | P37: =MIN(MAX($B$20,$E37),$F37) -> 178.29067 | Q37: =MIN(MAX($B$21,$E37),$F37) -> 177.99833 | R37: =MIN(MAX($B$22,$E37),$F37) -> 178.26533 | S37: =AVERAGE(G37:R37) -> 178.34752 | T37: =1.134*STDEV(G37:R37) -> 0.49208281 | U37: =ABS(S37-B37) -> 0.0006149437 | V37: =ABS(T37-C37) -> 0.0012885462 | W37: =IF(OR(NOT(ISNUMBER(B37)),B37=0),B37,ROUND(B37,MAX(3-1-INT(LOG10(ABS(B37))),0))) -> 178 | X37: =IF(OR(NOT(ISNUMBER(C37)),C37=0),C37,ROUND(C37,MAX(3-1-INT(LOG10(ABS(C37))),0))) -> 0.491 | Y37: =IF(OR(NOT(ISNUMBER(S37)),S37=0),S37,ROUND(S37,MAX(3-1-INT(LOG10(ABS(S37))),0))) -> 178 | Z37: =IF(OR(NOT(ISNUMBER(T37)),T37=0),T37,ROUND(T37,MAX(3-1-INT(LOG10(ABS(T37))),0))) -> 0.492 | AA37: =IF(AND(Y37=W37,Z37=X37),1,0) -> 0 | AB37: =IF(AND(U37<$B$4,V37<$B$4),1,0) -> 0 | AC37: =IF(OR(AA37=1,AB37=1),1,0) -> 0
A38: 12 | B38: =S37 -> 178.34752 | C38: =T37 -> 0.49208281 | D38: =1.5*C38 -> 0.73812422 | E38: =B38-D38 -> 177.60939 | F38: =B38+D38 -> 179.08564 | G38: =MIN(MAX($B$11,$E38),$F38) -> 178.72233 | H38: =MIN(MAX($B$12,$E38),$F38) -> 177.98167 | I38: =MIN(MAX($B$13,$E38),$F38) -> 179.08564 | J38: =MIN(MAX($B$14,$E38),$F38) -> 178.66967 | K38: =MIN(MAX($B$15,$E38),$F38) -> 177.849 | L38: =MIN(MAX($B$16,$E38),$F38) -> 178.03933 | M38: =MIN(MAX($B$17,$E38),$F38) -> 179.08564 | N38: =MIN(MAX($B$18,$E38),$F38) -> 178.035 | O38: =MIN(MAX($B$19,$E38),$F38) -> 178.15267 | P38: =MIN(MAX($B$20,$E38),$F38) -> 178.29067 | Q38: =MIN(MAX($B$21,$E38),$F38) -> 177.99833 | R38: =MIN(MAX($B$22,$E38),$F38) -> 178.26533 | S38: =AVERAGE(G38:R38) -> 178.34794 | T38: =1.134*STDEV(G38:R38) -> 0.49297375 | U38: =ABS(S38-B38) -> 0.00042462718 | V38: =ABS(T38-C38) -> 0.00089093376 | W38: =IF(OR(NOT(ISNUMBER(B38)),B38=0),B38,ROUND(B38,MAX(3-1-INT(LOG10(ABS(B38))),0))) -> 178 | X38: =IF(OR(NOT(ISNUMBER(C38)),C38=0),C38,ROUND(C38,MAX(3-1-INT(LOG10(ABS(C38))),0))) -> 0.492 | Y38: =IF(OR(NOT(ISNUMBER(S38)),S38=0),S38,ROUND(S38,MAX(3-1-INT(LOG10(ABS(S38))),0))) -> 178 | Z38: =IF(OR(NOT(ISNUMBER(T38)),T38=0),T38,ROUND(T38,MAX(3-1-INT(LOG10(ABS(T38))),0))) -> 0.493 | AA38: =IF(AND(Y38=W38,Z38=X38),1,0) -> 0 | AB38: =IF(AND(U38<$B$4,V38<$B$4),1,0) -> 0 | AC38: =IF(OR(AA38=1,AB38=1),1,0) -> 0
A39: 13 | B39: =S38 -> 178.34794 | C39: =T38 -> 0.49297375 | D39: =1.5*C39 -> 0.73946062 | E39: =B39-D39 -> 177.60848 | F39: =B39+D39 -> 179.0874 | G39: =MIN(MAX($B$11,$E39),$F39) -> 178.72233 | H39: =MIN(MAX($B$12,$E39),$F39) -> 177.98167 | I39: =MIN(MAX($B$13,$E39),$F39) -> 179.0874 | J39: =MIN(MAX($B$14,$E39),$F39) -> 178.66967 | K39: =MIN(MAX($B$15,$E39),$F39) -> 177.849 | L39: =MIN(MAX($B$16,$E39),$F39) -> 178.03933 | M39: =MIN(MAX($B$17,$E39),$F39) -> 179.0874 | N39: =MIN(MAX($B$18,$E39),$F39) -> 178.035 | O39: =MIN(MAX($B$19,$E39),$F39) -> 178.15267 | P39: =MIN(MAX($B$20,$E39),$F39) -> 178.29067 | Q39: =MIN(MAX($B$21,$E39),$F39) -> 177.99833 | R39: =MIN(MAX($B$22,$E39),$F39) -> 178.26533 | S39: =AVERAGE(G39:R39) -> 178.34823 | T39: =1.134*STDEV(G39:R39) -> 0.49359012 | U39: =ABS(S39-B39) -> 0.00029350464 | V39: =ABS(T39-C39) -> 0.00061637601 | W39: =IF(OR(NOT(ISNUMBER(B39)),B39=0),B39,ROUND(B39,MAX(3-1-INT(LOG10(ABS(B39))),0))) -> 178 | X39: =IF(OR(NOT(ISNUMBER(C39)),C39=0),C39,ROUND(C39,MAX(3-1-INT(LOG10(ABS(C39))),0))) -> 0.493 | Y39: =IF(OR(NOT(ISNUMBER(S39)),S39=0),S39,ROUND(S39,MAX(3-1-INT(LOG10(ABS(S39))),0))) -> 178 | Z39: =IF(OR(NOT(ISNUMBER(T39)),T39=0),T39,ROUND(T39,MAX(3-1-INT(LOG10(ABS(T39))),0))) -> 0.494 | AA39: =IF(AND(Y39=W39,Z39=X39),1,0) -> 0 | AB39: =IF(AND(U39<$B$4,V39<$B$4),1,0) -> 0 | AC39: =IF(OR(AA39=1,AB39=1),1,0) -> 0
... A76: 50 | B76: =S75 -> 178.34889 | C76: =T75 -> 0.49497736 | D76: =1.5*C76 -> 0.74246604 | E76: =B76-D76 -> 177.60643 | F76: =B76+D76 -> 179.09136 | G76: =MIN(MAX($B$11,$E76),$F76) -> 178.72233 | H76: =MIN(MAX($B$12,$E76),$F76) -> 177.98167 | I76: =MIN(MAX($B$13,$E76),$F76) -> 179.09136 | J76: =MIN(MAX($B$14,$E76),$F76) -> 178.66967 | K76: =MIN(MAX($B$15,$E76),$F76) -> 177.849 | L76: =MIN(MAX($B$16,$E76),$F76) -> 178.03933 | M76: =MIN(MAX($B$17,$E76),$F76) -> 179.09136 | N76: =MIN(MAX($B$18,$E76),$F76) -> 178.035 | O76: =MIN(MAX($B$19,$E76),$F76) -> 178.15267 | P76: =MIN(MAX($B$20,$E76),$F76) -> 178.29067 | Q76: =MIN(MAX($B$21,$E76),$F76) -> 177.99833 | R76: =MIN(MAX($B$22,$E76),$F76) -> 178.26533 | S76: =AVERAGE(G76:R76) -> 178.34889 | T76: =1.134*STDEV(G76:R76) -> 0.49497736 | U76: =ABS(S76-B76) -> 3.6857273e-10 | V76: =ABS(T76-C76) -> 7.7563433e-10 | W76: =IF(OR(NOT(ISNUMBER(B76)),B76=0),B76,ROUND(B76,MAX(3-1-INT(LOG10(ABS(B76))),0))) -> 178 | X76: =IF(OR(NOT(ISNUMBER(C76)),C76=0),C76,ROUND(C76,MAX(3-1-INT(LOG10(ABS(C76))),0))) -> 0.495 | Y76: =IF(OR(NOT(ISNUMBER(S76)),S76=0),S76,ROUND(S76,MAX(3-1-INT(LOG10(ABS(S76))),0))) -> 178 | Z76: =IF(OR(NOT(ISNUMBER(T76)),T76=0),T76,ROUND(T76,MAX(3-1-INT(LOG10(ABS(T76))),0))) -> 0.495 | AA76: =IF(AND(Y76=W76,Z76=X76),1,0) -> 1 | AB76: =IF(AND(U76<$B$4,V76<$B$4),1,0) -> 0 | AC76: =IF(OR(AA76=1,AB76=1),1,0) -> 1

Sheet valor_asignado
A1: method_key | B1: method | C1: x_pt | D1: sigma_pt | E1: u_xpt | F1: u_hom | G1: u_stab | H1: u_xpt_def | I1: U_xpt | J1: n_participants | K1: estado
A2: ref | B2: Referencia (1) | C2: =datos_referencia!$D$2 -> 177.614 | D2: =0.02*datos_referencia!$D$2+1 -> 4.55228 | E2: =datos_referencia!$E$2 -> 1.781 | F2: =calc_homogeneidad!$B$9 -> 1.3430925 | G2: =calc_estabilidad!$B$10/SQRT(3) -> 0.12704593 | H2: =SQRT(E2^2+F2^2+G2^2) -> 2.2342782 | I2: =2*H2 -> 4.4685564 | J2: =COUNT(datos_participantes!$D:$D) -> 12 | K2: =IF(SUM(ABS(C2-validacion_snapshot!$K$30),ABS(D2-validacion_snapshot!$L$30),ABS(E2-validacion_snapshot!$M$30),ABS(F2-validacion_snapshot!$N$30),ABS(G2-validacion_snapshot!$O$30),ABS(H2-validacion_snapshot!$P$30),ABS(I2-validacion_snapshot!$Q$30),ABS(J2-validacion_snapshot!$R$30))<=0.00000001,"OK","FALLA") -> OK
A3: consensus_ma | B3: Consenso MADe (2a) | C3: =MEDIAN(datos_participantes!$D$2:$D$13) -> 178.209 | D3: =algoritmo_A_iteraciones!$B$3 -> 0.324777 | E3: =1.25*D3/SQRT(COUNT(datos_participantes!$D:$D)) -> 0.11719381 | F3: =calc_homogeneidad!$B$9 -> 1.3430925 | G3: =calc_estabilidad!$B$10/SQRT(3) -> 0.12704593 | H3: =SQRT(E3^2+F3^2+G3^2) -> 1.3541686 | I3: =2*H3 -> 2.7083371 | J3: =COUNT(datos_participantes!$D:$D) -> 12 | K3: =IF(SUM(ABS(C3-validacion_snapshot!$K$31),ABS(D3-validacion_snapshot!$L$31),ABS(E3-validacion_snapshot!$M$31),ABS(F3-validacion_snapshot!$N$31),ABS(G3-validacion_snapshot!$O$31),ABS(H3-validacion_snapshot!$P$31),ABS(I3-validacion_snapshot!$Q$31),ABS(J3-validacion_snapshot!$R$31))<=0.00000001,"OK","FALLA") -> OK
A4: consensus_niqr | B4: Consenso nIQR (2b) | C4: =MEDIAN(datos_participantes!$D$2:$D$13) -> 178.209 | D4: =0.7413*(QUARTILE(datos_participantes!$D$2:$D$13,3)-QUARTILE(datos_participantes!$D$2:$D$13,1)) -> 0.4870341 | E4: =1.25*D4/SQRT(COUNT(datos_participantes!$D:$D)) -> 0.17574329 | F4: =calc_homogeneidad!$B$9 -> 1.3430925 | G4: =calc_estabilidad!$B$10/SQRT(3) -> 0.12704593 | H4: =SQRT(E4^2+F4^2+G4^2) -> 1.3604866 | I4: =2*H4 -> 2.7209732 | J4: =COUNT(datos_participantes!$D:$D) -> 12 | K4: =IF(SUM(ABS(C4-validacion_snapshot!$K$32),ABS(D4-validacion_snapshot!$L$32),ABS(E4-validacion_snapshot!$M$32),ABS(F4-validacion_snapshot!$N$32),ABS(G4-validacion_snapshot!$O$32),ABS(H4-validacion_snapshot!$P$32),ABS(I4-validacion_snapshot!$Q$32),ABS(J4-validacion_snapshot!$R$32))<=0.00000001,"OK","FALLA") -> OK
A5: algo | B5: Algoritmo A (3) | C5: =algoritmo_A_iteraciones!$B$7 -> 178.34844 | D5: =algoritmo_A_iteraciones!$B$8 -> 0.49401672 | E5: =1.25*D5/SQRT(COUNT(datos_participantes!$D:$D)) -> 0.17826293 | F5: =calc_homogeneidad!$B$9 -> 1.3430925 | G5: =calc_estabilidad!$B$10/SQRT(3) -> 0.12704593 | H5: =SQRT(E5^2+F5^2+G5^2) -> 1.3608144 | I5: =2*H5 -> 2.7216288 | J5: =COUNT(datos_participantes!$D:$D) -> 12 | K5: =IF(SUM(ABS(C5-validacion_snapshot!$K$33),ABS(D5-validacion_snapshot!$L$33),ABS(E5-validacion_snapshot!$M$33),ABS(F5-validacion_snapshot!$N$33),ABS(G5-validacion_snapshot!$O$33),ABS(H5-validacion_snapshot!$P$33),ABS(I5-validacion_snapshot!$Q$33),ABS(J5-validacion_snapshot!$R$33))<=0.00000001,"OK","FALLA") -> OK
A6: expert | B6: Expertos (4) | C6: =datos_referencia!$D$2 -> 177.614 | D6: =0.02*datos_referencia!$D$2+1 -> 4.55228 | E6: =datos_referencia!$E$2 -> 1.781 | F6: =calc_homogeneidad!$B$9 -> 1.3430925 | G6: =calc_estabilidad!$B$10/SQRT(3) -> 0.12704593 | H6: =SQRT(E6^2+F6^2+G6^2) -> 2.2342782 | I6: =2*H6 -> 4.4685564 | J6: =COUNT(datos_participantes!$D:$D) -> 12 | K6: =IF(SUM(ABS(C6-validacion_snapshot!$K$34),ABS(D6-validacion_snapshot!$L$34),ABS(E6-validacion_snapshot!$M$34),ABS(F6-validacion_snapshot!$N$34),ABS(G6-validacion_snapshot!$O$34),ABS(H6-validacion_snapshot!$P$34),ABS(I6-validacion_snapshot!$Q$34),ABS(J6-validacion_snapshot!$R$34))<=0.00000001,"OK","FALLA") -> OK

Sheet algoritmo_A
A1: bloque | B1: parametro | C1: app_value | D1: calculado | E1: estado
A2: Algoritmo A | B2: Analito | C2: O3 | D2: ="O3" -> O3 | E2: =IF(IFERROR(ABS(D2-validacion_snapshot!$H$35)<=0.0005,D2=validacion_snapshot!$H$35),"OK","FALLA") -> OK
A3: Algoritmo A | B3: Esquema (n) | C3: 13 | D3: =13 -> 13 | E3: =IF(IFERROR(ABS(D3-validacion_snapshot!$H$36)<=0.0005,D3=validacion_snapshot!$H$36),"OK","FALLA") -> OK
A4: Algoritmo A | B4: Nivel | C4: 180-nmol/mol | D4: ="180-nmol/mol" -> 180-nmol/mol | E4: =IF(IFERROR(ABS(D4-validacion_snapshot!$H$37)<=0.0005,D4=validacion_snapshot!$H$37),"OK","FALLA") -> OK
A5: Algoritmo A | B5: n participantes | C5: 12 | D5: =algoritmo_A_iteraciones!$B$5 -> 12 | E5: =IF(IFERROR(ABS(D5-validacion_snapshot!$H$38)<=0.0005,D5=validacion_snapshot!$H$38),"OK","FALLA") -> OK
A6: Algoritmo A | B6: x*0 = mediana | C6: 178.2090 | D6: =ROUND(algoritmo_A_iteraciones!$B$2,4) -> 178.209 | E6: =IF(IFERROR(ABS(D6-validacion_snapshot!$H$39)<=0.0005,D6=validacion_snapshot!$H$39),"OK","FALLA") -> OK
A7: Algoritmo A | B7: s*0 = MADe | C7: 0.3248 | D7: =ROUND(algoritmo_A_iteraciones!$B$3,4) -> 0.3248 | E7: =IF(IFERROR(ABS(D7-validacion_snapshot!$H$40)<=0.0005,D7=validacion_snapshot!$H$40),"OK","FALLA") -> OK
A8: Algoritmo A | B8: x* (valor asignado) | C8: 178.3484 | D8: =ROUND(algoritmo_A_iteraciones!$B$7,4) -> 178.3484 | E8: =IF(IFERROR(ABS(D8-validacion_snapshot!$H$41)<=0.0005,D8=validacion_snapshot!$H$41),"OK","FALLA") -> OK
A9: Algoritmo A | B9: s* (desviación robusta) | C9: 0.4940 | D9: =ROUND(algoritmo_A_iteraciones!$B$8,4) -> 0.494 | E9: =IF(IFERROR(ABS(D9-validacion_snapshot!$H$42)<=0.0005,D9=validacion_snapshot!$H$42),"OK","FALLA") -> OK
A10: Algoritmo A | B10: Observaciones winzorizadas | C10: 2 | D10: =algoritmo_A_iteraciones!$B$9 -> 2 | E10: =IF(IFERROR(ABS(D10-validacion_snapshot!$H$43)<=0.0005,D10=validacion_snapshot!$H$43),"OK","FALLA") -> OK
A11: Algoritmo A | B11: Observaciones totales | C11: 12 | D11: =algoritmo_A_iteraciones!$B$5 -> 12 | E11: =IF(IFERROR(ABS(D11-validacion_snapshot!$H$44)<=0.0005,D11=validacion_snapshot!$H$44),"OK","FALLA") -> OK
A12: Algoritmo A | B12: n_iteraciones | C12: 14 | D12: =algoritmo_A_iteraciones!$B$6 -> 14 | E12: =IF(IFERROR(ABS(D12-validacion_snapshot!$H$45)<=0.0005,D12=validacion_snapshot!$H$45),"OK","FALLA") -> OK
A13: Algoritmo A | B13: criterio | C13: 3 cifras significativas | D13: ="3 cifras significativas" -> 3 cifras significativas | E13: =IF(IFERROR(ABS(D13-validacion_snapshot!$H$46)<=0.0005,D13=validacion_snapshot!$H$46),"OK","FALLA") -> OK
A14: Algoritmo A | B14: guardia_numérica | C14: 0.0000000001 | D14: =TEXT(algoritmo_A_iteraciones!$B$4,"0.0000000000") -> 0.0000000001 | E14: =IF(IFERROR(ABS(D14-validacion_snapshot!$H$47)<=0.0005,D14=validacion_snapshot!$H$47),"OK","FALLA") -> OK
A15: Algoritmo A | B15: primera_iteración_3ra_cifra | C15: 14 | D15: =algoritmo_A_iteraciones!$B$6 -> 14 | E15: =IF(IFERROR(ABS(D15-validacion_snapshot!$H$48)<=0.0005,D15=validacion_snapshot!$H$48),"OK","FALLA") -> OK

Sheet puntajes_EA
A1: method_key | B1: method | C1: participant_id | D1: result | E1: u_xi | F1: z_score | G1: z_score_eval | H1: z_prime_score | I1: z_prime_score_eval | J1: zeta_score | K1: zeta_score_eval | L1: En_score | M1: En_score_eval | N1: estado
B2: Referencia (1) | C2: part_1 | D2: =INDEX(datos_participantes!$D:$D,MATCH(C2,datos_participantes!$A:$A,0)) -> 178.72233 | E2: =INDEX(datos_participantes!$F:$F,MATCH(C2,datos_participantes!$A:$A,0)) -> 0.33457897 | F2: =IF(OR(NOT(ISNUMBER(D2)),NOT(ISNUMBER(INDEX(valor_asignado!$C:$C,MATCH(B2,valor_asignado!$B:$B,0)))),NOT(ISNUMBER(INDEX(valor_asignado!$D:$D,MATCH(B2,valor_asignado!$B:$B,0)))),INDEX(valor_asignado!$D:$D,MATCH(B2,valor_asignado!$B:$B,0))=0),"",(D2-INDEX(valor_asignado!$C:$C,MATCH(B2,valor_asignado!$B:$B,0)))/INDEX(valor_asignado!$D:$D,MATCH(B2,valor_asignado!$B:$B,0))) -> 0.24346774 | G2: =IF(F2="","N/A",IF(ABS(F2)<=2,"Satisfactorio",IF(ABS(F2)<3,"Cuestionable","No satisfactorio"))) -> Satisfactorio | H2: =IF(OR(NOT(ISNUMBER(D2)),NOT(ISNUMBER(INDEX(valor_asignado!$C:$C,MATCH(B2,valor_asignado!$B:$B,0)))),NOT(ISNUMBER(SQRT(INDEX(valor_asignado!$D:$D,MATCH(B2,valor_asignado!$B:$B,0))^2+INDEX(valor_asignado!$H:$H,MATCH(B2,valor_asignado!$B:$B,0))^2))),SQRT(INDEX(valor_asignado!$D:$D,MATCH(B2,valor_asignado!$B:$B,0))^2+INDEX(valor_asignado!$H:$H,MATCH(B2,valor_asignado!$B:$B,0))^2)=0),"",(D2-INDEX(valor_asignado!$C:$C,MATCH(B2,valor_asignado!$B:$B,0)))/SQRT(INDEX(valor_asignado!$D:$D,MATCH(B2,valor_asignado!$B:$B,0))^2+INDEX(valor_asignado!$H:$H,MATCH(B2,valor_asignado!$B:$B,0))^2)) -> 0.21856217 | I2: =IF(H2="","N/A",IF(ABS(H2)<=2,"Satisfactorio",IF(ABS(H2)<3,"Cuestionable","No satisfactorio"))) -> Satisfactorio | J2: =IF(OR(NOT(ISNUMBER(D2)),NOT(ISNUMBER(INDEX(valor_asignado!$C:$C,MATCH(B2,valor_asignado!$B:$B,0)))),NOT(ISNUMBER(SQRT(E2^2+INDEX(valor_asignado!$H:$H,MATCH(B2,valor_asignado!$B:$B,0))^2))),SQRT(E2^2+INDEX(valor_asignado!$H:$H,MATCH(B2,valor_asignado!$B:$B,0))^2)=0),"",(D2-INDEX(valor_asignado!$C:$C,MATCH(B2,valor_asignado!$B:$B,0)))/SQRT(E2^2+INDEX(valor_asignado!$H:$H,MATCH(B2,valor_asignado!$B:$B,0))^2)) -> 0.49058868 | K2: =IF(J2="","N/A",IF(ABS(J2)<=2,"Satisfactorio",IF(ABS(J2)<3,"Cuestionable","No satisfactorio"))) -> Satisfactorio | L2: =IF(OR(NOT(ISNUMBER(D2)),NOT(ISNUMBER(INDEX(valor_asignado!$C:$C,MATCH(B2,valor_asignado!$B:$B,0)))),NOT(ISNUMBER(SQRT((2*E2)^2+(2*INDEX(valor_asignado!$H:$H,MATCH(B2,valor_asignado!$B:$B,0)))^2))),SQRT((2*E2)^2+(2*INDEX(valor_asignado!$H:$H,MATCH(B2,valor_asignado!$B:$B,0)))^2)=0),"",(D2-INDEX(valor_asignado!$C:$C,MATCH(B2,valor_asignado!$B:$B,0)))/SQRT((2*E2)^2+(2*INDEX(valor_asignado!$H:$H,MATCH(B2,valor_asignado!$B:$B,0)))^2)) -> 0.24529434 | M2: =IF(L2="","N/A",IF(ABS(L2)<=1,"Satisfactorio","No satisfactorio")) -> Satisfactorio | N2: =IF(AND(SUM(IF(AND(D2="",validacion_snapshot!$U$49=""),0,IFERROR(ABS(D2-validacion_snapshot!$U$49),1E+099)),IF(AND(E2="",validacion_snapshot!$V$49=""),0,IFERROR(ABS(E2-validacion_snapshot!$V$49),1E+099)),IF(AND(F2="",validacion_snapshot!$W$49=""),0,IFERROR(ABS(F2-validacion_snapshot!$W$49),1E+099)),IF(AND(H2="",validacion_snapshot!$Y$49=""),0,IFERROR(ABS(H2-validacion_snapshot!$Y$49),1E+099)),IF(AND(J2="",validacion_snapshot!$AA$49=""),0,IFERROR(ABS(J2-validacion_snapshot!$AA$49),1E+099)),IF(AND(L2="",validacion_snapshot!$AC$49=""),0,IFERROR(ABS(L2-validacion_snapshot!$AC$49),1E+099)))<=0.00000001,G2=validacion_snapshot!$X$49,I2=validacion_snapshot!$Z$49,K2=validacion_snapshot!$AB$49,M2=validacion_snapshot!$AD$49),"OK","FALLA") -> OK
B3: Referencia (1) | C3: part_10 | D3: =INDEX(datos_participantes!$D:$D,MATCH(C3,datos_participantes!$A:$A,0)) -> 177.98167 | E3: =INDEX(datos_participantes!$F:$F,MATCH(C3,datos_participantes!$A:$A,0)) -> 0.41435806 | F3: =IF(OR(NOT(ISNUMBER(D3)),NOT(ISNUMBER(INDEX(valor_asignado!$C:$C,MATCH(B3,valor_asignado!$B:$B,0)))),NOT(ISNUMBER(INDEX(valor_asignado!$D:$D,MATCH(B3,valor_asignado!$B:$B,0)))),INDEX(valor_asignado!$D:$D,MATCH(B3,valor_asignado!$B:$B,0))=0),"",(D3-INDEX(valor_asignado!$C:$C,MATCH(B3,valor_asignado!$B:$B,0)))/INDEX(valor_asignado!$D:$D,MATCH(B3,valor_asignado!$B:$B,0))) -> 0.080765389 | G3: =IF(F3="","N/A",IF(ABS(F3)<=2,"Satisfactorio",IF(ABS(F3)<3,"Cuestionable","No satisfactorio"))) -> Satisfactorio | H3: =IF(OR(NOT(ISNUMBER(D3)),NOT(ISNUMBER(INDEX(valor_asignado!$C:$C,MATCH(B3,valor_asignado!$B:$B,0)))),NOT(ISNUMBER(SQRT(INDEX(valor_asignado!$D:$D,MATCH(B3,valor_asignado!$B:$B,0))^2+INDEX(valor_asignado!$H:$H,MATCH(B3,valor_asignado!$B:$B,0))^2))),SQRT(INDEX(valor_asignado!$D:$D,MATCH(B3,valor_asignado!$B:$B,0))^2+INDEX(valor_asignado!$H:$H,MATCH(B3,valor_asignado!$B:$B,0))^2)=0),"",(D3-INDEX(valor_asignado!$C:$C,MATCH(B3,valor_asignado!$B:$B,0)))/SQRT(INDEX(valor_asignado!$D:$D,MATCH(B3,valor_asignado!$B:$B,0))^2+INDEX(valor_asignado!$H:$H,MATCH(B3,valor_asignado!$B:$B,0))^2)) -> 0.072503482 | I3: =IF(H3="","N/A",IF(ABS(H3)<=2,"Satisfactorio",IF(ABS(H3)<3,"Cuestionable","No satisfactorio"))) -> Satisfactorio | J3: =IF(OR(NOT(ISNUMBER(D3)),NOT(ISNUMBER(INDEX(valor_asignado!$C:$C,MATCH(B3,valor_asignado!$B:$B,0)))),NOT(ISNUMBER(SQRT(E3^2+INDEX(valor_asignado!$H:$H,MATCH(B3,valor_asignado!$B:$B,0))^2))),SQRT(E3^2+INDEX(valor_asignado!$H:$H,MATCH(B3,valor_asignado!$B:$B,0))^2)=0),"",(D3-INDEX(valor_asignado!$C:$C,MATCH(B3,valor_asignado!$B:$B,0)))/SQRT(E3^2+INDEX(valor_asignado!$H:$H,MATCH(B3,valor_asignado!$B:$B,0))^2)) -> 0.16179836 | K3: =IF(J3="","N/A",IF(ABS(J3)<=2,"Satisfactorio",IF(ABS(J3)<3,"Cuestionable","No satisfactorio"))) -> Satisfactorio | L3: =IF(OR(NOT(ISNUMBER(D3)),NOT(ISNUMBER(INDEX(valor_asignado!$C:$C,MATCH(B3,valor_asignado!$B:$B,0)))),NOT(ISNUMBER(SQRT((2*E3)^2+(2*INDEX(valor_asignado!$H:$H,MATCH(B3,valor_asignado!$B:$B,0)))^2))),SQRT((2*E3)^2+(2*INDEX(valor_asignado!$H:$H,MATCH(B3,valor_asignado!$B:$B,0)))^2)=0),"",(D3-INDEX(valor_asignado!$C:$C,MATCH(B3,valor_asignado!$B:$B,0)))/SQRT((2*E3)^2+(2*INDEX(valor_asignado!$H:$H,MATCH(B3,valor_asignado!$B:$B,0)))^2)) -> 0.080899178 | M3: =IF(L3="","N/A",IF(ABS(L3)<=1,"Satisfactorio","No satisfactorio")) -> Satisfactorio | N3: =IF(AND(SUM(IF(AND(D3="",validacion_snapshot!$U$50=""),0,IFERROR(ABS(D3-validacion_snapshot!$U$50),1E+099)),IF(AND(E3="",validacion_snapshot!$V$50=""),0,IFERROR(ABS(E3-validacion_snapshot!$V$50),1E+099)),IF(AND(F3="",validacion_snapshot!$W$50=""),0,IFERROR(ABS(F3-validacion_snapshot!$W$50),1E+099)),IF(AND(H3="",validacion_snapshot!$Y$50=""),0,IFERROR(ABS(H3-validacion_snapshot!$Y$50),1E+099)),IF(AND(J3="",validacion_snapshot!$AA$50=""),0,IFERROR(ABS(J3-validacion_snapshot!$AA$50),1E+099)),IF(AND(L3="",validacion_snapshot!$AC$50=""),0,IFERROR(ABS(L3-validacion_snapshot!$AC$50),1E+099)))<=0.00000001,G3=validacion_snapshot!$X$50,I3=validacion_snapshot!$Z$50,K3=validacion_snapshot!$AB$50,M3=validacion_snapshot!$AD$50),"OK","FALLA") -> OK
B4: Referencia (1) | C4: part_11 | D4: =INDEX(datos_participantes!$D:$D,MATCH(C4,datos_participantes!$A:$A,0)) -> 179.61033 | E4: =INDEX(datos_participantes!$F:$F,MATCH(C4,datos_participantes!$A:$A,0)) -> 0.38076127 | F4: =IF(OR(NOT(ISNUMBER(D4)),NOT(ISNUMBER(INDEX(valor_asignado!$C:$C,MATCH(B4,valor_asignado!$B:$B,0)))),NOT(ISNUMBER(INDEX(valor_asignado!$D:$D,MATCH(B4,valor_asignado!$B:$B,0)))),INDEX(valor_asignado!$D:$D,MATCH(B4,valor_asignado!$B:$B,0))=0),"",(D4-INDEX(valor_asignado!$C:$C,MATCH(B4,valor_asignado!$B:$B,0)))/INDEX(valor_asignado!$D:$D,MATCH(B4,valor_asignado!$B:$B,0))) -> 0.43853483 | G4: =IF(F4="","N/A",IF(ABS(F4)<=2,"Satisfactorio",IF(ABS(F4)<3,"Cuestionable","No satisfactorio"))) -> Satisfactorio | H4: =IF(OR(NOT(ISNUMBER(D4)),NOT(ISNUMBER(INDEX(valor_asignado!$C:$C,MATCH(B4,valor_asignado!$B:$B,0)))),NOT(ISNUMBER(SQRT(INDEX(valor_asignado!$D:$D,MATCH(B4,valor_asignado!$B:$B,0))^2+INDEX(valor_asignado!$H:$H,MATCH(B4,valor_asignado!$B:$B,0))^2))),SQRT(INDEX(valor_asignado!$D:$D,MATCH(B4,valor_asignado!$B:$B,0))^2+INDEX(valor_asignado!$H:$H,MATCH(B4,valor_asignado!$B:$B,0))^2)=0),"",(D4-INDEX(valor_asignado!$C:$C,MATCH(B4,valor_asignado!$B:$B,0)))/SQRT(INDEX(valor_asignado!$D:$D,MATCH(B4,valor_asignado!$B:$B,0))^2+INDEX(valor_asignado!$H:$H,MATCH(B4,valor_asignado!$B:$B,0))^2)) -> 0.39367484 | I4: =IF(H4="","N/A",IF(ABS(H4)<=2,"Satisfactorio",IF(ABS(H4)<3,"Cuestionable","No satisfactorio"))) -> Satisfactorio | J4: =IF(OR(NOT(ISNUMBER(D4)),NOT(ISNUMBER(INDEX(valor_asignado!$C:$C,MATCH(B4,valor_asignado!$B:$B,0)))),NOT(ISNUMBER(SQRT(E4^2+INDEX(valor_asignado!$H:$H,MATCH(B4,valor_asignado!$B:$B,0))^2))),SQRT(E4^2+INDEX(valor_asignado!$H:$H,MATCH(B4,valor_asignado!$B:$B,0))^2)=0),"",(D4-INDEX(valor_asignado!$C:$C,MATCH(B4,valor_asignado!$B:$B,0)))/SQRT(E4^2+INDEX(valor_asignado!$H:$H,MATCH(B4,valor_asignado!$B:$B,0))^2)) -> 0.88080383 | K4: =IF(J4="","N/A",IF(ABS(J4)<=2,"Satisfactorio",IF(ABS(J4)<3,"Cuestionable","No satisfactorio"))) -> Satisfactorio | L4: =IF(OR(NOT(ISNUMBER(D4)),NOT(ISNUMBER(INDEX(valor_asignado!$C:$C,MATCH(B4,valor_asignado!$B:$B,0)))),NOT(ISNUMBER(SQRT((2*E4)^2+(2*INDEX(valor_asignado!$H:$H,MATCH(B4,valor_asignado!$B:$B,0)))^2))),SQRT((2*E4)^2+(2*INDEX(valor_asignado!$H:$H,MATCH(B4,valor_asignado!$B:$B,0)))^2)=0),"",(D4-INDEX(valor_asignado!$C:$C,MATCH(B4,valor_asignado!$B:$B,0)))/SQRT((2*E4)^2+(2*INDEX(valor_asignado!$H:$H,MATCH(B4,valor_asignado!$B:$B,0)))^2)) -> 0.44040192 | M4: =IF(L4="","N/A",IF(ABS(L4)<=1,"Satisfactorio","No satisfactorio")) -> Satisfactorio | N4: =IF(AND(SUM(IF(AND(D4="",validacion_snapshot!$U$51=""),0,IFERROR(ABS(D4-validacion_snapshot!$U$51),1E+099)),IF(AND(E4="",validacion_snapshot!$V$51=""),0,IFERROR(ABS(E4-validacion_snapshot!$V$51),1E+099)),IF(AND(F4="",validacion_snapshot!$W$51=""),0,IFERROR(ABS(F4-validacion_snapshot!$W$51),1E+099)),IF(AND(H4="",validacion_snapshot!$Y$51=""),0,IFERROR(ABS(H4-validacion_snapshot!$Y$51),1E+099)),IF(AND(J4="",validacion_snapshot!$AA$51=""),0,IFERROR(ABS(J4-validacion_snapshot!$AA$51),1E+099)),IF(AND(L4="",validacion_snapshot!$AC$51=""),0,IFERROR(ABS(L4-validacion_snapshot!$AC$51),1E+099)))<=0.00000001,G4=validacion_snapshot!$X$51,I4=validacion_snapshot!$Z$51,K4=validacion_snapshot!$AB$51,M4=validacion_snapshot!$AD$51),"OK","FALLA") -> OK
B5: Referencia (1) | C5: part_12 | D5: =INDEX(datos_participantes!$D:$D,MATCH(C5,datos_participantes!$A:$A,0)) -> 178.66967 | E5: =INDEX(datos_participantes!$F:$F,MATCH(C5,datos_participantes!$A:$A,0)) -> 0.34365895 | F5: =IF(OR(NOT(ISNUMBER(D5)),NOT(ISNUMBER(INDEX(valor_asignado!$C:$C,MATCH(B5,valor_asignado!$B:$B,0)))),NOT(ISNUMBER(INDEX(valor_asignado!$D:$D,MATCH(B5,valor_asignado!$B:$B,0)))),INDEX(valor_asignado!$D:$D,MATCH(B5,valor_asignado!$B:$B,0))=0),"",(D5-INDEX(valor_asignado!$C:$C,MATCH(B5,valor_asignado!$B:$B,0)))/INDEX(valor_asignado!$D:$D,MATCH(B5,valor_asignado!$B:$B,0))) -> 0.23189845 | G5: =IF(F5="","N/A",IF(ABS(F5)<=2,"Satisfactorio",IF(ABS(F5)<3,"Cuestionable","No satisfactorio"))) -> Satisfactorio | H5: =IF(OR(NOT(ISNUMBER(D5)),NOT(ISNUMBER(INDEX(valor_asignado!$C:$C,MATCH(B5,valor_asignado!$B:$B,0)))),NOT(ISNUMBER(SQRT(INDEX(valor_asignado!$D:$D,MATCH(B5,valor_asignado!$B:$B,0))^2+INDEX(valor_asignado!$H:$H,MATCH(B5,valor_asignado!$B:$B,0))^2))),SQRT(INDEX(valor_asignado!$D:$D,MATCH(B5,valor_asignado!$B:$B,0))^2+INDEX(valor_asignado!$H:$H,MATCH(B5,valor_asignado!$B:$B,0))^2)=0),"",(D5-INDEX(valor_asignado!$C:$C,MATCH(B5,valor_asignado!$B:$B,0)))/SQRT(INDEX(valor_asignado!$D:$D,MATCH(B5,valor_asignado!$B:$B,0))^2+INDEX(valor_asignado!$H:$H,MATCH(B5,valor_asignado!$B:$B,0))^2)) -> 0.20817636 | I5: =IF(H5="","N/A",IF(ABS(H5)<=2,"Satisfactorio",IF(ABS(H5)<3,"Cuestionable","No satisfactorio"))) -> Satisfactorio | J5: =IF(OR(NOT(ISNUMBER(D5)),NOT(ISNUMBER(INDEX(valor_asignado!$C:$C,MATCH(B5,valor_asignado!$B:$B,0)))),NOT(ISNUMBER(SQRT(E5^2+INDEX(valor_asignado!$H:$H,MATCH(B5,valor_asignado!$B:$B,0))^2))),SQRT(E5^2+INDEX(valor_asignado!$H:$H,MATCH(B5,valor_asignado!$B:$B,0))^2)=0),"",(D5-INDEX(valor_asignado!$C:$C,MATCH(B5,valor_asignado!$B:$B,0)))/SQRT(E5^2+INDEX(valor_asignado!$H:$H,MATCH(B5,valor_asignado!$B:$B,0))^2)) -> 0.46699484 | K5: =IF(J5="","N/A",IF(ABS(J5)<=2,"Satisfactorio",IF(ABS(J5)<3,"Cuestionable","No satisfactorio"))) -> Satisfactorio | L5: =IF(OR(NOT(ISNUMBER(D5)),NOT(ISNUMBER(INDEX(valor_asignado!$C:$C,MATCH(B5,valor_asignado!$B:$B,0)))),NOT(ISNUMBER(SQRT((2*E5)^2+(2*INDEX(valor_asignado!$H:$H,MATCH(B5,valor_asignado!$B:$B,0)))^2))),SQRT((2*E5)^2+(2*INDEX(valor_asignado!$H:$H,MATCH(B5,valor_asignado!$B:$B,0)))^2)=0),"",(D5-INDEX(valor_asignado!$C:$C,MATCH(B5,valor_asignado!$B:$B,0)))/SQRT((2*E5)^2+(2*INDEX(valor_asignado!$H:$H,MATCH(B5,valor_asignado!$B:$B,0)))^2)) -> 0.23349742 | M5: =IF(L5="","N/A",IF(ABS(L5)<=1,"Satisfactorio","No satisfactorio")) -> Satisfactorio | N5: =IF(AND(SUM(IF(AND(D5="",validacion_snapshot!$U$52=""),0,IFERROR(ABS(D5-validacion_snapshot!$U$52),1E+099)),IF(AND(E5="",validacion_snapshot!$V$52=""),0,IFERROR(ABS(E5-validacion_snapshot!$V$52),1E+099)),IF(AND(F5="",validacion_snapshot!$W$52=""),0,IFERROR(ABS(F5-validacion_snapshot!$W$52),1E+099)),IF(AND(H5="",validacion_snapshot!$Y$52=""),0,IFERROR(ABS(H5-validacion_snapshot!$Y$52),1E+099)),IF(AND(J5="",validacion_snapshot!$AA$52=""),0,IFERROR(ABS(J5-validacion_snapshot!$AA$52),1E+099)),IF(AND(L5="",validacion_snapshot!$AC$52=""),0,IFERROR(ABS(L5-validacion_snapshot!$AC$52),1E+099)))<=0.00000001,G5=validacion_snapshot!$X$52,I5=validacion_snapshot!$Z$52,K5=validacion_snapshot!$AB$52,M5=validacion_snapshot!$AD$52),"OK","FALLA") -> OK
B6: Referencia (1) | C6: part_2 | D6: =INDEX(datos_participantes!$D:$D,MATCH(C6,datos_participantes!$A:$A,0)) -> 177.849 | E6: =INDEX(datos_participantes!$F:$F,MATCH(C6,datos_participantes!$A:$A,0)) -> 0.14017657 | F6: =IF(OR(NOT(ISNUMBER(D6)),NOT(ISNUMBER(INDEX(valor_asignado!$C:$C,MATCH(B6,valor_asignado!$B:$B,0)))),NOT(ISNUMBER(INDEX(valor_asignado!$D:$D,MATCH(B6,valor_asignado!$B:$B,0)))),INDEX(valor_asignado!$D:$D,MATCH(B6,valor_asignado!$B:$B,0))=0),"",(D6-INDEX(valor_asignado!$C:$C,MATCH(B6,valor_asignado!$B:$B,0)))/INDEX(valor_asignado!$D:$D,MATCH(B6,valor_asignado!$B:$B,0))) -> 0.051622484 | G6: =IF(F6="","N/A",IF(ABS(F6)<=2,"Satisfactorio",IF(ABS(F6)<3,"Cuestionable","No satisfactorio"))) -> Satisfactorio | H6: =IF(OR(NOT(ISNUMBER(D6)),NOT(ISNUMBER(INDEX(valor_asignado!$C:$C,MATCH(B6,valor_asignado!$B:$B,0)))),NOT(ISNUMBER(SQRT(INDEX(valor_asignado!$D:$D,MATCH(B6,valor_asignado!$B:$B,0))^2+INDEX(valor_asignado!$H:$H,MATCH(B6,valor_asignado!$B:$B,0))^2))),SQRT(INDEX(valor_asignado!$D:$D,MATCH(B6,valor_asignado!$B:$B,0))^2+INDEX(valor_asignado!$H:$H,MATCH(B6,valor_asignado!$B:$B,0))^2)=0),"",(D6-INDEX(valor_asignado!$C:$C,MATCH(B6,valor_asignado!$B:$B,0)))/SQRT(INDEX(valor_asignado!$D:$D,MATCH(B6,valor_asignado!$B:$B,0))^2+INDEX(valor_asignado!$H:$H,MATCH(B6,valor_asignado!$B:$B,0))^2)) -> 0.046341754 | I6: =IF(H6="","N/A",IF(ABS(H6)<=2,"Satisfactorio",IF(ABS(H6)<3,"Cuestionable","No satisfactorio"))) -> Satisfactorio | J6: =IF(OR(NOT(ISNUMBER(D6)),NOT(ISNUMBER(INDEX(valor_asignado!$C:$C,MATCH(B6,valor_asignado!$B:$B,0)))),NOT(ISNUMBER(SQRT(E6^2+INDEX(valor_asignado!$H:$H,MATCH(B6,valor_asignado!$B:$B,0))^2))),SQRT(E6^2+INDEX(valor_asignado!$H:$H,MATCH(B6,valor_asignado!$B:$B,0))^2)=0),"",(D6-INDEX(valor_asignado!$C:$C,MATCH(B6,valor_asignado!$B:$B,0)))/SQRT(E6^2+INDEX(valor_asignado!$H:$H,MATCH(B6,valor_asignado!$B:$B,0))^2)) -> 0.10497299 | K6: =IF(J6="","N/A",IF(ABS(J6)<=2,"Satisfactorio",IF(ABS(J6)<3,"Cuestionable","No satisfactorio"))) -> Satisfactorio | L6: =IF(OR(NOT(ISNUMBER(D6)),NOT(ISNUMBER(INDEX(valor_asignado!$C:$C,MATCH(B6,valor_asignado!$B:$B,0)))),NOT(ISNUMBER(SQRT((2*E6)^2+(2*INDEX(valor_asignado!$H:$H,MATCH(B6,valor_asignado!$B:$B,0)))^2))),SQRT((2*E6)^2+(2*INDEX(valor_asignado!$H:$H,MATCH(B6,valor_asignado!$B:$B,0)))^2)=0),"",(D6-INDEX(valor_asignado!$C:$C,MATCH(B6,valor_asignado!$B:$B,0)))/SQRT((2*E6)^2+(2*INDEX(valor_asignado!$H:$H,MATCH(B6,valor_asignado!$B:$B,0)))^2)) -> 0.052486494 | M6: =IF(L6="","N/A",IF(ABS(L6)<=1,"Satisfactorio","No satisfactorio")) -> Satisfactorio | N6: =IF(AND(SUM(IF(AND(D6="",validacion_snapshot!$U$53=""),0,IFERROR(ABS(D6-validacion_snapshot!$U$53),1E+099)),IF(AND(E6="",validacion_snapshot!$V$53=""),0,IFERROR(ABS(E6-validacion_snapshot!$V$53),1E+099)),IF(AND(F6="",validacion_snapshot!$W$53=""),0,IFERROR(ABS(F6-validacion_snapshot!$W$53),1E+099)),IF(AND(H6="",validacion_snapshot!$Y$53=""),0,IFERROR(ABS(H6-validacion_snapshot!$Y$53),1E+099)),IF(AND(J6="",validacion_snapshot!$AA$53=""),0,IFERROR(ABS(J6-validacion_snapshot!$AA$53),1E+099)),IF(AND(L6="",validacion_snapshot!$AC$53=""),0,IFERROR(ABS(L6-validacion_snapshot!$AC$53),1E+099)))<=0.00000001,G6=validacion_snapshot!$X$53,I6=validacion_snapshot!$Z$53,K6=validacion_snapshot!$AB$53,M6=validacion_snapshot!$AD$53),"OK","FALLA") -> OK
