Workbook

Sheet README
A1: Excel con formulas validacion O3
A3: bloque | B3: contenido
A4: Combo | B4: O3_80
A5: Nivel | B5: 80-nmol/mol
A6: Analito | B6: o3
A7: Fecha de generacion | B7: 2026-05-13 21:09:21 -0500
A8: Script generador | B8: validation_1/validation/excel/validacion_o3/script_excel_formulas_validacion_o3.R
A9: Fuentes | B9: data/homogeneity - homogeneity.csv data/stability - stability.csv data/summary_n13.csv data/pt_data_n13.csv validation_1/validation/excel/validacion_o3/valores_validacion_o3.csv
A10: Convenciones | B10: Azul = dato fuente; negro = formula; verde = link interno; amarillo = control.
A11: Criterio Fase 4 | B11: Homogeneidad y estabilidad generadas con formulas y controles contra snapshot.

Sheet datos_homogeneidad
A1: sample_id | B1: sample_1 | C1: sample_2 | D1: promedio_muestra | E1: rango_absoluto | F1: abs_diff_from_xpt
A2: 1 | B2: 79.477 | C2: 79.596 | D2: =AVERAGE(B2:C2) -> 79.5365 | E2: =ABS(B2-C2) -> 0.119 | F2: =ABS(C2-MEDIAN($B$2:$B$11)) -> 0.061
A3: 2 | B3: 80.683 | C3: 79.628 | D3: =AVERAGE(B3:C3) -> 80.1555 | E3: =ABS(B3-C3) -> 1.055 | F3: =ABS(C3-MEDIAN($B$2:$B$11)) -> 0.093
A4: 3 | B4: 80.717 | C4: 80.664 | D4: =AVERAGE(B4:C4) -> 80.6905 | E4: =ABS(B4-C4) -> 0.053 | F4: =ABS(C4-MEDIAN($B$2:$B$11)) -> 1.129
A5: 4 | B5: 80.655 | C5: 79.55 | D5: =AVERAGE(B5:C5) -> 80.1025 | E5: =ABS(B5-C5) -> 1.105 | F5: =ABS(C5-MEDIAN($B$2:$B$11)) -> 0.015
A6: 5 | B6: 79.543 | C6: 79.537 | D6: =AVERAGE(B6:C6) -> 79.54 | E6: =ABS(B6-C6) -> 0.006 | F6: =ABS(C6-MEDIAN($B$2:$B$11)) -> 0.002
A7: 6 | B7: 79.527 | C7: 80.651 | D7: =AVERAGE(B7:C7) -> 80.089 | E7: =ABS(B7-C7) -> 1.124 | F7: =ABS(C7-MEDIAN($B$2:$B$11)) -> 1.116
A8: 7 | B8: 79.498 | C8: 80.607 | D8: =AVERAGE(B8:C8) -> 80.0525 | E8: =ABS(B8-C8) -> 1.109 | F8: =ABS(C8-MEDIAN($B$2:$B$11)) -> 1.072
A9: 8 | B9: 79.513 | C9: 79.479 | D9: =AVERAGE(B9:C9) -> 79.496 | E9: =ABS(B9-C9) -> 0.034 | F9: =ABS(C9-MEDIAN($B$2:$B$11)) -> 0.056
A10: 9 | B10: 79.524 | C10: 79.581 | D10: =AVERAGE(B10:C10) -> 79.5525 | E10: =ABS(B10-C10) -> 0.057 | F10: =ABS(C10-MEDIAN($B$2:$B$11)) -> 0.046
A11: 10 | B11: 79.579 | C11: 79.533 | D11: =AVERAGE(B11:C11) -> 79.556 | E11: =ABS(B11-C11) -> 0.046 | F11: =ABS(C11-MEDIAN($B$2:$B$11)) -> 0.002

Sheet calc_homogeneidad
A1: parametro | B1: valor | C1: notas
A2: g | B2: =COUNT(datos_homogeneidad!$B$2:$B$11) -> 10 | C2: Numero de muestras.
A3: m | B3: =2 -> 2 | C3: Numero de replicas.
A4: general_mean | B4: =AVERAGE(datos_homogeneidad!$B$2:$B$11,datos_homogeneidad!$C$2:$C$11) -> 79.8771 | C4: Promedio de todos los valores.
A5: x_pt | B5: =MEDIAN(datos_homogeneidad!$B$2:$B$11) -> 79.535 | C5: Mediana de sample_1.
A6: s_x_bar_sq | B6: =VAR(datos_homogeneidad!$D$2:$D$11) -> 0.16099449 | C6: Varianza de promedios por muestra.
A7: sw | B7: =SQRT(SUMSQ(datos_homogeneidad!$E$2:$E$11)/(2*B2)) -> 0.49248523 | C7: Desviacion dentro de muestra para m = 2.
A8: ss_sq | B8: =ABS(B6-(B7^2/B3)) -> 0.039723639 | C8: Componente entre muestras sin truncamiento, usando ABS como ptcalc.
A9: ss | B9: =SQRT(B8) -> 0.1993079 | C9: Desviacion entre muestras.
A10: median_abs_diff | B10: =MEDIAN(datos_homogeneidad!$F$2:$F$11) -> 0.0585 | C10: Mediana de |sample_2 - x_pt|.
A11: MADe | B11: =1.483*B10 -> 0.0867555 | C11: 1.483 * median_abs_diff.
A12: u_sigma_pt | B12: =IFERROR(1.25*B11/SQRT(B2),0) -> 0.034293122 | C12: 1.25 * MADe / sqrt(g).
A13: Q1 | B13: =QUARTILE(datos_homogeneidad!$B$2:$B$11,1) -> 79.51575 | C13: Cuartil 25% de sample_1, type 7 equivalente.
A14: Q3 | B14: =QUARTILE(datos_homogeneidad!$B$2:$B$11,3) -> 80.386 | C14: Cuartil 75% de sample_1, type 7 equivalente.
A15: IQR | B15: =B14-B13 -> 0.87025 | C15: Q3 - Q1.
A16: nIQR | B16: =0.7413*B15 -> 0.64511632 | C16: 0.7413 * IQR.
A17: u_sigma_pt_niqr | B17: =IFERROR(1.25*B16/SQRT(B2),0) -> 0.25500462 | C17: 1.25 * nIQR / sqrt(g).
A18: criterio_made | B18: =0.3*B11 -> 0.02602665 | C18: 0.3 * MADe.
A19: criterio_niqr | B19: =0.3*B16 -> 0.1935349 | C19: 0.3 * nIQR.

Sheet resultado_homogeneidad
A1: tabla | B1: parametro | C1: app_value | D1: calculado | E1: delta_abs | F1: tolerancia | G1: estado
A2: Resumen del Estudio (Método MADe) | B2: Muestras (g) | C2: 10 | D2: =calc_homogeneidad!$B$2 -> 10 | E2: =IFERROR(ABS(D2-C2),"") -> 0 | F2: 0.0005 | G2: =IF(E2="","Pendiente",IF(E2<=F2,"OK","FALLA")) -> OK
A3: Resumen del Estudio (Método MADe) | B3: Réplicas (m) | C3: 2 | D3: =calc_homogeneidad!$B$3 -> 2 | E3: =IFERROR(ABS(D3-C3),"") -> 0 | F3: 0.0005 | G3: =IF(E3="","Pendiente",IF(E3<=F3,"OK","FALLA")) -> OK
A4: Resumen del Estudio (Método MADe) | B4: x_pt (hom_stab) | C4: 79.5350 | D4: =ROUND(calc_homogeneidad!$B$5,4) -> 79.535 | E4: =IFERROR(ABS(D4-C4),"") -> 0 | F4: 0.0005 | G4: =IF(E4="","Pendiente",IF(E4<=F4,"OK","FALLA")) -> OK
A5: Resumen del Estudio (Método MADe) | B5: Median |sample_2 - x_pt| | C5: 0.0868 | D5: =ROUND(calc_homogeneidad!$B$11,4) -> 0.0868 | E5: =IFERROR(ABS(D5-C5),"") -> 0 | F5: 0.0005 | G5: =IF(E5="","Pendiente",IF(E5<=F5,"OK","FALLA")) -> OK
A6: Resumen del Estudio (Método MADe) | B6: MADe (1.483 × median) | C6: 0.0868 | D6: =ROUND(calc_homogeneidad!$B$11,4) -> 0.0868 | E6: =IFERROR(ABS(D6-C6),"") -> 0 | F6: 0.0005 | G6: =IF(E6="","Pendiente",IF(E6<=F6,"OK","FALLA")) -> OK
A7: Resumen del Estudio (Método MADe) | B7: u_sigma_pt | C7: 0.0343 | D7: =ROUND(calc_homogeneidad!$B$12,4) -> 0.0343 | E7: =IFERROR(ABS(D7-C7),"") -> 0 | F7: 0.0005 | G7: =IF(E7="","Pendiente",IF(E7<=F7,"OK","FALLA")) -> OK
A8: Resumen del Estudio (Método nIQR) | B8: Muestras (g) | C8: 10 | D8: =calc_homogeneidad!$B$2 -> 10 | E8: =IFERROR(ABS(D8-C8),"") -> 0 | F8: 0.0005 | G8: =IF(E8="","Pendiente",IF(E8<=F8,"OK","FALLA")) -> OK
A9: Resumen del Estudio (Método nIQR) | B9: Réplicas (m) | C9: 2 | D9: =calc_homogeneidad!$B$3 -> 2 | E9: =IFERROR(ABS(D9-C9),"") -> 0 | F9: 0.0005 | G9: =IF(E9="","Pendiente",IF(E9<=F9,"OK","FALLA")) -> OK
A10: Resumen del Estudio (Método nIQR) | B10: x_pt (hom_stab) | C10: 79.5350 | D10: =ROUND(calc_homogeneidad!$B$5,4) -> 79.535 | E10: =IFERROR(ABS(D10-C10),"") -> 0 | F10: 0.0005 | G10: =IF(E10="","Pendiente",IF(E10<=F10,"OK","FALLA")) -> OK
A11: Resumen del Estudio (Método nIQR) | B11: Q1 (25%) | C11: 79.5157 | D11: =ROUND(calc_homogeneidad!$B$13,4) -> 79.5158 | E11: =IFERROR(ABS(D11-C11),"") -> 0.0001 | F11: 0.0005 | G11: =IF(E11="","Pendiente",IF(E11<=F11,"OK","FALLA")) -> OK
A12: Resumen del Estudio (Método nIQR) | B12: Q3 (75%) | C12: 80.3860 | D12: =ROUND(calc_homogeneidad!$B$14,4) -> 80.386 | E12: =IFERROR(ABS(D12-C12),"") -> 0 | F12: 0.0005 | G12: =IF(E12="","Pendiente",IF(E12<=F12,"OK","FALLA")) -> OK
A13: Resumen del Estudio (Método nIQR) | B13: IQR (Q3 - Q1) | C13: 0.8702 | D13: =ROUND(calc_homogeneidad!$B$15,4) -> 0.8702 | E13: =IFERROR(ABS(D13-C13),"") -> 0 | F13: 0.0005 | G13: =IF(E13="","Pendiente",IF(E13<=F13,"OK","FALLA")) -> OK
A14: Resumen del Estudio (Método nIQR) | B14: nIQR (0.7413 × IQR) | C14: 0.6451 | D14: =ROUND(calc_homogeneidad!$B$16,4) -> 0.6451 | E14: =IFERROR(ABS(D14-C14),"") -> 0 | F14: 0.0005 | G14: =IF(E14="","Pendiente",IF(E14<=F14,"OK","FALLA")) -> OK
A15: Resumen del Estudio (Método nIQR) | B15: u_sigma_pt (nIQR) | C15: 0.2550 | D15: =ROUND(calc_homogeneidad!$B$17,4) -> 0.255 | E15: =IFERROR(ABS(D15-C15),"") -> 0 | F15: 0.0005 | G15: =IF(E15="","Pendiente",IF(E15<=F15,"OK","FALLA")) -> OK

Sheet datos_estabilidad
A1: sample_id | B1: sample_1 | C1: sample_2 | D1: promedio_muestra | E1: rango_absoluto | F1: abs_diff_from_xpt
A2: 1 | B2: 80.633 | C2: 79.578 | D2: =AVERAGE(B2:C2) -> 80.1055 | E2: =ABS(B2-C2) -> 1.055 | F2: =ABS(C2-MEDIAN($B$2:$B$3)) -> 1.0835
A3: 2 | B3: 80.69 | C3: 79.472 | D3: =AVERAGE(B3:C3) -> 80.081 | E3: =ABS(B3-C3) -> 1.218 | F3: =ABS(C3-MEDIAN($B$2:$B$3)) -> 1.1895

Sheet calc_estabilidad
A1: parametro | B1: valor | C1: notas
A2: g_stab | B2: =COUNT(datos_estabilidad!$B$2:$B$3) -> 2 | C2: Numero de muestras estabilidad.
A3: m_stab | B3: =2 -> 2 | C3: Numero de replicas estabilidad.
A4: general_mean_stab | B4: =AVERAGE(datos_estabilidad!$B$2:$B$3,datos_estabilidad!$C$2:$C$3) -> 80.09325 | C4: Promedio de todos los valores de estabilidad.
A5: x_pt_stab | B5: =MEDIAN(datos_estabilidad!$B$2:$B$3) -> 80.6615 | C5: Mediana de sample_1 estabilidad.
A6: s_x_bar_sq_stab | B6: =VAR(datos_estabilidad!$D$2:$D$3) -> 0.000300125 | C6: Varianza de promedios estabilidad.
A7: sw_stab | B7: =SQRT(SUMSQ(datos_estabilidad!$E$2:$E$3)/(2*B2)) -> 0.80569054 | C7: Desviacion dentro de muestra para m = 2.
A8: ss_sq_stab | B8: =ABS(B6-(B7^2/B3)) -> 0.3242685 | C8: Componente entre muestras estabilidad.
A9: ss_stab | B9: =SQRT(B8) -> 0.56944578 | C9: Desviacion entre muestras estabilidad.
A10: diff_hom_stab | B10: =ABS(B4-calc_homogeneidad!$B$4) -> 0.21615 | C10: |media estabilidad - media homogeneidad|.
A11: u_hom_mean | B11: =IFERROR(stdev.s(datos_homogeneidad!$B$2:$C$3)/SQRT(COUNT(datos_homogeneidad!$B$2:$C$3)),0) -> 0 | C11: STDEV.S(valores homogeneidad) / sqrt(n).
A12: u_stab_mean | B12: =IFERROR(stdev.s(datos_estabilidad!$B$2:$C$3)/SQRT(COUNT(datos_estabilidad!$B$2:$C$3)),0) -> 0 | C12: STDEV.S(valores estabilidad) / sqrt(n).
A13: criterio_made | B13: =calc_homogeneidad!$B$18 -> 0.02602665 | C13: 0.3 * MADe de homogeneidad.
A14: criterio_made_expandido | B14: =B13+2*SQRT(B11^2+B12^2) -> 0.02602665 | C14: criterio + 2 * incertidumbre de medias.
A15: criterio_niqr | B15: =calc_homogeneidad!$B$19 -> 0.1935349 | C15: 0.3 * nIQR de homogeneidad.
A16: criterio_niqr_expandido | B16: =B15+2*SQRT(B11^2+B12^2) -> 0.1935349 | C16: criterio nIQR + 2 * incertidumbre de medias.

Sheet resultado_estabilidad
A1: tabla | B1: parametro | C1: app_value | D1: calculado | E1: delta_abs | F1: tolerancia | G1: estado
A2: Resumen del Estudio (Método MADe) | B2: Muestras (g) | C2: 10 | D2: =calc_homogeneidad!$B$2 -> 10 | E2: =IFERROR(ABS(D2-C2),"") -> 0 | F2: 0.0005 | G2: =IF(E2="","Pendiente",IF(E2<=F2,"OK","FALLA")) -> OK
A3: Resumen del Estudio (Método MADe) | B3: Réplicas (m) | C3: 2 | D3: =calc_homogeneidad!$B$3 -> 2 | E3: =IFERROR(ABS(D3-C3),"") -> 0 | F3: 0.0005 | G3: =IF(E3="","Pendiente",IF(E3<=F3,"OK","FALLA")) -> OK
A4: Resumen del Estudio (Método MADe) | B4: x_pt (hom_stab) | C4: 79.5350 | D4: =ROUND(calc_homogeneidad!$B$5,4) -> 79.535 | E4: =IFERROR(ABS(D4-C4),"") -> 0 | F4: 0.0005 | G4: =IF(E4="","Pendiente",IF(E4<=F4,"OK","FALLA")) -> OK
A5: Resumen del Estudio (Método MADe) | B5: Median |sample_2 - x_pt| | C5: 0.0868 | D5: =ROUND(calc_homogeneidad!$B$11,4) -> 0.0868 | E5: =IFERROR(ABS(D5-C5),"") -> 0 | F5: 0.0005 | G5: =IF(E5="","Pendiente",IF(E5<=F5,"OK","FALLA")) -> OK
A6: Resumen del Estudio (Método MADe) | B6: MADe (1.483 × median) | C6: 0.0868 | D6: =ROUND(calc_homogeneidad!$B$11,4) -> 0.0868 | E6: =IFERROR(ABS(D6-C6),"") -> 0 | F6: 0.0005 | G6: =IF(E6="","Pendiente",IF(E6<=F6,"OK","FALLA")) -> OK
A7: Resumen del Estudio (Método MADe) | B7: u_sigma_pt | C7: 0.0343 | D7: =ROUND(calc_homogeneidad!$B$12,4) -> 0.0343 | E7: =IFERROR(ABS(D7-C7),"") -> 0 | F7: 0.0005 | G7: =IF(E7="","Pendiente",IF(E7<=F7,"OK","FALLA")) -> OK
A8: Resumen del Estudio (Método nIQR) | B8: Muestras (g) | C8: 10 | D8: =calc_homogeneidad!$B$2 -> 10 | E8: =IFERROR(ABS(D8-C8),"") -> 0 | F8: 0.0005 | G8: =IF(E8="","Pendiente",IF(E8<=F8,"OK","FALLA")) -> OK
A9: Resumen del Estudio (Método nIQR) | B9: Réplicas (m) | C9: 2 | D9: =calc_homogeneidad!$B$3 -> 2 | E9: =IFERROR(ABS(D9-C9),"") -> 0 | F9: 0.0005 | G9: =IF(E9="","Pendiente",IF(E9<=F9,"OK","FALLA")) -> OK
A10: Resumen del Estudio (Método nIQR) | B10: x_pt (hom_stab) | C10: 79.5350 | D10: =ROUND(calc_homogeneidad!$B$5,4) -> 79.535 | E10: =IFERROR(ABS(D10-C10),"") -> 0 | F10: 0.0005 | G10: =IF(E10="","Pendiente",IF(E10<=F10,"OK","FALLA")) -> OK
A11: Resumen del Estudio (Método nIQR) | B11: Q1 (25%) | C11: 79.5157 | D11: =ROUND(calc_homogeneidad!$B$13,4) -> 79.5158 | E11: =IFERROR(ABS(D11-C11),"") -> 0.0001 | F11: 0.0005 | G11: =IF(E11="","Pendiente",IF(E11<=F11,"OK","FALLA")) -> OK
A12: Resumen del Estudio (Método nIQR) | B12: Q3 (75%) | C12: 80.3860 | D12: =ROUND(calc_homogeneidad!$B$14,4) -> 80.386 | E12: =IFERROR(ABS(D12-C12),"") -> 0 | F12: 0.0005 | G12: =IF(E12="","Pendiente",IF(E12<=F12,"OK","FALLA")) -> OK
A13: Resumen del Estudio (Método nIQR) | B13: IQR (Q3 - Q1) | C13: 0.8702 | D13: =ROUND(calc_homogeneidad!$B$15,4) -> 0.8702 | E13: =IFERROR(ABS(D13-C13),"") -> 0 | F13: 0.0005 | G13: =IF(E13="","Pendiente",IF(E13<=F13,"OK","FALLA")) -> OK
A14: Resumen del Estudio (Método nIQR) | B14: nIQR (0.7413 × IQR) | C14: 0.6451 | D14: =ROUND(calc_homogeneidad!$B$16,4) -> 0.6451 | E14: =IFERROR(ABS(D14-C14),"") -> 0 | F14: 0.0005 | G14: =IF(E14="","Pendiente",IF(E14<=F14,"OK","FALLA")) -> OK
A15: Resumen del Estudio (Método nIQR) | B15: u_sigma_pt (nIQR) | C15: 0.2550 | D15: =ROUND(calc_homogeneidad!$B$17,4) -> 0.255 | E15: =IFERROR(ABS(D15-C15),"") -> 0 | F15: 0.0005 | G15: =IF(E15="","Pendiente",IF(E15<=F15,"OK","FALLA")) -> OK

Sheet datos_participantes
A1: participant_id | B1: pollutant | C1: level | D1: mean_value | E1: sd_value | F1: u_i | G1: u_i_check
A2: part_1 | B2: o3 | C2: 80-nmol/mol | D2: 80.229333 | E2: 0.57066667 | F2: 0.030643408 | G2: =IFERROR(F2/SQRT(3),"") -> 0.01769198
A3: part_10 | B3: o3 | C3: 80-nmol/mol | D3: 80.086 | E3: 0.58733333 | F3: 0.011708712 | G3: =IFERROR(F3/SQRT(3),"") -> 0.0067600279
A4: part_11 | B4: o3 | C4: 80-nmol/mol | D4: 80.056 | E4: 0.55833333 | F4: 0.094285887 | G4: =IFERROR(F4/SQRT(3),"") -> 0.054435982
A5: part_12 | B5: o3 | C5: 80-nmol/mol | D5: 80.031 | E5: 0.57566667 | F5: 0.092481926 | G5: =IFERROR(F5/SQRT(3),"") -> 0.053394465
A6: part_2 | B6: o3 | C6: 80-nmol/mol | D6: 80.057333 | E6: 0.54533333 | F6: 0.14760399 | G6: =IFERROR(F6/SQRT(3),"") -> 0.085219206
A7: part_3 | B7: o3 | C7: 80-nmol/mol | D7: 79.983667 | E7: 0.56733333 | F7: 0.070413856 | G7: =IFERROR(F7/SQRT(3),"") -> 0.040653459
A8: part_4 | B8: o3 | C8: 80-nmol/mol | D8: 80.091 | E8: 0.56766667 | F8: 0.1311521 | G8: =IFERROR(F8/SQRT(3),"") -> 0.075720702
A9: part_5 | B9: o3 | C9: 80-nmol/mol | D9: 80.158 | E9: 0.56966667 | F9: 0.095394535 | G9: =IFERROR(F9/SQRT(3),"") -> 0.055076061
A10: part_6 | B10: o3 | C10: 80-nmol/mol | D10: 80.260667 | E10: 0.566 | F10: 0.042729304 | G10: =IFERROR(F10/SQRT(3),"") -> 0.024669775
A11: part_7 | B11: o3 | C11: 80-nmol/mol | D11: 79.991667 | E11: 0.58333333 | F11: 0.0046615433 | G11: =IFERROR(F11/SQRT(3),"") -> 0.0026913433
A12: part_8 | B12: o3 | C12: 80-nmol/mol | D12: 80.047333 | E12: 0.56566667 | F12: 0.1009447 | G12: =IFERROR(F12/SQRT(3),"") -> 0.058280448
A13: part_9 | B13: o3 | C13: 80-nmol/mol | D13: 80.247667 | E13: 0.564 | F13: 0.038597288 | G13: =IFERROR(F13/SQRT(3),"") -> 0.022284154

Sheet datos_referencia
A1: pollutant | B1: level | C1: participant_id | D1: mean_value | E1: sd_value | F1: x_pt_ref | G1: u_ref_check
A2: o3 | B2: 80-nmol/mol | C2: ref | D2: 79.896333 | E2: 0.57033333 | F2: =AVERAGE(D2) -> 79.896333 | G2: =IFERROR(stdev.s(D2)/SQRT(COUNT(D2)),"")

Sheet algoritmo_A_iteraciones
A1: metrica | B1: valor
A2: x0_mediana | B2: =MEDIAN(algoritmo_A_iteraciones!B11:B22) -> 80.071667
A3: s0_MADe | B3: =1.483*MEDIAN(C11:C22) -> 0.089474333
A4: tolerancia | B4: 1e-10
A5: n_participantes | B5: =COUNT(algoritmo_A_iteraciones!B11:B22) -> 12
A6: iteracion_final | B6: =IFERROR(MATCH(1,AC27:AC76,0),50) -> 4
A7: x_final | B7: =INDEX(S27:S76,$B$6) -> 80.103306
A8: s_final | B8: =INDEX(T27:T76,$B$6) -> 0.11048474
A9: n_winsorizadas_final | B9: =--(INDEX(G27:G76,$B$6)<>$B$11)+--(INDEX(H27:H76,$B$6)<>$B$12)+--(INDEX(I27:I76,$B$6)<>$B$13)+--(INDEX(J27:J76,$B$6)<>$B$14)+--(INDEX(K27:K76,$B$6)<>$B$15)+--(INDEX(L27:L76,$B$6)<>$B$16)+--(INDEX(M27:M76,$B$6)<>$B$17)+--(INDEX(N27:N76,$B$6)<>$B$18)+--(INDEX(O27:O76,$B$6)<>$B$19)+--(INDEX(P27:P76,$B$6)<>$B$20)+--(INDEX(Q27:Q76,$B$6)<>$B$21)+--(INDEX(R27:R76,$B$6)<>$B$22) -> 0
A10: participant_id | B10: xi | C10: abs_xi_x0
A11: part_1 | B11: 80.229333 | C11: =ABS(B11-$B$2) -> 0.15766667
A12: part_10 | B12: 80.086 | C12: =ABS(B12-$B$2) -> 0.014333333
A13: part_11 | B13: 80.056 | C13: =ABS(B13-$B$2) -> 0.015666667
A14: part_12 | B14: 80.031 | C14: =ABS(B14-$B$2) -> 0.040666667
A15: part_2 | B15: 80.057333 | C15: =ABS(B15-$B$2) -> 0.014333333
A16: part_3 | B16: 79.983667 | C16: =ABS(B16-$B$2) -> 0.088
A17: part_4 | B17: 80.091 | C17: =ABS(B17-$B$2) -> 0.019333333
A18: part_5 | B18: 80.158 | C18: =ABS(B18-$B$2) -> 0.086333333
A19: part_6 | B19: 80.260667 | C19: =ABS(B19-$B$2) -> 0.189
A20: part_7 | B20: 79.991667 | C20: =ABS(B20-$B$2) -> 0.08
A21: part_8 | B21: 80.047333 | C21: =ABS(B21-$B$2) -> 0.024333333
A22: part_9 | B22: 80.247667 | C22: =ABS(B22-$B$2) -> 0.176
A26: iteracion | B26: x_prev | C26: s_prev | D26: delta | E26: limite_inf | F26: limite_sup | G26: w_part_1 | H26: w_part_10 | I26: w_part_11 | J26: w_part_12 | K26: w_part_2 | L26: w_part_3 | M26: w_part_4 | N26: w_part_5 | O26: w_part_6 | P26: w_part_7 | Q26: w_part_8 | R26: w_part_9 | S26: x_new | T26: s_new | U26: delta_x | V26: delta_s | W26: sig3_x_prev | X26: sig3_s_prev | Y26: sig3_x_new | Z26: sig3_s_new | AA26: signif3_converged | AB26: guardia_numerica | AC26: fila_seleccionada
A27: 1 | B27: =$B$2 -> 80.071667 | C27: =$B$3 -> 0.089474333 | D27: =1.5*C27 -> 0.1342115 | E27: =B27-D27 -> 79.937455 | F27: =B27+D27 -> 80.205878 | G27: =MIN(MAX($B$11,$E27),$F27) -> 80.205878 | H27: =MIN(MAX($B$12,$E27),$F27) -> 80.086 | I27: =MIN(MAX($B$13,$E27),$F27) -> 80.056 | J27: =MIN(MAX($B$14,$E27),$F27) -> 80.031 | K27: =MIN(MAX($B$15,$E27),$F27) -> 80.057333 | L27: =MIN(MAX($B$16,$E27),$F27) -> 79.983667 | M27: =MIN(MAX($B$17,$E27),$F27) -> 80.091 | N27: =MIN(MAX($B$18,$E27),$F27) -> 80.158 | O27: =MIN(MAX($B$19,$E27),$F27) -> 80.205878 | P27: =MIN(MAX($B$20,$E27),$F27) -> 79.991667 | Q27: =MIN(MAX($B$21,$E27),$F27) -> 80.047333 | R27: =MIN(MAX($B$22,$E27),$F27) -> 80.205878 | S27: =AVERAGE(G27:R27) -> 80.093303 | T27: =1.134*STDEV(G27:R27) -> 0.092565953 | U27: =ABS(S27-B27) -> 0.021636208 | V27: =ABS(T27-C27) -> 0.0030916193 | W27: =IF(OR(NOT(ISNUMBER(B27)),B27=0),B27,ROUND(B27,MAX(3-1-INT(LOG10(ABS(B27))),0))) -> 80.1 | X27: =IF(OR(NOT(ISNUMBER(C27)),C27=0),C27,ROUND(C27,MAX(3-1-INT(LOG10(ABS(C27))),0))) -> 0.0895 | Y27: =IF(OR(NOT(ISNUMBER(S27)),S27=0),S27,ROUND(S27,MAX(3-1-INT(LOG10(ABS(S27))),0))) -> 80.1 | Z27: =IF(OR(NOT(ISNUMBER(T27)),T27=0),T27,ROUND(T27,MAX(3-1-INT(LOG10(ABS(T27))),0))) -> 0.0926 | AA27: =IF(AND(Y27=W27,Z27=X27),1,0) -> 0 | AB27: =IF(AND(U27<$B$4,V27<$B$4),1,0) -> 0 | AC27: =IF(OR(AA27=1,AB27=1),1,0) -> 0
A28: 2 | B28: =S27 -> 80.093303 | C28: =T27 -> 0.092565953 | D28: =1.5*C28 -> 0.13884893 | E28: =B28-D28 -> 79.954454 | F28: =B28+D28 -> 80.232152 | G28: =MIN(MAX($B$11,$E28),$F28) -> 80.229333 | H28: =MIN(MAX($B$12,$E28),$F28) -> 80.086 | I28: =MIN(MAX($B$13,$E28),$F28) -> 80.056 | J28: =MIN(MAX($B$14,$E28),$F28) -> 80.031 | K28: =MIN(MAX($B$15,$E28),$F28) -> 80.057333 | L28: =MIN(MAX($B$16,$E28),$F28) -> 79.983667 | M28: =MIN(MAX($B$17,$E28),$F28) -> 80.091 | N28: =MIN(MAX($B$18,$E28),$F28) -> 80.158 | O28: =MIN(MAX($B$19,$E28),$F28) -> 80.232152 | P28: =MIN(MAX($B$20,$E28),$F28) -> 79.991667 | Q28: =MIN(MAX($B$21,$E28),$F28) -> 80.047333 | R28: =MIN(MAX($B$22,$E28),$F28) -> 80.232152 | S28: =AVERAGE(G28:R28) -> 80.099636 | T28: =1.134*STDEV(G28:R28) -> 0.10362613 | U28: =ABS(S28-B28) -> 0.0063335368 | V28: =ABS(T28-C28) -> 0.011060182 | W28: =IF(OR(NOT(ISNUMBER(B28)),B28=0),B28,ROUND(B28,MAX(3-1-INT(LOG10(ABS(B28))),0))) -> 80.1 | X28: =IF(OR(NOT(ISNUMBER(C28)),C28=0),C28,ROUND(C28,MAX(3-1-INT(LOG10(ABS(C28))),0))) -> 0.0926 | Y28: =IF(OR(NOT(ISNUMBER(S28)),S28=0),S28,ROUND(S28,MAX(3-1-INT(LOG10(ABS(S28))),0))) -> 80.1 | Z28: =IF(OR(NOT(ISNUMBER(T28)),T28=0),T28,ROUND(T28,MAX(3-1-INT(LOG10(ABS(T28))),0))) -> 0.104 | AA28: =IF(AND(Y28=W28,Z28=X28),1,0) -> 0 | AB28: =IF(AND(U28<$B$4,V28<$B$4),1,0) -> 0 | AC28: =IF(OR(AA28=1,AB28=1),1,0) -> 0
A29: 3 | B29: =S28 -> 80.099636 | C29: =T28 -> 0.10362613 | D29: =1.5*C29 -> 0.1554392 | E29: =B29-D29 -> 79.944197 | F29: =B29+D29 -> 80.255076 | G29: =MIN(MAX($B$11,$E29),$F29) -> 80.229333 | H29: =MIN(MAX($B$12,$E29),$F29) -> 80.086 | I29: =MIN(MAX($B$13,$E29),$F29) -> 80.056 | J29: =MIN(MAX($B$14,$E29),$F29) -> 80.031 | K29: =MIN(MAX($B$15,$E29),$F29) -> 80.057333 | L29: =MIN(MAX($B$16,$E29),$F29) -> 79.983667 | M29: =MIN(MAX($B$17,$E29),$F29) -> 80.091 | N29: =MIN(MAX($B$18,$E29),$F29) -> 80.158 | O29: =MIN(MAX($B$19,$E29),$F29) -> 80.255076 | P29: =MIN(MAX($B$20,$E29),$F29) -> 79.991667 | Q29: =MIN(MAX($B$21,$E29),$F29) -> 80.047333 | R29: =MIN(MAX($B$22,$E29),$F29) -> 80.247667 | S29: =AVERAGE(G29:R29) -> 80.10284 | T29: =1.134*STDEV(G29:R29) -> 0.10956513 | U29: =ABS(S29-B29) -> 0.0032032227 | V29: =ABS(T29-C29) -> 0.0059389976 | W29: =IF(OR(NOT(ISNUMBER(B29)),B29=0),B29,ROUND(B29,MAX(3-1-INT(LOG10(ABS(B29))),0))) -> 80.1 | X29: =IF(OR(NOT(ISNUMBER(C29)),C29=0),C29,ROUND(C29,MAX(3-1-INT(LOG10(ABS(C29))),0))) -> 0.104 | Y29: =IF(OR(NOT(ISNUMBER(S29)),S29=0),S29,ROUND(S29,MAX(3-1-INT(LOG10(ABS(S29))),0))) -> 80.1 | Z29: =IF(OR(NOT(ISNUMBER(T29)),T29=0),T29,ROUND(T29,MAX(3-1-INT(LOG10(ABS(T29))),0))) -> 0.11 | AA29: =IF(AND(Y29=W29,Z29=X29),1,0) -> 0 | AB29: =IF(AND(U29<$B$4,V29<$B$4),1,0) -> 0 | AC29: =IF(OR(AA29=1,AB29=1),1,0) -> 0
A30: 4 | B30: =S29 -> 80.10284 | C30: =T29 -> 0.10956513 | D30: =1.5*C30 -> 0.1643477 | E30: =B30-D30 -> 79.938492 | F30: =B30+D30 -> 80.267187 | G30: =MIN(MAX($B$11,$E30),$F30) -> 80.229333 | H30: =MIN(MAX($B$12,$E30),$F30) -> 80.086 | I30: =MIN(MAX($B$13,$E30),$F30) -> 80.056 | J30: =MIN(MAX($B$14,$E30),$F30) -> 80.031 | K30: =MIN(MAX($B$15,$E30),$F30) -> 80.057333 | L30: =MIN(MAX($B$16,$E30),$F30) -> 79.983667 | M30: =MIN(MAX($B$17,$E30),$F30) -> 80.091 | N30: =MIN(MAX($B$18,$E30),$F30) -> 80.158 | O30: =MIN(MAX($B$19,$E30),$F30) -> 80.260667 | P30: =MIN(MAX($B$20,$E30),$F30) -> 79.991667 | Q30: =MIN(MAX($B$21,$E30),$F30) -> 80.047333 | R30: =MIN(MAX($B$22,$E30),$F30) -> 80.247667 | S30: =AVERAGE(G30:R30) -> 80.103306 | T30: =1.134*STDEV(G30:R30) -> 0.11048474 | U30: =ABS(S30-B30) -> 0.00046592112 | V30: =ABS(T30-C30) -> 0.00091960816 | W30: =IF(OR(NOT(ISNUMBER(B30)),B30=0),B30,ROUND(B30,MAX(3-1-INT(LOG10(ABS(B30))),0))) -> 80.1 | X30: =IF(OR(NOT(ISNUMBER(C30)),C30=0),C30,ROUND(C30,MAX(3-1-INT(LOG10(ABS(C30))),0))) -> 0.11 | Y30: =IF(OR(NOT(ISNUMBER(S30)),S30=0),S30,ROUND(S30,MAX(3-1-INT(LOG10(ABS(S30))),0))) -> 80.1 | Z30: =IF(OR(NOT(ISNUMBER(T30)),T30=0),T30,ROUND(T30,MAX(3-1-INT(LOG10(ABS(T30))),0))) -> 0.11 | AA30: =IF(AND(Y30=W30,Z30=X30),1,0) -> 1 | AB30: =IF(AND(U30<$B$4,V30<$B$4),1,0) -> 0 | AC30: =IF(OR(AA30=1,AB30=1),1,0) -> 1
A31: 5 | B31: =S30 -> 80.103306 | C31: =T30 -> 0.11048474 | D31: =1.5*C31 -> 0.16572711 | E31: =B31-D31 -> 79.937578 | F31: =B31+D31 -> 80.269033 | G31: =MIN(MAX($B$11,$E31),$F31) -> 80.229333 | H31: =MIN(MAX($B$12,$E31),$F31) -> 80.086 | I31: =MIN(MAX($B$13,$E31),$F31) -> 80.056 | J31: =MIN(MAX($B$14,$E31),$F31) -> 80.031 | K31: =MIN(MAX($B$15,$E31),$F31) -> 80.057333 | L31: =MIN(MAX($B$16,$E31),$F31) -> 79.983667 | M31: =MIN(MAX($B$17,$E31),$F31) -> 80.091 | N31: =MIN(MAX($B$18,$E31),$F31) -> 80.158 | O31: =MIN(MAX($B$19,$E31),$F31) -> 80.260667 | P31: =MIN(MAX($B$20,$E31),$F31) -> 79.991667 | Q31: =MIN(MAX($B$21,$E31),$F31) -> 80.047333 | R31: =MIN(MAX($B$22,$E31),$F31) -> 80.247667 | S31: =AVERAGE(G31:R31) -> 80.103306 | T31: =1.134*STDEV(G31:R31) -> 0.11048474 | U31: =ABS(S31-B31) -> 0 | V31: =ABS(T31-C31) -> 0 | W31: =IF(OR(NOT(ISNUMBER(B31)),B31=0),B31,ROUND(B31,MAX(3-1-INT(LOG10(ABS(B31))),0))) -> 80.1 | X31: =IF(OR(NOT(ISNUMBER(C31)),C31=0),C31,ROUND(C31,MAX(3-1-INT(LOG10(ABS(C31))),0))) -> 0.11 | Y31: =IF(OR(NOT(ISNUMBER(S31)),S31=0),S31,ROUND(S31,MAX(3-1-INT(LOG10(ABS(S31))),0))) -> 80.1 | Z31: =IF(OR(NOT(ISNUMBER(T31)),T31=0),T31,ROUND(T31,MAX(3-1-INT(LOG10(ABS(T31))),0))) -> 0.11 | AA31: =IF(AND(Y31=W31,Z31=X31),1,0) -> 1 | AB31: =IF(AND(U31<$B$4,V31<$B$4),1,0) -> 1 | AC31: =IF(OR(AA31=1,AB31=1),1,0) -> 1
A32: 6 | B32: =S31 -> 80.103306 | C32: =T31 -> 0.11048474 | D32: =1.5*C32 -> 0.16572711 | E32: =B32-D32 -> 79.937578 | F32: =B32+D32 -> 80.269033 | G32: =MIN(MAX($B$11,$E32),$F32) -> 80.229333 | H32: =MIN(MAX($B$12,$E32),$F32) -> 80.086 | I32: =MIN(MAX($B$13,$E32),$F32) -> 80.056 | J32: =MIN(MAX($B$14,$E32),$F32) -> 80.031 | K32: =MIN(MAX($B$15,$E32),$F32) -> 80.057333 | L32: =MIN(MAX($B$16,$E32),$F32) -> 79.983667 | M32: =MIN(MAX($B$17,$E32),$F32) -> 80.091 | N32: =MIN(MAX($B$18,$E32),$F32) -> 80.158 | O32: =MIN(MAX($B$19,$E32),$F32) -> 80.260667 | P32: =MIN(MAX($B$20,$E32),$F32) -> 79.991667 | Q32: =MIN(MAX($B$21,$E32),$F32) -> 80.047333 | R32: =MIN(MAX($B$22,$E32),$F32) -> 80.247667 | S32: =AVERAGE(G32:R32) -> 80.103306 | T32: =1.134*STDEV(G32:R32) -> 0.11048474 | U32: =ABS(S32-B32) -> 0 | V32: =ABS(T32-C32) -> 0 | W32: =IF(OR(NOT(ISNUMBER(B32)),B32=0),B32,ROUND(B32,MAX(3-1-INT(LOG10(ABS(B32))),0))) -> 80.1 | X32: =IF(OR(NOT(ISNUMBER(C32)),C32=0),C32,ROUND(C32,MAX(3-1-INT(LOG10(ABS(C32))),0))) -> 0.11 | Y32: =IF(OR(NOT(ISNUMBER(S32)),S32=0),S32,ROUND(S32,MAX(3-1-INT(LOG10(ABS(S32))),0))) -> 80.1 | Z32: =IF(OR(NOT(ISNUMBER(T32)),T32=0),T32,ROUND(T32,MAX(3-1-INT(LOG10(ABS(T32))),0))) -> 0.11 | AA32: =IF(AND(Y32=W32,Z32=X32),1,0) -> 1 | AB32: =IF(AND(U32<$B$4,V32<$B$4),1,0) -> 1 | AC32: =IF(OR(AA32=1,AB32=1),1,0) -> 1
A33: 7 | B33: =S32 -> 80.103306 | C33: =T32 -> 0.11048474 | D33: =1.5*C33 -> 0.16572711 | E33: =B33-D33 -> 79.937578 | F33: =B33+D33 -> 80.269033 | G33: =MIN(MAX($B$11,$E33),$F33) -> 80.229333 | H33: =MIN(MAX($B$12,$E33),$F33) -> 80.086 | I33: =MIN(MAX($B$13,$E33),$F33) -> 80.056 | J33: =MIN(MAX($B$14,$E33),$F33) -> 80.031 | K33: =MIN(MAX($B$15,$E33),$F33) -> 80.057333 | L33: =MIN(MAX($B$16,$E33),$F33) -> 79.983667 | M33: =MIN(MAX($B$17,$E33),$F33) -> 80.091 | N33: =MIN(MAX($B$18,$E33),$F33) -> 80.158 | O33: =MIN(MAX($B$19,$E33),$F33) -> 80.260667 | P33: =MIN(MAX($B$20,$E33),$F33) -> 79.991667 | Q33: =MIN(MAX($B$21,$E33),$F33) -> 80.047333 | R33: =MIN(MAX($B$22,$E33),$F33) -> 80.247667 | S33: =AVERAGE(G33:R33) -> 80.103306 | T33: =1.134*STDEV(G33:R33) -> 0.11048474 | U33: =ABS(S33-B33) -> 0 | V33: =ABS(T33-C33) -> 0 | W33: =IF(OR(NOT(ISNUMBER(B33)),B33=0),B33,ROUND(B33,MAX(3-1-INT(LOG10(ABS(B33))),0))) -> 80.1 | X33: =IF(OR(NOT(ISNUMBER(C33)),C33=0),C33,ROUND(C33,MAX(3-1-INT(LOG10(ABS(C33))),0))) -> 0.11 | Y33: =IF(OR(NOT(ISNUMBER(S33)),S33=0),S33,ROUND(S33,MAX(3-1-INT(LOG10(ABS(S33))),0))) -> 80.1 | Z33: =IF(OR(NOT(ISNUMBER(T33)),T33=0),T33,ROUND(T33,MAX(3-1-INT(LOG10(ABS(T33))),0))) -> 0.11 | AA33: =IF(AND(Y33=W33,Z33=X33),1,0) -> 1 | AB33: =IF(AND(U33<$B$4,V33<$B$4),1,0) -> 1 | AC33: =IF(OR(AA33=1,AB33=1),1,0) -> 1
A34: 8 | B34: =S33 -> 80.103306 | C34: =T33 -> 0.11048474 | D34: =1.5*C34 -> 0.16572711 | E34: =B34-D34 -> 79.937578 | F34: =B34+D34 -> 80.269033 | G34: =MIN(MAX($B$11,$E34),$F34) -> 80.229333 | H34: =MIN(MAX($B$12,$E34),$F34) -> 80.086 | I34: =MIN(MAX($B$13,$E34),$F34) -> 80.056 | J34: =MIN(MAX($B$14,$E34),$F34) -> 80.031 | K34: =MIN(MAX($B$15,$E34),$F34) -> 80.057333 | L34: =MIN(MAX($B$16,$E34),$F34) -> 79.983667 | M34: =MIN(MAX($B$17,$E34),$F34) -> 80.091 | N34: =MIN(MAX($B$18,$E34),$F34) -> 80.158 | O34: =MIN(MAX($B$19,$E34),$F34) -> 80.260667 | P34: =MIN(MAX($B$20,$E34),$F34) -> 79.991667 | Q34: =MIN(MAX($B$21,$E34),$F34) -> 80.047333 | R34: =MIN(MAX($B$22,$E34),$F34) -> 80.247667 | S34: =AVERAGE(G34:R34) -> 80.103306 | T34: =1.134*STDEV(G34:R34) -> 0.11048474 | U34: =ABS(S34-B34) -> 0 | V34: =ABS(T34-C34) -> 0 | W34: =IF(OR(NOT(ISNUMBER(B34)),B34=0),B34,ROUND(B34,MAX(3-1-INT(LOG10(ABS(B34))),0))) -> 80.1 | X34: =IF(OR(NOT(ISNUMBER(C34)),C34=0),C34,ROUND(C34,MAX(3-1-INT(LOG10(ABS(C34))),0))) -> 0.11 | Y34: =IF(OR(NOT(ISNUMBER(S34)),S34=0),S34,ROUND(S34,MAX(3-1-INT(LOG10(ABS(S34))),0))) -> 80.1 | Z34: =IF(OR(NOT(ISNUMBER(T34)),T34=0),T34,ROUND(T34,MAX(3-1-INT(LOG10(ABS(T34))),0))) -> 0.11 | AA34: =IF(AND(Y34=W34,Z34=X34),1,0) -> 1 | AB34: =IF(AND(U34<$B$4,V34<$B$4),1,0) -> 1 | AC34: =IF(OR(AA34=1,AB34=1),1,0) -> 1
A35: 9 | B35: =S34 -> 80.103306 | C35: =T34 -> 0.11048474 | D35: =1.5*C35 -> 0.16572711 | E35: =B35-D35 -> 79.937578 | F35: =B35+D35 -> 80.269033 | G35: =MIN(MAX($B$11,$E35),$F35) -> 80.229333 | H35: =MIN(MAX($B$12,$E35),$F35) -> 80.086 | I35: =MIN(MAX($B$13,$E35),$F35) -> 80.056 | J35: =MIN(MAX($B$14,$E35),$F35) -> 80.031 | K35: =MIN(MAX($B$15,$E35),$F35) -> 80.057333 | L35: =MIN(MAX($B$16,$E35),$F35) -> 79.983667 | M35: =MIN(MAX($B$17,$E35),$F35) -> 80.091 | N35: =MIN(MAX($B$18,$E35),$F35) -> 80.158 | O35: =MIN(MAX($B$19,$E35),$F35) -> 80.260667 | P35: =MIN(MAX($B$20,$E35),$F35) -> 79.991667 | Q35: =MIN(MAX($B$21,$E35),$F35) -> 80.047333 | R35: =MIN(MAX($B$22,$E35),$F35) -> 80.247667 | S35: =AVERAGE(G35:R35) -> 80.103306 | T35: =1.134*STDEV(G35:R35) -> 0.11048474 | U35: =ABS(S35-B35) -> 0 | V35: =ABS(T35-C35) -> 0 | W35: =IF(OR(NOT(ISNUMBER(B35)),B35=0),B35,ROUND(B35,MAX(3-1-INT(LOG10(ABS(B35))),0))) -> 80.1 | X35: =IF(OR(NOT(ISNUMBER(C35)),C35=0),C35,ROUND(C35,MAX(3-1-INT(LOG10(ABS(C35))),0))) -> 0.11 | Y35: =IF(OR(NOT(ISNUMBER(S35)),S35=0),S35,ROUND(S35,MAX(3-1-INT(LOG10(ABS(S35))),0))) -> 80.1 | Z35: =IF(OR(NOT(ISNUMBER(T35)),T35=0),T35,ROUND(T35,MAX(3-1-INT(LOG10(ABS(T35))),0))) -> 0.11 | AA35: =IF(AND(Y35=W35,Z35=X35),1,0) -> 1 | AB35: =IF(AND(U35<$B$4,V35<$B$4),1,0) -> 1 | AC35: =IF(OR(AA35=1,AB35=1),1,0) -> 1
A36: 10 | B36: =S35 -> 80.103306 | C36: =T35 -> 0.11048474 | D36: =1.5*C36 -> 0.16572711 | E36: =B36-D36 -> 79.937578 | F36: =B36+D36 -> 80.269033 | G36: =MIN(MAX($B$11,$E36),$F36) -> 80.229333 | H36: =MIN(MAX($B$12,$E36),$F36) -> 80.086 | I36: =MIN(MAX($B$13,$E36),$F36) -> 80.056 | J36: =MIN(MAX($B$14,$E36),$F36) -> 80.031 | K36: =MIN(MAX($B$15,$E36),$F36) -> 80.057333 | L36: =MIN(MAX($B$16,$E36),$F36) -> 79.983667 | M36: =MIN(MAX($B$17,$E36),$F36) -> 80.091 | N36: =MIN(MAX($B$18,$E36),$F36) -> 80.158 | O36: =MIN(MAX($B$19,$E36),$F36) -> 80.260667 | P36: =MIN(MAX($B$20,$E36),$F36) -> 79.991667 | Q36: =MIN(MAX($B$21,$E36),$F36) -> 80.047333 | R36: =MIN(MAX($B$22,$E36),$F36) -> 80.247667 | S36: =AVERAGE(G36:R36) -> 80.103306 | T36: =1.134*STDEV(G36:R36) -> 0.11048474 | U36: =ABS(S36-B36) -> 0 | V36: =ABS(T36-C36) -> 0 | W36: =IF(OR(NOT(ISNUMBER(B36)),B36=0),B36,ROUND(B36,MAX(3-1-INT(LOG10(ABS(B36))),0))) -> 80.1 | X36: =IF(OR(NOT(ISNUMBER(C36)),C36=0),C36,ROUND(C36,MAX(3-1-INT(LOG10(ABS(C36))),0))) -> 0.11 | Y36: =IF(OR(NOT(ISNUMBER(S36)),S36=0),S36,ROUND(S36,MAX(3-1-INT(LOG10(ABS(S36))),0))) -> 80.1 | Z36: =IF(OR(NOT(ISNUMBER(T36)),T36=0),T36,ROUND(T36,MAX(3-1-INT(LOG10(ABS(T36))),0))) -> 0.11 | AA36: =IF(AND(Y36=W36,Z36=X36),1,0) -> 1 | AB36: =IF(AND(U36<$B$4,V36<$B$4),1,0) -> 1 | AC36: =IF(OR(AA36=1,AB36=1),1,0) -> 1
A37: 11 | B37: =S36 -> 80.103306 | C37: =T36 -> 0.11048474 | D37: =1.5*C37 -> 0.16572711 | E37: =B37-D37 -> 79.937578 | F37: =B37+D37 -> 80.269033 | G37: =MIN(MAX($B$11,$E37),$F37) -> 80.229333 | H37: =MIN(MAX($B$12,$E37),$F37) -> 80.086 | I37: =MIN(MAX($B$13,$E37),$F37) -> 80.056 | J37: =MIN(MAX($B$14,$E37),$F37) -> 80.031 | K37: =MIN(MAX($B$15,$E37),$F37) -> 80.057333 | L37: =MIN(MAX($B$16,$E37),$F37) -> 79.983667 | M37: =MIN(MAX($B$17,$E37),$F37) -> 80.091 | N37: =MIN(MAX($B$18,$E37),$F37) -> 80.158 | O37: =MIN(MAX($B$19,$E37),$F37) -> 80.260667 | P37: =MIN(MAX($B$20,$E37),$F37) -> 79.991667 | Q37: =MIN(MAX($B$21,$E37),$F37) -> 80.047333 | R37: =MIN(MAX($B$22,$E37),$F37) -> 80.247667 | S37: =AVERAGE(G37:R37) -> 80.103306 | T37: =1.134*STDEV(G37:R37) -> 0.11048474 | U37: =ABS(S37-B37) -> 0 | V37: =ABS(T37-C37) -> 0 | W37: =IF(OR(NOT(ISNUMBER(B37)),B37=0),B37,ROUND(B37,MAX(3-1-INT(LOG10(ABS(B37))),0))) -> 80.1 | X37: =IF(OR(NOT(ISNUMBER(C37)),C37=0),C37,ROUND(C37,MAX(3-1-INT(LOG10(ABS(C37))),0))) -> 0.11 | Y37: =IF(OR(NOT(ISNUMBER(S37)),S37=0),S37,ROUND(S37,MAX(3-1-INT(LOG10(ABS(S37))),0))) -> 80.1 | Z37: =IF(OR(NOT(ISNUMBER(T37)),T37=0),T37,ROUND(T37,MAX(3-1-INT(LOG10(ABS(T37))),0))) -> 0.11 | AA37: =IF(AND(Y37=W37,Z37=X37),1,0) -> 1 | AB37: =IF(AND(U37<$B$4,V37<$B$4),1,0) -> 1 | AC37: =IF(OR(AA37=1,AB37=1),1,0) -> 1
A38: 12 | B38: =S37 -> 80.103306 | C38: =T37 -> 0.11048474 | D38: =1.5*C38 -> 0.16572711 | E38: =B38-D38 -> 79.937578 | F38: =B38+D38 -> 80.269033 | G38: =MIN(MAX($B$11,$E38),$F38) -> 80.229333 | H38: =MIN(MAX($B$12,$E38),$F38) -> 80.086 | I38: =MIN(MAX($B$13,$E38),$F38) -> 80.056 | J38: =MIN(MAX($B$14,$E38),$F38) -> 80.031 | K38: =MIN(MAX($B$15,$E38),$F38) -> 80.057333 | L38: =MIN(MAX($B$16,$E38),$F38) -> 79.983667 | M38: =MIN(MAX($B$17,$E38),$F38) -> 80.091 | N38: =MIN(MAX($B$18,$E38),$F38) -> 80.158 | O38: =MIN(MAX($B$19,$E38),$F38) -> 80.260667 | P38: =MIN(MAX($B$20,$E38),$F38) -> 79.991667 | Q38: =MIN(MAX($B$21,$E38),$F38) -> 80.047333 | R38: =MIN(MAX($B$22,$E38),$F38) -> 80.247667 | S38: =AVERAGE(G38:R38) -> 80.103306 | T38: =1.134*STDEV(G38:R38) -> 0.11048474 | U38: =ABS(S38-B38) -> 0 | V38: =ABS(T38-C38) -> 0 | W38: =IF(OR(NOT(ISNUMBER(B38)),B38=0),B38,ROUND(B38,MAX(3-1-INT(LOG10(ABS(B38))),0))) -> 80.1 | X38: =IF(OR(NOT(ISNUMBER(C38)),C38=0),C38,ROUND(C38,MAX(3-1-INT(LOG10(ABS(C38))),0))) -> 0.11 | Y38: =IF(OR(NOT(ISNUMBER(S38)),S38=0),S38,ROUND(S38,MAX(3-1-INT(LOG10(ABS(S38))),0))) -> 80.1 | Z38: =IF(OR(NOT(ISNUMBER(T38)),T38=0),T38,ROUND(T38,MAX(3-1-INT(LOG10(ABS(T38))),0))) -> 0.11 | AA38: =IF(AND(Y38=W38,Z38=X38),1,0) -> 1 | AB38: =IF(AND(U38<$B$4,V38<$B$4),1,0) -> 1 | AC38: =IF(OR(AA38=1,AB38=1),1,0) -> 1
A39: 13 | B39: =S38 -> 80.103306 | C39: =T38 -> 0.11048474 | D39: =1.5*C39 -> 0.16572711 | E39: =B39-D39 -> 79.937578 | F39: =B39+D39 -> 80.269033 | G39: =MIN(MAX($B$11,$E39),$F39) -> 80.229333 | H39: =MIN(MAX($B$12,$E39),$F39) -> 80.086 | I39: =MIN(MAX($B$13,$E39),$F39) -> 80.056 | J39: =MIN(MAX($B$14,$E39),$F39) -> 80.031 | K39: =MIN(MAX($B$15,$E39),$F39) -> 80.057333 | L39: =MIN(MAX($B$16,$E39),$F39) -> 79.983667 | M39: =MIN(MAX($B$17,$E39),$F39) -> 80.091 | N39: =MIN(MAX($B$18,$E39),$F39) -> 80.158 | O39: =MIN(MAX($B$19,$E39),$F39) -> 80.260667 | P39: =MIN(MAX($B$20,$E39),$F39) -> 79.991667 | Q39: =MIN(MAX($B$21,$E39),$F39) -> 80.047333 | R39: =MIN(MAX($B$22,$E39),$F39) -> 80.247667 | S39: =AVERAGE(G39:R39) -> 80.103306 | T39: =1.134*STDEV(G39:R39) -> 0.11048474 | U39: =ABS(S39-B39) -> 0 | V39: =ABS(T39-C39) -> 0 | W39: =IF(OR(NOT(ISNUMBER(B39)),B39=0),B39,ROUND(B39,MAX(3-1-INT(LOG10(ABS(B39))),0))) -> 80.1 | X39: =IF(OR(NOT(ISNUMBER(C39)),C39=0),C39,ROUND(C39,MAX(3-1-INT(LOG10(ABS(C39))),0))) -> 0.11 | Y39: =IF(OR(NOT(ISNUMBER(S39)),S39=0),S39,ROUND(S39,MAX(3-1-INT(LOG10(ABS(S39))),0))) -> 80.1 | Z39: =IF(OR(NOT(ISNUMBER(T39)),T39=0),T39,ROUND(T39,MAX(3-1-INT(LOG10(ABS(T39))),0))) -> 0.11 | AA39: =IF(AND(Y39=W39,Z39=X39),1,0) -> 1 | AB39: =IF(AND(U39<$B$4,V39<$B$4),1,0) -> 1 | AC39: =IF(OR(AA39=1,AB39=1),1,0) -> 1
... A76: 50 | B76: =S75 -> 80.103306 | C76: =T75 -> 0.11048474 | D76: =1.5*C76 -> 0.16572711 | E76: =B76-D76 -> 79.937578 | F76: =B76+D76 -> 80.269033 | G76: =MIN(MAX($B$11,$E76),$F76) -> 80.229333 | H76: =MIN(MAX($B$12,$E76),$F76) -> 80.086 | I76: =MIN(MAX($B$13,$E76),$F76) -> 80.056 | J76: =MIN(MAX($B$14,$E76),$F76) -> 80.031 | K76: =MIN(MAX($B$15,$E76),$F76) -> 80.057333 | L76: =MIN(MAX($B$16,$E76),$F76) -> 79.983667 | M76: =MIN(MAX($B$17,$E76),$F76) -> 80.091 | N76: =MIN(MAX($B$18,$E76),$F76) -> 80.158 | O76: =MIN(MAX($B$19,$E76),$F76) -> 80.260667 | P76: =MIN(MAX($B$20,$E76),$F76) -> 79.991667 | Q76: =MIN(MAX($B$21,$E76),$F76) -> 80.047333 | R76: =MIN(MAX($B$22,$E76),$F76) -> 80.247667 | S76: =AVERAGE(G76:R76) -> 80.103306 | T76: =1.134*STDEV(G76:R76) -> 0.11048474 | U76: =ABS(S76-B76) -> 0 | V76: =ABS(T76-C76) -> 0 | W76: =IF(OR(NOT(ISNUMBER(B76)),B76=0),B76,ROUND(B76,MAX(3-1-INT(LOG10(ABS(B76))),0))) -> 80.1 | X76: =IF(OR(NOT(ISNUMBER(C76)),C76=0),C76,ROUND(C76,MAX(3-1-INT(LOG10(ABS(C76))),0))) -> 0.11 | Y76: =IF(OR(NOT(ISNUMBER(S76)),S76=0),S76,ROUND(S76,MAX(3-1-INT(LOG10(ABS(S76))),0))) -> 80.1 | Z76: =IF(OR(NOT(ISNUMBER(T76)),T76=0),T76,ROUND(T76,MAX(3-1-INT(LOG10(ABS(T76))),0))) -> 0.11 | AA76: =IF(AND(Y76=W76,Z76=X76),1,0) -> 1 | AB76: =IF(AND(U76<$B$4,V76<$B$4),1,0) -> 1 | AC76: =IF(OR(AA76=1,AB76=1),1,0) -> 1

Sheet valor_asignado
A1: method_key | B1: method | C1: x_pt | D1: sigma_pt | E1: u_xpt | F1: u_hom | G1: u_stab | H1: u_xpt_def | I1: U_xpt | J1: n_participants | K1: estado
A2: ref | B2: Referencia (1) | C2: =datos_referencia!$D$2 -> 79.896333 | D2: =0.02*datos_referencia!$D$2+1 -> 2.5979267 | E2: =datos_referencia!$E$2 -> 0.57033333 | F2: =calc_homogeneidad!$B$9 -> 0.1993079 | G2: =calc_estabilidad!$B$10/SQRT(3) -> 0.12479426 | H2: =SQRT(E2^2+F2^2+G2^2) -> 0.61690952 | I2: =2*H2 -> 1.233819 | J2: =COUNT(datos_participantes!$D:$D) -> 12 | K2: =IF(SUM(ABS(C2-validacion_snapshot!$K$30),ABS(D2-validacion_snapshot!$L$30),ABS(E2-validacion_snapshot!$M$30),ABS(F2-validacion_snapshot!$N$30),ABS(G2-validacion_snapshot!$O$30),ABS(H2-validacion_snapshot!$P$30),ABS(I2-validacion_snapshot!$Q$30),ABS(J2-validacion_snapshot!$R$30))<=0.00000001,"OK","FALLA") -> OK
A3: consensus_ma | B3: Consenso MADe (2a) | C3: =MEDIAN(datos_participantes!$D$2:$D$13) -> 80.071667 | D3: =algoritmo_A_iteraciones!$B$3 -> 0.089474333 | E3: =1.25*D3/SQRT(COUNT(datos_participantes!$D:$D)) -> 0.032286269 | F3: =calc_homogeneidad!$B$9 -> 0.1993079 | G3: =calc_estabilidad!$B$10/SQRT(3) -> 0.12479426 | H3: =SQRT(E3^2+F3^2+G3^2) -> 0.23735975 | I3: =2*H3 -> 0.47471949 | J3: =COUNT(datos_participantes!$D:$D) -> 12 | K3: =IF(SUM(ABS(C3-validacion_snapshot!$K$31),ABS(D3-validacion_snapshot!$L$31),ABS(E3-validacion_snapshot!$M$31),ABS(F3-validacion_snapshot!$N$31),ABS(G3-validacion_snapshot!$O$31),ABS(H3-validacion_snapshot!$P$31),ABS(I3-validacion_snapshot!$Q$31),ABS(J3-validacion_snapshot!$R$31))<=0.00000001,"OK","FALLA") -> OK
A4: consensus_niqr | B4: Consenso nIQR (2b) | C4: =MEDIAN(datos_participantes!$D$2:$D$13) -> 80.071667 | D4: =0.7413*(QUARTILE(datos_participantes!$D$2:$D$13,3)-QUARTILE(datos_participantes!$D$2:$D$13,1)) -> 0.098284025 | E4: =1.25*D4/SQRT(COUNT(datos_participantes!$D:$D)) -> 0.035465193 | F4: =calc_homogeneidad!$B$9 -> 0.1993079 | G4: =calc_estabilidad!$B$10/SQRT(3) -> 0.12479426 | H4: =SQRT(E4^2+F4^2+G4^2) -> 0.23781301 | I4: =2*H4 -> 0.47562601 | J4: =COUNT(datos_participantes!$D:$D) -> 12 | K4: =IF(SUM(ABS(C4-validacion_snapshot!$K$32),ABS(D4-validacion_snapshot!$L$32),ABS(E4-validacion_snapshot!$M$32),ABS(F4-validacion_snapshot!$N$32),ABS(G4-validacion_snapshot!$O$32),ABS(H4-validacion_snapshot!$P$32),ABS(I4-validacion_snapshot!$Q$32),ABS(J4-validacion_snapshot!$R$32))<=0.00000001,"OK","FALLA") -> OK
A5: algo | B5: Algoritmo A (3) | C5: =algoritmo_A_iteraciones!$B$7 -> 80.103306 | D5: =algoritmo_A_iteraciones!$B$8 -> 0.11048474 | E5: =1.25*D5/SQRT(COUNT(datos_participantes!$D:$D)) -> 0.039867747 | F5: =calc_homogeneidad!$B$9 -> 0.1993079 | G5: =calc_estabilidad!$B$10/SQRT(3) -> 0.12479426 | H5: =SQRT(E5^2+F5^2+G5^2) -> 0.23850929 | I5: =2*H5 -> 0.47701859 | J5: =COUNT(datos_participantes!$D:$D) -> 12 | K5: =IF(SUM(ABS(C5-validacion_snapshot!$K$33),ABS(D5-validacion_snapshot!$L$33),ABS(E5-validacion_snapshot!$M$33),ABS(F5-validacion_snapshot!$N$33),ABS(G5-validacion_snapshot!$O$33),ABS(H5-validacion_snapshot!$P$33),ABS(I5-validacion_snapshot!$Q$33),ABS(J5-validacion_snapshot!$R$33))<=0.00000001,"OK","FALLA") -> OK
A6: expert | B6: Expertos (4) | C6: =datos_referencia!$D$2 -> 79.896333 | D6: =0.02*datos_referencia!$D$2+1 -> 2.5979267 | E6: =datos_referencia!$E$2 -> 0.57033333 | F6: =calc_homogeneidad!$B$9 -> 0.1993079 | G6: =calc_estabilidad!$B$10/SQRT(3) -> 0.12479426 | H6: =SQRT(E6^2+F6^2+G6^2) -> 0.61690952 | I6: =2*H6 -> 1.233819 | J6: =COUNT(datos_participantes!$D:$D) -> 12 | K6: =IF(SUM(ABS(C6-validacion_snapshot!$K$34),ABS(D6-validacion_snapshot!$L$34),ABS(E6-validacion_snapshot!$M$34),ABS(F6-validacion_snapshot!$N$34),ABS(G6-validacion_snapshot!$O$34),ABS(H6-validacion_snapshot!$P$34),ABS(I6-validacion_snapshot!$Q$34),ABS(J6-validacion_snapshot!$R$34))<=0.00000001,"OK","FALLA") -> OK

Sheet algoritmo_A
A1: bloque | B1: parametro | C1: app_value | D1: calculado | E1: estado
A2: Algoritmo A | B2: Analito | C2: O3 | D2: ="O3" -> O3 | E2: =IF(IFERROR(ABS(D2-validacion_snapshot!$H$35)<=0.0005,D2=validacion_snapshot!$H$35),"OK","FALLA") -> OK
A3: Algoritmo A | B3: Esquema (n) | C3: 13 | D3: =13 -> 13 | E3: =IF(IFERROR(ABS(D3-validacion_snapshot!$H$36)<=0.0005,D3=validacion_snapshot!$H$36),"OK","FALLA") -> OK
A4: Algoritmo A | B4: Nivel | C4: 80-nmol/mol | D4: ="80-nmol/mol" -> 80-nmol/mol | E4: =IF(IFERROR(ABS(D4-validacion_snapshot!$H$37)<=0.0005,D4=validacion_snapshot!$H$37),"OK","FALLA") -> OK
A5: Algoritmo A | B5: n participantes | C5: 12 | D5: =algoritmo_A_iteraciones!$B$5 -> 12 | E5: =IF(IFERROR(ABS(D5-validacion_snapshot!$H$38)<=0.0005,D5=validacion_snapshot!$H$38),"OK","FALLA") -> OK
A6: Algoritmo A | B6: x*0 = mediana | C6: 80.0717 | D6: =ROUND(algoritmo_A_iteraciones!$B$2,4) -> 80.0717 | E6: =IF(IFERROR(ABS(D6-validacion_snapshot!$H$39)<=0.0005,D6=validacion_snapshot!$H$39),"OK","FALLA") -> OK
A7: Algoritmo A | B7: s*0 = MADe | C7: 0.0895 | D7: =ROUND(algoritmo_A_iteraciones!$B$3,4) -> 0.0895 | E7: =IF(IFERROR(ABS(D7-validacion_snapshot!$H$40)<=0.0005,D7=validacion_snapshot!$H$40),"OK","FALLA") -> OK
A8: Algoritmo A | B8: x* (valor asignado) | C8: 80.1033 | D8: =ROUND(algoritmo_A_iteraciones!$B$7,4) -> 80.1033 | E8: =IF(IFERROR(ABS(D8-validacion_snapshot!$H$41)<=0.0005,D8=validacion_snapshot!$H$41),"OK","FALLA") -> OK
A9: Algoritmo A | B9: s* (desviación robusta) | C9: 0.1105 | D9: =ROUND(algoritmo_A_iteraciones!$B$8,4) -> 0.1105 | E9: =IF(IFERROR(ABS(D9-validacion_snapshot!$H$42)<=0.0005,D9=validacion_snapshot!$H$42),"OK","FALLA") -> OK
A10: Algoritmo A | B10: Observaciones winzorizadas | C10: 0 | D10: =algoritmo_A_iteraciones!$B$9 -> 0 | E10: =IF(IFERROR(ABS(D10-validacion_snapshot!$H$43)<=0.0005,D10=validacion_snapshot!$H$43),"OK","FALLA") -> OK
A11: Algoritmo A | B11: Observaciones totales | C11: 12 | D11: =algoritmo_A_iteraciones!$B$5 -> 12 | E11: =IF(IFERROR(ABS(D11-validacion_snapshot!$H$44)<=0.0005,D11=validacion_snapshot!$H$44),"OK","FALLA") -> OK
A12: Algoritmo A | B12: n_iteraciones | C12: 4 | D12: =algoritmo_A_iteraciones!$B$6 -> 4 | E12: =IF(IFERROR(ABS(D12-validacion_snapshot!$H$45)<=0.0005,D12=validacion_snapshot!$H$45),"OK","FALLA") -> OK
A13: Algoritmo A | B13: criterio | C13: 3 cifras significativas | D13: ="3 cifras significativas" -> 3 cifras significativas | E13: =IF(IFERROR(ABS(D13-validacion_snapshot!$H$46)<=0.0005,D13=validacion_snapshot!$H$46),"OK","FALLA") -> OK
A14: Algoritmo A | B14: guardia_numérica | C14: 0.0000000001 | D14: =TEXT(algoritmo_A_iteraciones!$B$4,"0.0000000000") -> 0.0000000001 | E14: =IF(IFERROR(ABS(D14-validacion_snapshot!$H$47)<=0.0005,D14=validacion_snapshot!$H$47),"OK","FALLA") -> OK
A15: Algoritmo A | B15: primera_iteración_3ra_cifra | C15: 4 | D15: =algoritmo_A_iteraciones!$B$6 -> 4 | E15: =IF(IFERROR(ABS(D15-validacion_snapshot!$H$48)<=0.0005,D15=validacion_snapshot!$H$48),"OK","FALLA") -> OK

Sheet puntajes_EA
A1: method_key | B1: method | C1: participant_id | D1: result | E1: u_xi | F1: z_score | G1: z_score_eval | H1: z_prime_score | I1: z_prime_score_eval | J1: zeta_score | K1: zeta_score_eval | L1: En_score | M1: En_score_eval | N1: estado
B2: Referencia (1) | C2: part_1 | D2: =INDEX(datos_participantes!$D:$D,MATCH(C2,datos_participantes!$A:$A,0)) -> 80.229333 | E2: =INDEX(datos_participantes!$F:$F,MATCH(C2,datos_participantes!$A:$A,0)) -> 0.030643408 | F2: =IF(OR(NOT(ISNUMBER(D2)),NOT(ISNUMBER(INDEX(valor_asignado!$C:$C,MATCH(B2,valor_asignado!$B:$B,0)))),NOT(ISNUMBER(INDEX(valor_asignado!$D:$D,MATCH(B2,valor_asignado!$B:$B,0)))),INDEX(valor_asignado!$D:$D,MATCH(B2,valor_asignado!$B:$B,0))=0),"",(D2-INDEX(valor_asignado!$C:$C,MATCH(B2,valor_asignado!$B:$B,0)))/INDEX(valor_asignado!$D:$D,MATCH(B2,valor_asignado!$B:$B,0))) -> 0.12817914 | G2: =IF(F2="","N/A",IF(ABS(F2)<=2,"Satisfactorio",IF(ABS(F2)<3,"Cuestionable","No satisfactorio"))) -> Satisfactorio | H2: =IF(OR(NOT(ISNUMBER(D2)),NOT(ISNUMBER(INDEX(valor_asignado!$C:$C,MATCH(B2,valor_asignado!$B:$B,0)))),NOT(ISNUMBER(SQRT(INDEX(valor_asignado!$D:$D,MATCH(B2,valor_asignado!$B:$B,0))^2+INDEX(valor_asignado!$H:$H,MATCH(B2,valor_asignado!$B:$B,0))^2))),SQRT(INDEX(valor_asignado!$D:$D,MATCH(B2,valor_asignado!$B:$B,0))^2+INDEX(valor_asignado!$H:$H,MATCH(B2,valor_asignado!$B:$B,0))^2)=0),"",(D2-INDEX(valor_asignado!$C:$C,MATCH(B2,valor_asignado!$B:$B,0)))/SQRT(INDEX(valor_asignado!$D:$D,MATCH(B2,valor_asignado!$B:$B,0))^2+INDEX(valor_asignado!$H:$H,MATCH(B2,valor_asignado!$B:$B,0))^2)) -> 0.12471123 | I2: =IF(H2="","N/A",IF(ABS(H2)<=2,"Satisfactorio",IF(ABS(H2)<3,"Cuestionable","No satisfactorio"))) -> Satisfactorio | J2: =IF(OR(NOT(ISNUMBER(D2)),NOT(ISNUMBER(INDEX(valor_asignado!$C:$C,MATCH(B2,valor_asignado!$B:$B,0)))),NOT(ISNUMBER(SQRT(E2^2+INDEX(valor_asignado!$H:$H,MATCH(B2,valor_asignado!$B:$B,0))^2))),SQRT(E2^2+INDEX(valor_asignado!$H:$H,MATCH(B2,valor_asignado!$B:$B,0))^2)=0),"",(D2-INDEX(valor_asignado!$C:$C,MATCH(B2,valor_asignado!$B:$B,0)))/SQRT(E2^2+INDEX(valor_asignado!$H:$H,MATCH(B2,valor_asignado!$B:$B,0))^2)) -> 0.53912273 | K2: =IF(J2="","N/A",IF(ABS(J2)<=2,"Satisfactorio",IF(ABS(J2)<3,"Cuestionable","No satisfactorio"))) -> Satisfactorio | L2: =IF(OR(NOT(ISNUMBER(D2)),NOT(ISNUMBER(INDEX(valor_asignado!$C:$C,MATCH(B2,valor_asignado!$B:$B,0)))),NOT(ISNUMBER(SQRT((2*E2)^2+(2*INDEX(valor_asignado!$H:$H,MATCH(B2,valor_asignado!$B:$B,0)))^2))),SQRT((2*E2)^2+(2*INDEX(valor_asignado!$H:$H,MATCH(B2,valor_asignado!$B:$B,0)))^2)=0),"",(D2-INDEX(valor_asignado!$C:$C,MATCH(B2,valor_asignado!$B:$B,0)))/SQRT((2*E2)^2+(2*INDEX(valor_asignado!$H:$H,MATCH(B2,valor_asignado!$B:$B,0)))^2)) -> 0.26956136 | M2: =IF(L2="","N/A",IF(ABS(L2)<=1,"Satisfactorio","No satisfactorio")) -> Satisfactorio | N2: =IF(AND(SUM(IF(AND(D2="",validacion_snapshot!$U$49=""),0,IFERROR(ABS(D2-validacion_snapshot!$U$49),1E+099)),IF(AND(E2="",validacion_snapshot!$V$49=""),0,IFERROR(ABS(E2-validacion_snapshot!$V$49),1E+099)),IF(AND(F2="",validacion_snapshot!$W$49=""),0,IFERROR(ABS(F2-validacion_snapshot!$W$49),1E+099)),IF(AND(H2="",validacion_snapshot!$Y$49=""),0,IFERROR(ABS(H2-validacion_snapshot!$Y$49),1E+099)),IF(AND(J2="",validacion_snapshot!$AA$49=""),0,IFERROR(ABS(J2-validacion_snapshot!$AA$49),1E+099)),IF(AND(L2="",validacion_snapshot!$AC$49=""),0,IFERROR(ABS(L2-validacion_snapshot!$AC$49),1E+099)))<=0.00000001,G2=validacion_snapshot!$X$49,I2=validacion_snapshot!$Z$49,K2=validacion_snapshot!$AB$49,M2=validacion_snapshot!$AD$49),"OK","FALLA") -> OK
B3: Referencia (1) | C3: part_10 | D3: =INDEX(datos_participantes!$D:$D,MATCH(C3,datos_participantes!$A:$A,0)) -> 80.086 | E3: =INDEX(datos_participantes!$F:$F,MATCH(C3,datos_participantes!$A:$A,0)) -> 0.011708712 | F3: =IF(OR(NOT(ISNUMBER(D3)),NOT(ISNUMBER(INDEX(valor_asignado!$C:$C,MATCH(B3,valor_asignado!$B:$B,0)))),NOT(ISNUMBER(INDEX(valor_asignado!$D:$D,MATCH(B3,valor_asignado!$B:$B,0)))),INDEX(valor_asignado!$D:$D,MATCH(B3,valor_asignado!$B:$B,0))=0),"",(D3-INDEX(valor_asignado!$C:$C,MATCH(B3,valor_asignado!$B:$B,0)))/INDEX(valor_asignado!$D:$D,MATCH(B3,valor_asignado!$B:$B,0))) -> 0.073006936 | G3: =IF(F3="","N/A",IF(ABS(F3)<=2,"Satisfactorio",IF(ABS(F3)<3,"Cuestionable","No satisfactorio"))) -> Satisfactorio | H3: =IF(OR(NOT(ISNUMBER(D3)),NOT(ISNUMBER(INDEX(valor_asignado!$C:$C,MATCH(B3,valor_asignado!$B:$B,0)))),NOT(ISNUMBER(SQRT(INDEX(valor_asignado!$D:$D,MATCH(B3,valor_asignado!$B:$B,0))^2+INDEX(valor_asignado!$H:$H,MATCH(B3,valor_asignado!$B:$B,0))^2))),SQRT(INDEX(valor_asignado!$D:$D,MATCH(B3,valor_asignado!$B:$B,0))^2+INDEX(valor_asignado!$H:$H,MATCH(B3,valor_asignado!$B:$B,0))^2)=0),"",(D3-INDEX(valor_asignado!$C:$C,MATCH(B3,valor_asignado!$B:$B,0)))/SQRT(INDEX(valor_asignado!$D:$D,MATCH(B3,valor_asignado!$B:$B,0))^2+INDEX(valor_asignado!$H:$H,MATCH(B3,valor_asignado!$B:$B,0))^2)) -> 0.07103172 | I3: =IF(H3="","N/A",IF(ABS(H3)<=2,"Satisfactorio",IF(ABS(H3)<3,"Cuestionable","No satisfactorio"))) -> Satisfactorio | J3: =IF(OR(NOT(ISNUMBER(D3)),NOT(ISNUMBER(INDEX(valor_asignado!$C:$C,MATCH(B3,valor_asignado!$B:$B,0)))),NOT(ISNUMBER(SQRT(E3^2+INDEX(valor_asignado!$H:$H,MATCH(B3,valor_asignado!$B:$B,0))^2))),SQRT(E3^2+INDEX(valor_asignado!$H:$H,MATCH(B3,valor_asignado!$B:$B,0))^2)=0),"",(D3-INDEX(valor_asignado!$C:$C,MATCH(B3,valor_asignado!$B:$B,0)))/SQRT(E3^2+INDEX(valor_asignado!$H:$H,MATCH(B3,valor_asignado!$B:$B,0))^2)) -> 0.30739113 | K3: =IF(J3="","N/A",IF(ABS(J3)<=2,"Satisfactorio",IF(ABS(J3)<3,"Cuestionable","No satisfactorio"))) -> Satisfactorio | L3: =IF(OR(NOT(ISNUMBER(D3)),NOT(ISNUMBER(INDEX(valor_asignado!$C:$C,MATCH(B3,valor_asignado!$B:$B,0)))),NOT(ISNUMBER(SQRT((2*E3)^2+(2*INDEX(valor_asignado!$H:$H,MATCH(B3,valor_asignado!$B:$B,0)))^2))),SQRT((2*E3)^2+(2*INDEX(valor_asignado!$H:$H,MATCH(B3,valor_asignado!$B:$B,0)))^2)=0),"",(D3-INDEX(valor_asignado!$C:$C,MATCH(B3,valor_asignado!$B:$B,0)))/SQRT((2*E3)^2+(2*INDEX(valor_asignado!$H:$H,MATCH(B3,valor_asignado!$B:$B,0)))^2)) -> 0.15369556 | M3: =IF(L3="","N/A",IF(ABS(L3)<=1,"Satisfactorio","No satisfactorio")) -> Satisfactorio | N3: =IF(AND(SUM(IF(AND(D3="",validacion_snapshot!$U$50=""),0,IFERROR(ABS(D3-validacion_snapshot!$U$50),1E+099)),IF(AND(E3="",validacion_snapshot!$V$50=""),0,IFERROR(ABS(E3-validacion_snapshot!$V$50),1E+099)),IF(AND(F3="",validacion_snapshot!$W$50=""),0,IFERROR(ABS(F3-validacion_snapshot!$W$50),1E+099)),IF(AND(H3="",validacion_snapshot!$Y$50=""),0,IFERROR(ABS(H3-validacion_snapshot!$Y$50),1E+099)),IF(AND(J3="",validacion_snapshot!$AA$50=""),0,IFERROR(ABS(J3-validacion_snapshot!$AA$50),1E+099)),IF(AND(L3="",validacion_snapshot!$AC$50=""),0,IFERROR(ABS(L3-validacion_snapshot!$AC$50),1E+099)))<=0.00000001,G3=validacion_snapshot!$X$50,I3=validacion_snapshot!$Z$50,K3=validacion_snapshot!$AB$50,M3=validacion_snapshot!$AD$50),"OK","FALLA") -> OK
B4: Referencia (1) | C4: part_11 | D4: =INDEX(datos_participantes!$D:$D,MATCH(C4,datos_participantes!$A:$A,0)) -> 80.056 | E4: =INDEX(datos_participantes!$F:$F,MATCH(C4,datos_participantes!$A:$A,0)) -> 0.094285887 | F4: =IF(OR(NOT(ISNUMBER(D4)),NOT(ISNUMBER(INDEX(valor_asignado!$C:$C,MATCH(B4,valor_asignado!$B:$B,0)))),NOT(ISNUMBER(INDEX(valor_asignado!$D:$D,MATCH(B4,valor_asignado!$B:$B,0)))),INDEX(valor_asignado!$D:$D,MATCH(B4,valor_asignado!$B:$B,0))=0),"",(D4-INDEX(valor_asignado!$C:$C,MATCH(B4,valor_asignado!$B:$B,0)))/INDEX(valor_asignado!$D:$D,MATCH(B4,valor_asignado!$B:$B,0))) -> 0.061459266 | G4: =IF(F4="","N/A",IF(ABS(F4)<=2,"Satisfactorio",IF(ABS(F4)<3,"Cuestionable","No satisfactorio"))) -> Satisfactorio | H4: =IF(OR(NOT(ISNUMBER(D4)),NOT(ISNUMBER(INDEX(valor_asignado!$C:$C,MATCH(B4,valor_asignado!$B:$B,0)))),NOT(ISNUMBER(SQRT(INDEX(valor_asignado!$D:$D,MATCH(B4,valor_asignado!$B:$B,0))^2+INDEX(valor_asignado!$H:$H,MATCH(B4,valor_asignado!$B:$B,0))^2))),SQRT(INDEX(valor_asignado!$D:$D,MATCH(B4,valor_asignado!$B:$B,0))^2+INDEX(valor_asignado!$H:$H,MATCH(B4,valor_asignado!$B:$B,0))^2)=0),"",(D4-INDEX(valor_asignado!$C:$C,MATCH(B4,valor_asignado!$B:$B,0)))/SQRT(INDEX(valor_asignado!$D:$D,MATCH(B4,valor_asignado!$B:$B,0))^2+INDEX(valor_asignado!$H:$H,MATCH(B4,valor_asignado!$B:$B,0))^2)) -> 0.059796474 | I4: =IF(H4="","N/A",IF(ABS(H4)<=2,"Satisfactorio",IF(ABS(H4)<3,"Cuestionable","No satisfactorio"))) -> Satisfactorio | J4: =IF(OR(NOT(ISNUMBER(D4)),NOT(ISNUMBER(INDEX(valor_asignado!$C:$C,MATCH(B4,valor_asignado!$B:$B,0)))),NOT(ISNUMBER(SQRT(E4^2+INDEX(valor_asignado!$H:$H,MATCH(B4,valor_asignado!$B:$B,0))^2))),SQRT(E4^2+INDEX(valor_asignado!$H:$H,MATCH(B4,valor_asignado!$B:$B,0))^2)=0),"",(D4-INDEX(valor_asignado!$C:$C,MATCH(B4,valor_asignado!$B:$B,0)))/SQRT(E4^2+INDEX(valor_asignado!$H:$H,MATCH(B4,valor_asignado!$B:$B,0))^2)) -> 0.25584611 | K4: =IF(J4="","N/A",IF(ABS(J4)<=2,"Satisfactorio",IF(ABS(J4)<3,"Cuestionable","No satisfactorio"))) -> Satisfactorio | L4: =IF(OR(NOT(ISNUMBER(D4)),NOT(ISNUMBER(INDEX(valor_asignado!$C:$C,MATCH(B4,valor_asignado!$B:$B,0)))),NOT(ISNUMBER(SQRT((2*E4)^2+(2*INDEX(valor_asignado!$H:$H,MATCH(B4,valor_asignado!$B:$B,0)))^2))),SQRT((2*E4)^2+(2*INDEX(valor_asignado!$H:$H,MATCH(B4,valor_asignado!$B:$B,0)))^2)=0),"",(D4-INDEX(valor_asignado!$C:$C,MATCH(B4,valor_asignado!$B:$B,0)))/SQRT((2*E4)^2+(2*INDEX(valor_asignado!$H:$H,MATCH(B4,valor_asignado!$B:$B,0)))^2)) -> 0.12792306 | M4: =IF(L4="","N/A",IF(ABS(L4)<=1,"Satisfactorio","No satisfactorio")) -> Satisfactorio | N4: =IF(AND(SUM(IF(AND(D4="",validacion_snapshot!$U$51=""),0,IFERROR(ABS(D4-validacion_snapshot!$U$51),1E+099)),IF(AND(E4="",validacion_snapshot!$V$51=""),0,IFERROR(ABS(E4-validacion_snapshot!$V$51),1E+099)),IF(AND(F4="",validacion_snapshot!$W$51=""),0,IFERROR(ABS(F4-validacion_snapshot!$W$51),1E+099)),IF(AND(H4="",validacion_snapshot!$Y$51=""),0,IFERROR(ABS(H4-validacion_snapshot!$Y$51),1E+099)),IF(AND(J4="",validacion_snapshot!$AA$51=""),0,IFERROR(ABS(J4-validacion_snapshot!$AA$51),1E+099)),IF(AND(L4="",validacion_snapshot!$AC$51=""),0,IFERROR(ABS(L4-validacion_snapshot!$AC$51),1E+099)))<=0.00000001,G4=validacion_snapshot!$X$51,I4=validacion_snapshot!$Z$51,K4=validacion_snapshot!$AB$51,M4=validacion_snapshot!$AD$51),"OK","FALLA") -> OK
B5: Referencia (1) | C5: part_12 | D5: =INDEX(datos_participantes!$D:$D,MATCH(C5,datos_participantes!$A:$A,0)) -> 80.031 | E5: =INDEX(datos_participantes!$F:$F,MATCH(C5,datos_participantes!$A:$A,0)) -> 0.092481926 | F5: =IF(OR(NOT(ISNUMBER(D5)),NOT(ISNUMBER(INDEX(valor_asignado!$C:$C,MATCH(B5,valor_asignado!$B:$B,0)))),NOT(ISNUMBER(INDEX(valor_asignado!$D:$D,MATCH(B5,valor_asignado!$B:$B,0)))),INDEX(valor_asignado!$D:$D,MATCH(B5,valor_asignado!$B:$B,0))=0),"",(D5-INDEX(valor_asignado!$C:$C,MATCH(B5,valor_asignado!$B:$B,0)))/INDEX(valor_asignado!$D:$D,MATCH(B5,valor_asignado!$B:$B,0))) -> 0.051836208 | G5: =IF(F5="","N/A",IF(ABS(F5)<=2,"Satisfactorio",IF(ABS(F5)<3,"Cuestionable","No satisfactorio"))) -> Satisfactorio | H5: =IF(OR(NOT(ISNUMBER(D5)),NOT(ISNUMBER(INDEX(valor_asignado!$C:$C,MATCH(B5,valor_asignado!$B:$B,0)))),NOT(ISNUMBER(SQRT(INDEX(valor_asignado!$D:$D,MATCH(B5,valor_asignado!$B:$B,0))^2+INDEX(valor_asignado!$H:$H,MATCH(B5,valor_asignado!$B:$B,0))^2))),SQRT(INDEX(valor_asignado!$D:$D,MATCH(B5,valor_asignado!$B:$B,0))^2+INDEX(valor_asignado!$H:$H,MATCH(B5,valor_asignado!$B:$B,0))^2)=0),"",(D5-INDEX(valor_asignado!$C:$C,MATCH(B5,valor_asignado!$B:$B,0)))/SQRT(INDEX(valor_asignado!$D:$D,MATCH(B5,valor_asignado!$B:$B,0))^2+INDEX(valor_asignado!$H:$H,MATCH(B5,valor_asignado!$B:$B,0))^2)) -> 0.050433769 | I5: =IF(H5="","N/A",IF(ABS(H5)<=2,"Satisfactorio",IF(ABS(H5)<3,"Cuestionable","No satisfactorio"))) -> Satisfactorio | J5: =IF(OR(NOT(ISNUMBER(D5)),NOT(ISNUMBER(INDEX(valor_asignado!$C:$C,MATCH(B5,valor_asignado!$B:$B,0)))),NOT(ISNUMBER(SQRT(E5^2+INDEX(valor_asignado!$H:$H,MATCH(B5,valor_asignado!$B:$B,0))^2))),SQRT(E5^2+INDEX(valor_asignado!$H:$H,MATCH(B5,valor_asignado!$B:$B,0))^2)=0),"",(D5-INDEX(valor_asignado!$C:$C,MATCH(B5,valor_asignado!$B:$B,0)))/SQRT(E5^2+INDEX(valor_asignado!$H:$H,MATCH(B5,valor_asignado!$B:$B,0))^2)) -> 0.2158801 | K5: =IF(J5="","N/A",IF(ABS(J5)<=2,"Satisfactorio",IF(ABS(J5)<3,"Cuestionable","No satisfactorio"))) -> Satisfactorio | L5: =IF(OR(NOT(ISNUMBER(D5)),NOT(ISNUMBER(INDEX(valor_asignado!$C:$C,MATCH(B5,valor_asignado!$B:$B,0)))),NOT(ISNUMBER(SQRT((2*E5)^2+(2*INDEX(valor_asignado!$H:$H,MATCH(B5,valor_asignado!$B:$B,0)))^2))),SQRT((2*E5)^2+(2*INDEX(valor_asignado!$H:$H,MATCH(B5,valor_asignado!$B:$B,0)))^2)=0),"",(D5-INDEX(valor_asignado!$C:$C,MATCH(B5,valor_asignado!$B:$B,0)))/SQRT((2*E5)^2+(2*INDEX(valor_asignado!$H:$H,MATCH(B5,valor_asignado!$B:$B,0)))^2)) -> 0.10794005 | M5: =IF(L5="","N/A",IF(ABS(L5)<=1,"Satisfactorio","No satisfactorio")) -> Satisfactorio | N5: =IF(AND(SUM(IF(AND(D5="",validacion_snapshot!$U$52=""),0,IFERROR(ABS(D5-validacion_snapshot!$U$52),1E+099)),IF(AND(E5="",validacion_snapshot!$V$52=""),0,IFERROR(ABS(E5-validacion_snapshot!$V$52),1E+099)),IF(AND(F5="",validacion_snapshot!$W$52=""),0,IFERROR(ABS(F5-validacion_snapshot!$W$52),1E+099)),IF(AND(H5="",validacion_snapshot!$Y$52=""),0,IFERROR(ABS(H5-validacion_snapshot!$Y$52),1E+099)),IF(AND(J5="",validacion_snapshot!$AA$52=""),0,IFERROR(ABS(J5-validacion_snapshot!$AA$52),1E+099)),IF(AND(L5="",validacion_snapshot!$AC$52=""),0,IFERROR(ABS(L5-validacion_snapshot!$AC$52),1E+099)))<=0.00000001,G5=validacion_snapshot!$X$52,I5=validacion_snapshot!$Z$52,K5=validacion_snapshot!$AB$52,M5=validacion_snapshot!$AD$52),"OK","FALLA") -> OK
B6: Referencia (1) | C6: part_2 | D6: =INDEX(datos_participantes!$D:$D,MATCH(C6,datos_participantes!$A:$A,0)) -> 80.057333 | E6: =INDEX(datos_participantes!$F:$F,MATCH(C6,datos_participantes!$A:$A,0)) -> 0.14760399 | F6: =IF(OR(NOT(ISNUMBER(D6)),NOT(ISNUMBER(INDEX(valor_asignado!$C:$C,MATCH(B6,valor_asignado!$B:$B,0)))),NOT(ISNUMBER(INDEX(valor_asignado!$D:$D,MATCH(B6,valor_asignado!$B:$B,0)))),INDEX(valor_asignado!$D:$D,MATCH(B6,valor_asignado!$B:$B,0))=0),"",(D6-INDEX(valor_asignado!$C:$C,MATCH(B6,valor_asignado!$B:$B,0)))/INDEX(valor_asignado!$D:$D,MATCH(B6,valor_asignado!$B:$B,0))) -> 0.061972496 | G6: =IF(F6="","N/A",IF(ABS(F6)<=2,"Satisfactorio",IF(ABS(F6)<3,"Cuestionable","No satisfactorio"))) -> Satisfactorio | H6: =IF(OR(NOT(ISNUMBER(D6)),NOT(ISNUMBER(INDEX(valor_asignado!$C:$C,MATCH(B6,valor_asignado!$B:$B,0)))),NOT(ISNUMBER(SQRT(INDEX(valor_asignado!$D:$D,MATCH(B6,valor_asignado!$B:$B,0))^2+INDEX(valor_asignado!$H:$H,MATCH(B6,valor_asignado!$B:$B,0))^2))),SQRT(INDEX(valor_asignado!$D:$D,MATCH(B6,valor_asignado!$B:$B,0))^2+INDEX(valor_asignado!$H:$H,MATCH(B6,valor_asignado!$B:$B,0))^2)=0),"",(D6-INDEX(valor_asignado!$C:$C,MATCH(B6,valor_asignado!$B:$B,0)))/SQRT(INDEX(valor_asignado!$D:$D,MATCH(B6,valor_asignado!$B:$B,0))^2+INDEX(valor_asignado!$H:$H,MATCH(B6,valor_asignado!$B:$B,0))^2)) -> 0.060295818 | I6: =IF(H6="","N/A",IF(ABS(H6)<=2,"Satisfactorio",IF(ABS(H6)<3,"Cuestionable","No satisfactorio"))) -> Satisfactorio | J6: =IF(OR(NOT(ISNUMBER(D6)),NOT(ISNUMBER(INDEX(valor_asignado!$C:$C,MATCH(B6,valor_asignado!$B:$B,0)))),NOT(ISNUMBER(SQRT(E6^2+INDEX(valor_asignado!$H:$H,MATCH(B6,valor_asignado!$B:$B,0))^2))),SQRT(E6^2+INDEX(valor_asignado!$H:$H,MATCH(B6,valor_asignado!$B:$B,0))^2)=0),"",(D6-INDEX(valor_asignado!$C:$C,MATCH(B6,valor_asignado!$B:$B,0)))/SQRT(E6^2+INDEX(valor_asignado!$H:$H,MATCH(B6,valor_asignado!$B:$B,0))^2)) -> 0.25381434 | K6: =IF(J6="","N/A",IF(ABS(J6)<=2,"Satisfactorio",IF(ABS(J6)<3,"Cuestionable","No satisfactorio"))) -> Satisfactorio | L6: =IF(OR(NOT(ISNUMBER(D6)),NOT(ISNUMBER(INDEX(valor_asignado!$C:$C,MATCH(B6,valor_asignado!$B:$B,0)))),NOT(ISNUMBER(SQRT((2*E6)^2+(2*INDEX(valor_asignado!$H:$H,MATCH(B6,valor_asignado!$B:$B,0)))^2))),SQRT((2*E6)^2+(2*INDEX(valor_asignado!$H:$H,MATCH(B6,valor_asignado!$B:$B,0)))^2)=0),"",(D6-INDEX(valor_asignado!$C:$C,MATCH(B6,valor_asignado!$B:$B,0)))/SQRT((2*E6)^2+(2*INDEX(valor_asignado!$H:$H,MATCH(B6,valor_asignado!$B:$B,0)))^2)) -> 0.12690717 | M6: =IF(L6="","N/A",IF(ABS(L6)<=1,"Satisfactorio","No satisfactorio")) -> Satisfactorio | N6: =IF(AND(SUM(IF(AND(D6="",validacion_snapshot!$U$53=""),0,IFERROR(ABS(D6-validacion_snapshot!$U$53),1E+099)),IF(AND(E6="",validacion_snapshot!$V$53=""),0,IFERROR(ABS(E6-validacion_snapshot!$V$53),1E+099)),IF(AND(F6="",validacion_snapshot!$W$53=""),0,IFERROR(ABS(F6-validacion_snapshot!$W$53),1E+099)),IF(AND(H6="",validacion_snapshot!$Y$53=""),0,IFERROR(ABS(H6-validacion_snapshot!$Y$53),1E+099)),IF(AND(J6="",validacion_snapshot!$AA$53=""),0,IFERROR(ABS(J6-validacion_snapshot!$AA$53),1E+099)),IF(AND(L6="",validacion_snapshot!$AC$53=""),0,IFERROR(ABS(L6-validacion_snapshot!$AC$53),1E+099)))<=0.00000001,G6=validacion_snapshot!$X$53,I6=validacion_snapshot!$Z$53,K6=validacion_snapshot!$AB$53,M6=validacion_snapshot!$AD$53),"OK","FALLA") -> OK
